<?xml version='1.0' encoding='utf-8'?>
<robot name="Quadruped-IsaacSim">
    <link name="Basic_Body">
        <inertial>
            <origin xyz="3.2699753365527856e-11 -0.0012499987421279188 -0.004750000038203694" rpy="0.0 0.0 0.0" />
            <mass value="0.5223502772293394" />
            <inertia ixx="0.000774574690005525" iyy="0.011438778897726667" izz="0.01205863802906395" ixy="-1.1564890962261062e-10" iyz="3.863476379095676e-13" ixz="2.9993621752067147e-12" />
        </inertial>
        <visual name="Body1_visual">
            <origin xyz="0.0 0.0 0.0" rpy="0.0 0.0 0.0" />
            <geometry>
                <mesh filename="meshes/Body1.stl" />
            </geometry>
        </visual>
        <collision name="Body1_collision">
            <origin xyz="0.0 0.0 0.0" rpy="0.0 0.0 0.0" />
            <geometry>
                <mesh filename="meshes/Body1.stl" />
            </geometry>
        </collision>
    </link>
    <link name="FL-Single-Motor1">
        <inertial>
            <origin xyz="-0.008058511743548396 0.024291032753734853 0.016750000002170324" rpy="0.0 -0.0 0.0" />
            <mass value="0.18505114928963637" />
            <inertia ixx="6.927157374956791e-05" iyy="5.2779060673292105e-05" izz="8.852045695425213e-05" ixy="1.5973926095205152e-07" iyz="4.3619621803436814e-15" ixz="1.0601762523432257e-14" />
        </inertial>
        <visual name="FL-Single-Motor1_visual">
            <origin xyz="-0.041749999999999954 0.039250000000000014 0.016749999999999973" rpy="-1.5707963267948968 -1.5707963267948966 0" />
            <geometry>
                <mesh filename="meshes/FL-Single-Motor1.stl" />
            </geometry>
        </visual>
        <collision name="FL-Single-Motor1_collision">
            <origin xyz="-0.041749999999999954 0.039250000000000014 0.016749999999999973" rpy="-1.5707963267948968 -1.5707963267948966 0" />
            <geometry>
                <mesh filename="meshes/FL-Single-Motor1.stl" />
            </geometry>
        </collision>
    </link>
    <link name="FL-Double-Motor1">
        <inertial>
            <origin xyz="-0.06716414766997797 0.00542494091347443 0.009451637209221975" rpy="0.0 -0.0 0.0" />
            <mass value="0.4782524941626558" />
            <inertia ixx="0.0003096692588512723" iyy="0.0008123248398218923" izz="0.0007226948848486764" ixy="-1.8409934400207006e-07" iyz="-7.691806622294427e-05" ixz="-7.498838760300702e-07" />
        </inertial>
        <visual name="FL-Double-Motor1_visual">
            <origin xyz="-0.08224999999999996 7.105427357601002e-17 1.7763568394002505e-17" rpy="7.351718556377353e-17 -0.5235987755982987 -1.5707963267948966" />
            <geometry>
                <mesh filename="meshes/FL-Double-Motor1.stl" />
            </geometry>
        </visual>
        <!-- <collision name="FL-Double-Motor1_collision">
            <origin xyz="-0.08224999999999996 7.105427357601002e-17 1.7763568394002505e-17" rpy="7.351718556377353e-17 -0.5235987755982987 -1.5707963267948966" />
            <geometry>
                <mesh filename="meshes/FL-Double-Motor1.stl" />
            </geometry>
        </collision> -->
    </link>
    <link name="FL-leg-link11">
        <inertial>
            <origin xyz="-0.03429140259846331 -0.025620270865074807 -0.032139907337445095" rpy="0.0 -0.0 0.0" />
            <mass value="0.04770813454279477" />
            <inertia ixx="6.36302553655918e-05" iyy="8.89846515557298e-05" izz="6.558294511018001e-05" ixy="-2.8303963607115894e-05" iyz="-2.8671359242327797e-05" ixz="-4.1221187352143054e-05" />
        </inertial>
        <visual name="FL-leg-link11_visual">
            <origin xyz="3.552713678800501e-17 -0.00866024939550707 0.005" rpy="2.4113673972429335 -0.7233643550425849 0.5349780765624936" />
            <geometry>
                <mesh filename="meshes/FL-leg-link11.stl" />
            </geometry>
        </visual>
        <!-- <collision name="FL-leg-link11_collision">
            <origin xyz="3.552713678800501e-17 -0.00866024939550707 0.005" rpy="2.4113673972429335 -0.7233643550425849 0.5349780765624936" />
            <geometry>
                <mesh filename="meshes/FL-leg-link11.stl" />
            </geometry>
        </collision> -->
    </link>
    <!-- <link name="FL-leg-link31">
        <inertial>
            <origin xyz="-0.027784006284850626 0.05516827626297925 -0.033931111316207546" rpy="0.0 -0.0 0.0" />
            <mass value="0.030992351814191726" />
            <inertia ixx="4.1797781016090024e-05" iyy="2.5101887656093925e-05" izz="5.216342305184938e-05" ixy="2.2489027187463555e-05" iyz="1.3811198092937396e-05" ixz="-8.336460485588408e-06" />
        </inertial>
        <visual name="FL-leg-link31_visual">
            <origin xyz="0.0014091637734288832 0.0013351061748942783 0.00048140935420729395" rpy="2.5539983614180954 -1.1216409235946698 2.8696449517481084" />
            <geometry>
                <mesh filename="meshes/FL-leg-link31.stl" />
            </geometry>
        </visual>
        <collision name="FL-leg-link31_collision">
            <origin xyz="0.0014091637734288832 0.0013351061748942783 0.00048140935420729395" rpy="2.5539983614180954 -1.1216409235946698 2.8696449517481084" />
            <geometry>
                <mesh filename="meshes/FL-leg-link31.stl" />
            </geometry>
        </collision>
    </link>
    <link name="FL-leg-link41">
        <inertial>
            <origin xyz="0.004921954583490873 -0.026260730543362136 -0.05031446570950955" rpy="0.0 -0.0 2.993496475303259e-49" />
            <mass value="0.049054688661482895" />
            <inertia ixx="0.00010828569935672841" iyy="9.383889167156358e-05" izz="2.0884071472399707e-05" ixy="3.685945410098312e-06" iyz="-3.853858145171302e-05" ixz="8.370993681913823e-06" />
        </inertial>
        <visual name="FL-leg-link41_visual">
            <origin xyz="1.0658141036401502e-16 0.007967430604493071 -0.004600000000000009" rpy="-1.425522688459402 1.0410402069617724 -1.4028497870582188" />
            <geometry>
                <mesh filename="meshes/FL-leg-link41.stl" />
            </geometry>
        </visual>
        <collision name="FL-leg-link41_collision">
            <origin xyz="1.0658141036401502e-16 0.007967430604493071 -0.004600000000000009" rpy="-1.425522688459402 1.0410402069617724 -1.4028497870582188" />
            <geometry>
                <mesh filename="meshes/FL-leg-link41.stl" />
            </geometry>
        </collision>
    </link> -->
    <link name="FL-leg-link21">
        <inertial>
            <origin xyz="0.010346172100577498 0.06008226076579486 -0.04227209085096202" rpy="0.0 -0.0 0.0" />
            <mass value="0.03786194092058064" />
            <inertia ixx="8.732714459541886e-05" iyy="3.414151467267334e-05" izz="6.0041064589192085e-05" ixy="-1.112391699728233e-05" iyz="4.093020630023653e-05" ixz="8.177127433257536e-06" />
        </inertial>
        <visual name="FL-leg-link21_visual">
            <origin xyz="-0.0010808984164838976 0.0011299930161795403 0.0012469101556211726" rpy="0.8167077041448609 -0.5445881822840094 0.2591490785230335" />
            <geometry>
                <mesh filename="meshes/FL-leg-link21.stl" />
            </geometry>
        </visual>
        <collision name="FL-leg-link21_collision">
            <origin xyz="-0.0010808984164838976 0.0011299930161795403 0.0012469101556211726" rpy="0.8167077041448609 -0.5445881822840094 0.2591490785230335" />
            <geometry>
                <mesh filename="meshes/FL-leg-link21.stl" />
            </geometry>
        </collision>
    </link>



    <link name="RL-Single-Motor1">
        <inertial>
            <origin xyz="0.00805851174354844 0.024291032753734853 0.01674999999782983" rpy="0.0 -0.0 0.0" />
            <mass value="0.18505114928963637" />
            <inertia ixx="6.92715737496026e-05" iyy="5.27790606733268e-05" izz="8.852045695425127e-05" ixy="-1.59739260951401e-07" iyz="-4.361094818605693e-15" ixz="1.0604364608646222e-14" />
        </inertial>
        <visual name="RL-Single-Motor1_visual">
            <origin xyz="0.04174999999999999 0.03925 0.016750000000000043" rpy="-1.5707963267948966 1.5707963267948966 0" />
            <geometry>
                <mesh filename="meshes/RL-Single-Motor1.stl" />
            </geometry>
        </visual>
        <collision name="RL-Single-Motor1_collision">
            <origin xyz="0.04174999999999999 0.03925 0.016750000000000043" rpy="-1.5707963267948966 1.5707963267948966 0" />
            <geometry>
                <mesh filename="meshes/RL-Single-Motor1.stl" />
            </geometry>
        </collision>
    </link>
    <link name="RL-Double-Motor1">
        <inertial>
            <origin xyz="0.06716414766997804 0.0048941336366256395 0.00973708815798121" rpy="0.0 -0.0 0.0" />
            <mass value="0.4782524941626558" />
            <inertia ixx="0.0003096692588512445" iyy="0.0008207034759449682" izz="0.0007143162487255744" ixy="5.241007754348826e-07" iyz="-7.138074383015483e-05" ixz="5.67042126471508e-07" />
        </inertial>
        <visual name="RL-Double-Motor1_visual">
            <origin xyz="0.08224999999999996 0.0 5.062616992290714e-16" rpy="2.01526633129011e-15 0.463207708438608 1.5707963267948977" />
            <geometry>
                <mesh filename="meshes/RL-Double-Motor1.stl" />
            </geometry>
        </visual>
        <!-- <collision name="RL-Double-Motor1_collision">
            <origin xyz="0.08224999999999996 0.0 5.062616992290714e-16" rpy="2.01526633129011e-15 0.463207708438608 1.5707963267948977" />
            <geometry>
                <mesh filename="meshes/RL-Double-Motor1.stl" />
            </geometry>
        </collision> -->
    </link>
    <link name="RL-leg-link11">
        <inertial>
            <origin xyz="-0.018187575134685014 -0.0278010245702095 -0.04197126709316429" rpy="0.0 -0.0 0.0" />
            <mass value="0.04770813454279477" />
            <inertia ixx="9.38577026527148e-05" iyy="8.545018353156748e-05" izz="3.888996584721628e-05" ixy="-1.6505880254080552e-05" iyz="-3.9788557821569114e-05" ixz="-2.8091963059880598e-05" />
        </inertial>
        <visual name="RL-leg-link11_visual">
            <origin xyz="2.486899575160351e-16 -0.008946235112596668 0.004468202786253741" rpy="2.17124332610022 -0.9985218448045559 0.8872287946654374" />
            <geometry>
                <mesh filename="meshes/RL-leg-link11.stl" />
            </geometry>
        </visual>
        <!-- <collision name="RL-leg-link11_collision">
            <origin xyz="2.486899575160351e-16 -0.008946235112596668 0.004468202786253741" rpy="2.17124332610022 -0.9985218448045559 0.8872287946654374" />
            <geometry>
                <mesh filename="meshes/RL-leg-link11.stl" />
            </geometry>
        </collision> -->
    </link>
    <!-- <link name="RL-leg-link31">
        <inertial>
            <origin xyz="-0.009870261189729525 0.05923453093001441 -0.03688710288419682" rpy="0.0 -0.0 0.0" />
            <mass value="0.030992351814191726" />
            <inertia ixx="5.096791650977808e-05" iyy="1.925626945370811e-05" izz="4.883890576054277e-05" ixy="1.482031722228722e-05" iyz="1.9307225662326438e-05" ixz="-6.7673300906637664e-06" />
        </inertial>
        <visual name="RL-leg-link31_visual">
            <origin xyz="0.0012817170732537875 0.0011521926129546502 0.001014721809617587" rpy="2.320489800622202 -0.8048584932280782 2.9617957951061364" />
            <geometry>
                <mesh filename="meshes/RL-leg-link31.stl" />
            </geometry>
        </visual>
        <collision name="RL-leg-link31_collision">
            <origin xyz="0.0012817170732537875 0.0011521926129546502 0.001014721809617587" rpy="2.320489800622202 -0.8048584932280782 2.9617957951061364" />
            <geometry>
                <mesh filename="meshes/RL-leg-link31.stl" />
            </geometry>
        </collision>
    </link>
    <link name="RL-leg-link41">
        <inertial>
            <origin xyz="0.024158096806667615 -0.020866977631660184 -0.04718424430272236" rpy="0.0 -0.0 0.0" />
            <mass value="0.049054688661482895" />
            <inertia ixx="9.023066630052361e-05" iyy="0.00010094445675933907" izz="3.183353944083336e-05" ixy="1.3285355785992931e-05" iyz="-2.7304265271900496e-05" ixz="3.8188092445052245e-05" />
        </inertial>
        <visual name="RL-leg-link41_visual">
            <origin xyz="2.1316282072803005e-16 0.008230534887403315 -0.004110747213746322" rpy="-0.8685317926765391 0.9455253589537899 -0.764059848904591" />
            <geometry>
                <mesh filename="meshes/RL-leg-link41.stl" />
            </geometry>
        </visual>
        <collision name="RL-leg-link41_collision">
            <origin xyz="2.1316282072803005e-16 0.008230534887403315 -0.004110747213746322" rpy="-0.8685317926765391 0.9455253589537899 -0.764059848904591" />
            <geometry>
                <mesh filename="meshes/RL-leg-link41.stl" />
            </geometry>
        </collision>
    </link> -->
    <link name="RL-leg-link21">
        <inertial>
            <origin xyz="0.029139284884755003 0.060302052863784684 -0.03191261917070124" rpy="0.0 -0.0 0.0" />
            <mass value="0.03786194092058064" />
            <inertia ixx="7.448018286321028e-05" iyy="3.3920191756298313e-05" izz="7.310934923777091e-05" ixy="-2.9055049424507536e-05" iyz="3.0784069314594614e-05" ixz="1.584008316575741e-05" />
        </inertial>
        <visual name="RL-leg-link21_visual">
            <origin xyz="-0.0013289292056403214 0.0011882835980298269 0.0009066050031298012" rpy="0.7994953932588053 -0.8863852112506413 0.16833296756001442" />
            <geometry>
                <mesh filename="meshes/RL-leg-link21.stl" />
            </geometry>
        </visual>
        <collision name="RL-leg-link21_collision">
            <origin xyz="-0.0013289292056403214 0.0011882835980298269 0.0009066050031298012" rpy="0.7994953932588053 -0.8863852112506413 0.16833296756001442" />
            <geometry>
                <mesh filename="meshes/RL-leg-link21.stl" />
            </geometry>
        </collision>
    </link>


    <link name="FR-Single-Motor1">
        <inertial>
            <origin xyz="-0.008058511743548396 -0.02429103275373481 0.016749999997829692" rpy="0.0 -0.0 0.0" />
            <mass value="0.18505114928963637" />
            <inertia ixx="6.92715737495922e-05" iyy="5.277906067331986e-05" izz="8.852045695425062e-05" ixy="-1.5973926095205152e-07" iyz="4.361094818605693e-15" ixz="-1.0603497246908233e-14" />
        </inertial>
        <visual name="FR-Single-Motor1_visual">
            <origin xyz="-0.04174999999999992 -0.03924999999999997 0.016749999999999973" rpy="1.5707963267948966 1.5707963267948966 0" />
            <geometry>
                <mesh filename="meshes/FR-Single-Motor1.stl" />
            </geometry>
        </visual>
        <collision name="FR-Single-Motor1_collision">
            <origin xyz="-0.04174999999999992 -0.03924999999999997 0.016749999999999973" rpy="1.5707963267948966 1.5707963267948966 0" />
            <geometry>
                <mesh filename="meshes/FR-Single-Motor1.stl" />
            </geometry>
        </collision>
    </link>
    <link name="FR-Double-Motor1">
        <inertial>
            <origin xyz="-0.06716414766997794 0.005472887473803354 -0.009423955249709124" rpy="0.0 -0.0 0.0" />
            <mass value="0.4782524941626558" />
            <inertia ixx="0.00030966925885123064" iyy="0.0008117153729510305" izz="0.0007233043517194948" ixy="-5.573688145396604e-07" iyz="7.726994208490101e-05" ixz="5.343766467432569e-07" />
        </inertial>
        <visual name="FR-Double-Motor1_visual">
            <origin xyz="-0.08224999999999989 -1.4210854715202004e-16 1.7763568394002506e-16" rpy="-3.141592653589793 -0.5235987755982989 1.570796326794897" />
            <geometry>
                <mesh filename="meshes/FR-Double-Motor1.stl" />
            </geometry>
        </visual>
        <!-- <collision name="FR-Double-Motor1_collision">
            <origin xyz="-0.08224999999999989 -1.4210854715202004e-16 1.7763568394002506e-16" rpy="-3.141592653589793 -0.5235987755982989 1.570796326794897" />
            <geometry>
                <mesh filename="meshes/FR-Double-Motor1.stl" />
            </geometry>
        </collision> -->
    </link>
    <link name="FR-leg-link11">
        <inertial>
            <origin xyz="-0.0392504534288604 0.02323732059089055 -0.02801251639064752" rpy="0.0 -0.0 0.0" />
            <mass value="0.047708134542766116" />
            <inertia ixx="5.058596311753247e-05" iyy="9.271224645527806e-05" izz="7.48996424585562e-05" ixy="2.9004627760761355e-05" iyz="2.2753668503204108e-05" ixz="-4.1415231467140535e-05" />
        </inertial>
        <visual name="FR-leg-link11_visual">
            <origin xyz="-7.105427357601002e-17 0.008660249395506928 0.004999999999999787" rpy="0.6637961054570317 -0.6240105391945766 -0.42869167538801345" />
            <geometry>
                <mesh filename="meshes/FR-leg-link11.stl" />
            </geometry>
        </visual>
        <!-- <collision name="FR-leg-link11_collision">
            <origin xyz="-7.105427357601002e-17 0.008660249395506928 0.004999999999999787" rpy="0.6637961054570317 -0.6240105391945766 -0.42869167538801345" />
            <geometry>
                <mesh filename="meshes/FR-leg-link11.stl" />
            </geometry>
        </collision> -->
    </link>
    <link name="FR-leg-link21">
        <inertial>
            <origin xyz="0.0029824732745502304 0.06030582122666935 0.043106422151264305" rpy="0.0 -0.0 0.0" />
            <mass value="0.03786194092058894" />
            <inertia ixx="8.926159316228945e-05" iyy="3.363042089469369e-05" izz="5.861770980042343e-05" ixy="-4.095614841022887e-06" iyz="-4.20746136570426e-05" ixz="-3.131503509630333e-06" />
        </inertial>
        <visual name="FR-leg-link21_visual">
            <origin xyz="-0.0009541540325433574 0.0010958606223879742 -0.0013743016819035957" rpy="-0.8539855599227406 0.42399626641840427 0.2753025393609303" />
            <geometry>
                <mesh filename="meshes/FR-leg-link21.stl" />
            </geometry>
        </visual>
        <collision name="FR-leg-link21_collision">
            <origin xyz="-0.0009541540325433574 0.0010958606223879742 -0.0013743016819035957" rpy="-0.8539855599227406 0.42399626641840427 0.2753025393609303" />
            <geometry>
                <mesh filename="meshes/FR-leg-link21.stl" />
            </geometry>
        </collision>
    </link>
    <!-- <link name="FR-leg-link31">
        <inertial>
            <origin xyz="-0.03362474629608322 0.05413827562982711 0.03008709543269612" rpy="0.0 -0.0 0.0" />
            <mass value="0.030992351814247344" />
            <inertia ixx="3.8274043513176155e-05" iyy="2.6678868376040266e-05" izz="5.411017983539754e-05" ixy="2.4491368988972677e-05" iyz="-1.0607696054176567e-05" ixz="7.103149258507075e-06" />
        </inertial>
        <visual name="FR-leg-link31_visual">
            <origin xyz="0.001412790401899251 0.0013824369479977605 -0.0003047696924419974" rpy="-2.6513921813390615 1.2411943749583882 2.812912790352554" />
            <geometry>
                <mesh filename="meshes/FR-leg-link31.stl" />
            </geometry>
        </visual>
        <collision name="FR-leg-link31_collision">
            <origin xyz="0.001412790401899251 0.0013824369479977605 -0.0003047696924419974" rpy="-2.6513921813390615 1.2411943749583882 2.812912790352554" />
            <geometry>
                <mesh filename="meshes/FR-leg-link31.stl" />
            </geometry>
        </collision>
    </link>
    <link name="FR-leg-link41">
        <inertial>
            <origin xyz="-0.0024380763075627955 0.026341203667214295 -0.05045383314626655" rpy="0.0 -0.0 0.0" />
            <mass value="0.04905477511303801" />
            <inertia ixx="0.00010890521879905989" iyy="9.370575242678009e-05" izz="2.0397585143995447e-05" ixy="1.6429673672332403e-06" iyz="3.8794256055914734e-05" ixz="-4.056017968107577e-06" />
        </inertial>
        <visual name="FR-leg-link41_visual">
            <origin xyz="-6.392042450897862e-13 -0.007967430607364606 -0.004600000001657989" rpy="-1.4932782866955108 1.0454576602664718 1.6603364301662176" />
            <geometry>
                <mesh filename="meshes/FR-leg-link41.stl" />
            </geometry>
        </visual>
        <collision name="FR-leg-link41_collision">
            <origin xyz="-6.392042450897862e-13 -0.007967430607364606 -0.004600000001657989" rpy="-1.4932782866955108 1.0454576602664718 1.6603364301662176" />
            <geometry>
                <mesh filename="meshes/FR-leg-link41.stl" />
            </geometry>
        </collision>
    </link> -->
    <link name="RR-Single-Motor1">
        <inertial>
            <origin xyz="0.008058511743548361 -0.024291032753734863 0.016750000002170466" rpy="0.0 -0.0 0.0" />
            <mass value="0.18505114928963637" />
            <inertia ixx="6.927157374958179e-05" iyy="5.277906067330945e-05" izz="8.852045695425148e-05" ixy="1.5973926095183468e-07" iyz="-4.360227456867705e-15" ixz="-1.060219620430125e-14" />
        </inertial>
        <visual name="RR-Single-Motor1_visual">
            <origin xyz="0.041749999999999884 -0.039250000000000014 0.016750000000000115" rpy="1.5707963267948968 -1.5707963267948966 0" />
            <geometry>
                <mesh filename="meshes/RR-Single-Motor1.stl" />
            </geometry>
        </visual>
        <collision name="RR-Single-Motor1_collision">
            <origin xyz="0.041749999999999884 -0.039250000000000014 0.016750000000000115" rpy="1.5707963267948968 -1.5707963267948966 0" />
            <geometry>
                <mesh filename="meshes/RR-Single-Motor1.stl" />
            </geometry>
        </collision>
    </link>
    <link name="RR-Double-Motor1">
        <inertial>
            <origin xyz="0.06716414766997786 0.0054249409134740035 -0.009451637209221868" rpy="0.0 -0.0 0.0" />
            <mass value="0.4782524941626558" />
            <inertia ixx="0.0003096692588513138" iyy="0.0008123248398218992" izz="0.0007226948848487317" ixy="1.8409934400900882e-07" iyz="7.691806622295466e-05" ixz="-7.498838760292002e-07" />
        </inertial>
        <visual name="RR-Double-Motor1_visual">
            <origin xyz="0.08224999999999977 -2.842170943040401e-16 5.329070518200751e-17" rpy="-3.141592653589793 0.5235987755982987 -1.570796326794897" />
            <geometry>
                <mesh filename="meshes/RR-Double-Motor1.stl" />
            </geometry>
        </visual>
        <!-- <collision name="RR-Double-Motor1_collision">
            <origin xyz="0.08224999999999977 -2.842170943040401e-16 5.329070518200751e-17" rpy="-3.141592653589793 0.5235987755982987 -1.570796326794897" />
            <geometry>
                <mesh filename="meshes/RR-Double-Motor1.stl" />
            </geometry>
        </collision> -->
    </link>
    <link name="RR-leg-link11">
        <inertial>
            <origin xyz="-0.02049529540828065 0.0298328178022809 -0.039436252661954045" rpy="0.0 -0.0 0.0" />
            <mass value="0.047708134542766116" />
            <inertia ixx="9.066477928141445e-05" iyy="8.137903758726438e-05" izz="4.615403516268841e-05" ixy="2.0114478992803006e-05" iyz="4.086665734444459e-05" ixz="-2.992238667434614e-05" />
        </inertial>
        <visual name="RR-leg-link11_visual">
            <origin xyz="-3.1974423109204507e-16 0.008660249395507247 0.0049999999999996445" rpy="0.9821746740840134 -0.9258276201676335 -0.8748561591377285" />
            <geometry>
                <mesh filename="meshes/RR-leg-link11.stl" />
            </geometry>
        </visual>
        <!-- <collision name="RR-leg-link11_collision">
            <origin xyz="-3.1974423109204507e-16 0.008660249395507247 0.0049999999999996445" rpy="0.9821746740840134 -0.9258276201676335 -0.8748561591377285" />
            <geometry>
                <mesh filename="meshes/RR-leg-link11.stl" />
            </geometry>
        </collision> -->
    </link>
    <link name="RR-leg-link21">
        <inertial>
            <origin xyz="0.026808419669417542 0.058603462989383924 0.03675315182862125" rpy="0.0 -0.0 0.0" />
            <mass value="0.03786194092058894" />
            <inertia ixx="7.66827704643605e-05" iyy="3.711925391000625e-05" izz="6.770769948303808e-05" ixy="-2.6071937231539568e-05" iyz="-3.4346534923379984e-05" ixz="-1.6838950294716128e-05" />
        </inertial>
        <visual name="RR-leg-link21_visual">
            <origin xyz="-0.0013049509610227794 0.0012249511105342492 -0.0008925123095268539" rpy="-0.7228732455792783 0.8304127646811991 0.2397761024208059" />
            <geometry>
                <mesh filename="meshes/RR-leg-link21.stl" />
            </geometry>
        </visual>
        <collision name="RR-leg-link21_collision">
            <origin xyz="-0.0013049509610227794 0.0012249511105342492 -0.0008925123095268539" rpy="-0.7228732455792783 0.8304127646811991 0.2397761024208059" />
            <geometry>
                <mesh filename="meshes/RR-leg-link21.stl" />
            </geometry>
        </collision>
    </link>
    <!-- <link name="RR-leg-link31">
        <inertial>
            <origin xyz="-0.012362829956947189 0.05676616941385852 0.039894526685076016" rpy="0.0 -0.0 0.0" />
            <mass value="0.030992351814247344" />
            <inertia ixx="4.989771804890866e-05" iyy="2.2052695287080153e-05" izz="4.7112678388621745e-05" ixy="1.565508882488436e-05" iyz="-2.0177739991756243e-05" ixz="8.0632527831976e-06" />
        </inertial>
        <visual name="RR-leg-link31_visual">
            <origin xyz="0.0013081595516952049 0.0012269555689081813 -0.0008850359659596663" rpy="-2.420738693439757 0.8359679143132223 2.9018544437780833" />
            <geometry>
                <mesh filename="meshes/RR-leg-link31.stl" />
            </geometry>
        </visual>
        <collision name="RR-leg-link31_collision">
            <origin xyz="0.0013081595516952049 0.0012269555689081813 -0.0008850359659596663" rpy="-2.420738693439757 0.8359679143132223 2.9018544437780833" />
            <geometry>
                <mesh filename="meshes/RR-leg-link31.stl" />
            </geometry>
        </collision>
    </link>
    <link name="RR-leg-link41">
        <inertial>
            <origin xyz="0.021731340036846056 0.024211367327730996 -0.04676484839008317" rpy="0.0 -0.0 0.0" />
            <mass value="0.04905477511303801" />
            <inertia ixx="9.381797384840947e-05" iyy="9.670427321229608e-05" izz="3.2486309309129945e-05" ixy="-1.4391355852821272e-05" iyz="3.2707746805857054e-05" ixz="3.4225439634142606e-05" />
        </inertial>
        <visual name="RR-leg-link41_visual">
            <origin xyz="-4.405364961712621e-15 -0.007967430604493 -0.004600000000000293" rpy="-2.1528358059330697 0.9290985520356033 0.883082812773521" />
            <geometry>
                <mesh filename="meshes/RR-leg-link41.stl" />
            </geometry>
        </visual>
        <collision name="RR-leg-link41_collision">
            <origin xyz="-4.405364961712621e-15 -0.007967430604493 -0.004600000000000293" rpy="-2.1528358059330697 0.9290985520356033 0.883082812773521" />
            <geometry>
                <mesh filename="meshes/RR-leg-link41.stl" />
            </geometry>
        </collision>
    </link> -->



<joint name="Basic_Body_FL-Rigid" type="fixed">
        <origin xyz="-0.044000000000000004 -0.032 0.012000000000000028" rpy="3.141592653589793 -0.0 0.0" />
        <parent link="Basic_Body" />
        <child link="FL-Single-Motor1" />
    </joint>
    <joint name="FL-Single-Motor1_FL-Revolute_joint" type="revolute">
        <origin xyz="-0.034499999999999996 0.03925 0.016750000000000043" rpy="-1.5707963267948966 -0.0 0.0" />
        <parent link="FL-Single-Motor1" />
        <child link="FL-Double-Motor1" />
        <axis xyz="-1.0 0.0 7.806255641895643e-18" />
        <limit effort="5" lower="-1.570795" upper="1.570795" velocity="3.25"/>
        <dynamics damping="0" friction="0"/>

    </joint>
    <joint name="FL-Double-Motor1_FL-Motor-Link1_joint" type="revolute">
        <origin xyz="-0.08225 0.031400000000000004 0.054386399999999994" rpy="-1.5707963267948968 1.0785207688568522e-32 5.551115123125783e-17" />
        <parent link="FL-Double-Motor1" />
        <child link="FL-leg-link11" />
        <axis xyz="2.775557561562891e-17 -0.8660250000000002 0.4999999999999999" />
        <limit effort="5" lower="-1.570795" upper="1.570795" velocity="3.25"/>
        <dynamics damping="0" friction="0"/>
    </joint>
    <joint name="FL-leg-link11_FL-Link1-Link2_joint" type="revolute">
        <origin xyz="-0.08532916 -0.06154961999999999 -0.08377865" rpy="-0.7853981633974452 -0.0 -3.851859888774472e-33" />
        <parent link="FL-leg-link11" />
        <child link="FL-leg-link21" />
        <axis xyz="0.540447 -0.5649967029443643 -0.6234546347586148" />
        <limit effort="5" lower="-1.2" upper="0.4" velocity="3.25"/>
        <dynamics damping="0" friction="0"/>
    </joint>
    <!-- <joint name="FL-Double-Motor1_FL-Motor-Link4" type="revolute">
        <origin xyz="-0.08225 0.041000000000000016 0.07101408" rpy="-1.5707963267948968 1.0785207688568522e-32 5.551115123125783e-17" />
        <parent link="FL-Double-Motor1" />
        <child link="FL-leg-link41" />
        <axis xyz="2.775557561562891e-17 -0.866025 0.5" />
    </joint>
    <joint name="FL-leg-link41_FL-Link4-Link3" type="revolute">
        <origin xyz="0.009909659999999968 -0.06007759 -0.11962901" rpy="-0.7853981633974534 5.551115123125783e-17 -3.851859888774471e-33" />
        <parent link="FL-leg-link41" />
        <child link="FL-leg-link31" />
        <axis xyz="0.7045800000000001 0.6675540562740957 0.2407062193837161" />
    </joint>
    <joint name="FL-leg-link21_FL-Link2-Link3" type="revolute">
        <origin xyz="0.019425109999999995 0.10661083588181829 -0.07883614820728686" rpy="-2.1862760354652835 -0.523598775598294 2.5261129449194097" />
        <parent link="FL-leg-link21" />
        <child link="FL-leg-link31" />
        <axis xyz="-0.5376733898125287 0.17866800000000002 0.8240049671455295" />
    </joint> -->
    <joint name="Basic_Body_RL-Rigid" type="fixed">
        <origin xyz="0.044000000000000004 -0.032 0.012000000000000028" rpy="3.141592653589793 -0.0 0.0" />
        <parent link="Basic_Body" />
        <child link="RL-Single-Motor1" />
    </joint>
    <joint name="RL-Single-Motor1_RL-Revolute_joint" type="revolute">
        <origin xyz="0.034499999999999996 0.03925 0.016750000000000043" rpy="-1.5707963267948966 6.077163357286271e-64 0.0" />
        <parent link="RL-Single-Motor1" />
        <child link="RL-Double-Motor1" />
        <axis xyz="1.0 4.930380657631324e-32 -7.806255641895643e-18" />
        <limit effort="5" lower="-1.570795" upper="1.570795" velocity="3.25"/>
        <dynamics damping="0" friction="0"/>
    </joint>
    <joint name="RL-Double-Motor1_RL-Motor-Link1_joint" type="revolute">
        <origin xyz="0.08225 0.0280603 0.05618238" rpy="-1.5707963267948968 1.4791141972893971e-31 -1.8474149676157256e-47" />
        <parent link="RL-Double-Motor1" />
        <child link="RL-leg-link11" />
        <axis xyz="-1.3232510596358296e-31 -0.894624 0.4468199999999999" />
        <limit effort="5" lower="-1.570795" upper="1.570795" velocity="3.25"/>
        <dynamics damping="0" friction="0"/>
    </joint>
    <joint name="RL-leg-link11_RL-Link1-Link2_joint" type="revolute">
        <origin xyz="-0.04450177 -0.06669059999999999 -0.10798259000000002" rpy="-0.7853981633974452 5.551115123125783e-17 -1.4111326436170527e-31" />
        <parent link="RL-leg-link11" />
        <child link="RL-leg-link21" />
        <axis xyz="0.664463 -0.594142937358092 -0.4533028228949145" />
        <limit effort="5" lower="-1.2" upper="0.4" velocity="3.25"/>
        <dynamics damping="0" friction="0"/>
    </joint>
    <!-- <joint name="RL-Double-Motor1_RL-Motor-Link4" type="revolute">
        <origin xyz="0.08225 0.03663924999999999 0.07335915" rpy="-1.5707963267948968 1.4791141972893971e-31 -1.8474149676157256e-47" />
        <parent link="RL-Double-Motor1" />
        <child link="RL-leg-link41" />
        <axis xyz="-1.3232510596358296e-31 -0.894624 0.44682" />
    </joint>
    <joint name="RL-leg-link41_RL-Link4-Link3" type="revolute">
        <origin xyz="0.055349129999999996 -0.047565880000000005 -0.11266135" rpy="-0.7853981633974534 -5.551115123125783e-17 -1.4791141972893971e-31" />
        <parent link="RL-leg-link41" />
        <child link="RL-leg-link31" />
        <axis xyz="0.640856 0.5760968651954262 0.5073618434234122" />
    </joint>
    <joint name="RL-leg-link21_RL-Link2-Link3" type="revolute">
        <origin xyz="0.053980549999999995 0.10704380443500675 -0.05988378435424599" rpy="0.9553166181245095 -0.523598775598294 2.5261129449194093" />
        <parent link="RL-leg-link21" />
        <child link="RL-leg-link31" />
        <axis xyz="0.7022977479676944 0.2640149999999999 0.6611158490313971" />
    </joint> -->
    <joint name="Basic_Body_FR-Rigid" type="fixed">
        <origin xyz="-0.044000000000000004 0.029500000000000002 0.012000000000000028" rpy="3.141592653589793 -0.0 0.0" />
        <parent link="Basic_Body" />
        <child link="FR-Single-Motor1" />
    </joint>
    <joint name="FR-Single-Motor1_FR-Revolute_joint" type="revolute">
        <origin xyz="-0.034499999999999996 -0.03925 0.016750000000000043" rpy="-1.5707963267948966 -0.0 0.0" />
        <parent link="FR-Single-Motor1" />
        <child link="FR-Double-Motor1" />
        <axis xyz="-1.0 -2.465190328815662e-32 7.806255641895643e-18" />
        <limit effort="5" lower="-1.570795" upper="1.570795" velocity="3.25"/>
        <dynamics damping="0" friction="0"/>
    </joint>
    <joint name="FR-Double-Motor1_FR-Motor-Link1_joint" type="revolute">
        <origin xyz="-0.08225 0.031400000000000004 -0.054386399999999994" rpy="-1.5707963267948968 -6.93334779979405e-33 -5.551115123125783e-17" />
        <parent link="FR-Double-Motor1" />
        <child link="FR-leg-link11" />
        <axis xyz="-2.7755575615628914e-17 0.8660249999999999 0.5000000000000001" />
        <limit effort="5" lower="-1.570795" upper="1.570795" velocity="3.25"/>
        <dynamics damping="0" friction="0"/>
    </joint>
    <joint name="FR-leg-link11_FR-Link1-Link2_joint" type="revolute">
        <origin xyz="-0.09795199 0.05561083000000002 -0.07349235999999998" rpy="-2.356194490192348 -1.1102230246251565e-16 -5.551115123125785e-17" />
        <parent link="FR-leg-link11" />
        <child link="FR-leg-link21" />
        <axis xyz="0.47707499999999997 -0.5479299736736459 0.6871479851807744" />
        <limit effort="5" lower="-1.2" upper="0.4" velocity="3.25"/>
        <dynamics damping="0" friction="0"/>
    </joint>
    <!-- <joint name="FR-Double-Motor1_FR-Motor-Link4" type="revolute">
        <origin xyz="-0.08225 0.041000000000000016 -0.07101408" rpy="-1.5707963267948968 -6.93334779979405e-33 -5.551115123125783e-17" />
        <parent link="FR-Double-Motor1" />
        <child link="FR-leg-link41" />
        <axis xyz="-2.7755575615628914e-17 0.866025 0.5" />
    </joint>
    <joint name="FR-leg-link41_FR-Link4-Link3" type="revolute">
        <origin xyz="-0.007422009999999979 0.060158200000000016 -0.11976863000000001" rpy="-2.35619449019234 -5.551115123125783e-17 1.1102230246251568e-16" />
        <parent link="FR-leg-link41" />
        <child link="FR-leg-link31" />
        <axis xyz="0.7063949999999998 0.6912195060268473 -0.15238292555926752" />
    </joint>
    <joint name="FR-leg-link21_FR-Link2-Link3" type="revolute">
        <origin xyz="0.0058727100000000474 0.10703515651907282 0.08041971384375421" rpy="2.1862760354652835 -0.5235987755982939 -2.5261129449194093" />
        <parent link="FR-leg-link21" />
        <child link="FR-leg-link31" />
        <axis xyz="0.8697469977137005 0.15142800000000003 -0.4696914367624818" />
    </joint> -->
    <joint name="Basic_Body_RR-Rigid" type="fixed">
        <origin xyz="0.044000000000000004 0.029500000000000002 0.012000000000000028" rpy="3.141592653589793 -0.0 0.0" />
        <parent link="Basic_Body" />
        <child link="RR-Single-Motor1" />
    </joint>
    <joint name="RR-Single-Motor1_RR-Revolute_joint" type="revolute">
        <origin xyz="0.034499999999999996 -0.03925 0.016750000000000043" rpy="-1.5707963267948966 -0.0 0.0" />
        <parent link="RR-Single-Motor1" />
        <child link="RR-Double-Motor1" />
        <axis xyz="0.9999999999999999 -3.851859888774472e-34 0.0" />
        <limit effort="5" lower="-1.570795" upper="1.570795" velocity="3.25"/>
        <dynamics damping="0" friction="0"/>

    </joint>
    <joint name="RR-Double-Motor1_RR-Motor-Link1_joint" type="revolute">
        <origin xyz="0.08224999999999998 0.031400000000000004 -0.05438639999999999" rpy="-1.5707963267948968 -4.9303806576313227e-32 6.07716335728627e-64" />
        <parent link="RR-Double-Motor1" />
        <child link="RR-leg-link11" />
        <axis xyz="-4.2698329090251674e-32 0.8660249999999999 0.5000000000000002" />
        <limit effort="5" lower="-1.570795" upper="1.570795" velocity="3.25"/>
        <dynamics damping="0" friction="0"/>
    </joint>
    <joint name="RR-leg-link11_RR-Link1-Link2_joint" type="revolute">
        <origin xyz="-0.05034087999999999 0.07198128000000002 -0.10184681999999995" rpy="-2.356194490192348 -5.551115123125783e-17 4.250565120907878e-32" />
        <parent link="RR-leg-link11" />
        <child link="RR-leg-link21" />
        <axis xyz="0.652478 -0.6124768019806968 0.44625721092717185" />
        <limit effort="5" lower="-1.2" upper="0.4" velocity="3.25"/>
        <dynamics damping="0" friction="0"/>
    </joint>
    <!-- <joint name="RR-Double-Motor1_Revolute_45" type="revolute">
        <origin xyz="0.08224999999999998 0.041000000000000016 -0.07101407999999998" rpy="-1.5707963267948966 -4.9303806576313227e-32 6.07716335728627e-64" />
        <parent link="RR-Double-Motor1" />
        <child link="RR-leg-link41" />
        <axis xyz="-4.2698329090251674e-32 0.866025 0.5000000000000001" />
    </joint>
    <joint name="RR-leg-link41_Revolute_46" type="revolute">
        <origin xyz="0.04960471999999999 0.05550153000000002 -0.11170303999999995" rpy="-2.35619449019234 5.551115123125783e-17 4.930380657631324e-32" />
        <parent link="RR-leg-link41" />
        <child link="RR-leg-link31" />
        <axis xyz="0.65408 0.6134773580760723 -0.4425215658021684" />
    </joint>
    <joint name="RR-leg-link21_Revolute_47" type="revolute">
        <origin xyz="0.049697599999999974 0.10385966724398457 0.0685686607596101" rpy="2.1862760354652835 -0.5235987755982938 -2.5261129449194093" />
        <parent link="RR-leg-link21" />
        <child link="RR-leg-link31" />
        <axis xyz="0.693352140078903 0.20589499999999997 -0.6905576540796612" />
    </joint> -->







    <!-- <joint name="Body1_FL-Rigid" type="fixed">
        <origin xyz="-0.044000000000000004 -0.032 0.012000000000000028" rpy="3.141592653589793 -0.0 0.0" />
        <parent link="Body1" />
        <child link="FL-Single-Motor1" />
    </joint>
    <joint name="FL-Single-Motor1_FL-Revolute" type="continuous">
        <origin xyz="-0.034499999999999996 0.03925 0.016750000000000043" rpy="-1.5707963267948966 -0.0 0.0" />
        <parent link="FL-Single-Motor1" />
        <child link="FL-Double-Motor1" />
        <axis xyz="-1.0 0.0 7.806255641895643e-18" />
    </joint>
    <joint name="FL-Double-Motor1_FL-Motor-Link1" type="continuous">
        <origin xyz="-0.08225 0.031400000000000004 0.054386399999999994" rpy="-1.5707963267948968 1.0785207688568522e-32 5.551115123125783e-17" />
        <parent link="FL-Double-Motor1" />
        <child link="FL-leg-link11" />
        <axis xyz="2.775557561562891e-17 -0.8660250000000002 0.4999999999999999" />
    </joint>
    <joint name="FL-leg-link11_FL-Link1-Link2" type="continuous">
        <origin xyz="-0.08532916 -0.06154961999999999 -0.08377865" rpy="-0.7853981633974452 -0.0 -3.851859888774472e-33" />
        <parent link="FL-leg-link11" />
        <child link="FL-leg-link21" />
        <axis xyz="0.540447 -0.5649967029443643 -0.6234546347586148" />
    </joint>
    <joint name="FL-Double-Motor1_FL-Motor-Link4" type="continuous">
        <origin xyz="-0.08225 0.041000000000000016 0.07101408" rpy="-1.5707963267948968 1.0785207688568522e-32 5.551115123125783e-17" />
        <parent link="FL-Double-Motor1" />
        <child link="FL-leg-link41" />
        <axis xyz="2.775557561562891e-17 -0.866025 0.5" />
    </joint>
    <joint name="FL-leg-link41_FL-Link4-Link3" type="continuous">
        <origin xyz="0.009909659999999968 -0.06007759 -0.11962901" rpy="-0.7853981633974534 5.551115123125783e-17 -3.851859888774471e-33" />
        <parent link="FL-leg-link41" />
        <child link="FL-leg-link31" />
        <axis xyz="0.7045800000000001 0.6675540562740957 0.2407062193837161" />
    </joint>
    <joint name="FL-leg-link21_FL-Link2-Link3" type="continuous">
        <origin xyz="0.019425109999999995 0.10661083588181829 -0.07883614820728686" rpy="-2.1862760354652835 -0.523598775598294 2.5261129449194097" />
        <parent link="FL-leg-link21" />
        <child link="FL-leg-link31" />
        <axis xyz="-0.5376733898125287 0.17866800000000002 0.8240049671455295" />
    </joint>
    <joint name="Body1_RL-Rigid" type="fixed">
        <origin xyz="0.044000000000000004 -0.032 0.012000000000000028" rpy="3.141592653589793 -0.0 0.0" />
        <parent link="Body1" />
        <child link="RL-Single-Motor1" />
    </joint>
    <joint name="RL-Single-Motor1_RL-Revolute" type="continuous">
        <origin xyz="0.034499999999999996 0.03925 0.016750000000000043" rpy="-1.5707963267948966 6.077163357286271e-64 0.0" />
        <parent link="RL-Single-Motor1" />
        <child link="RL-Double-Motor1" />
        <axis xyz="1.0 4.930380657631324e-32 -7.806255641895643e-18" />
    </joint>
    <joint name="RL-Double-Motor1_RL-Motor-Link1" type="continuous">
        <origin xyz="0.08225 0.0280603 0.05618238" rpy="-1.5707963267948968 1.4791141972893971e-31 -1.8474149676157256e-47" />
        <parent link="RL-Double-Motor1" />
        <child link="RL-leg-link11" />
        <axis xyz="-1.3232510596358296e-31 -0.894624 0.4468199999999999" />
    </joint>
    <joint name="RL-leg-link11_RL-Link1-Link2" type="continuous">
        <origin xyz="-0.04450177 -0.06669059999999999 -0.10798259000000002" rpy="-0.7853981633974452 5.551115123125783e-17 -1.4111326436170527e-31" />
        <parent link="RL-leg-link11" />
        <child link="RL-leg-link21" />
        <axis xyz="0.664463 -0.594142937358092 -0.4533028228949145" />
    </joint>
    <joint name="RL-Double-Motor1_RL-Motor-Link4" type="continuous">
        <origin xyz="0.08225 0.03663924999999999 0.07335915" rpy="-1.5707963267948968 1.4791141972893971e-31 -1.8474149676157256e-47" />
        <parent link="RL-Double-Motor1" />
        <child link="RL-leg-link41" />
        <axis xyz="-1.3232510596358296e-31 -0.894624 0.44682" />
    </joint>
    <joint name="RL-leg-link41_RL-Link4-Link3" type="continuous">
        <origin xyz="0.055349129999999996 -0.047565880000000005 -0.11266135" rpy="-0.7853981633974534 -5.551115123125783e-17 -1.4791141972893971e-31" />
        <parent link="RL-leg-link41" />
        <child link="RL-leg-link31" />
        <axis xyz="0.640856 0.5760968651954262 0.5073618434234122" />
    </joint>
    <joint name="RL-leg-link21_RL-Link2-Link3" type="continuous">
        <origin xyz="0.053980549999999995 0.10704380443500675 -0.05988378435424599" rpy="0.9553166181245095 -0.523598775598294 2.5261129449194093" />
        <parent link="RL-leg-link21" />
        <child link="RL-leg-link31" />
        <axis xyz="0.7022977479676944 0.2640149999999999 0.6611158490313971" />
    </joint>
    <joint name="Body1_FR-Rigid" type="fixed">
        <origin xyz="-0.044000000000000004 0.029500000000000002 0.012000000000000028" rpy="3.141592653589793 -0.0 0.0" />
        <parent link="Body1" />
        <child link="FR-Single-Motor1" />
    </joint>
    <joint name="FR-Single-Motor1_FR-Revolute" type="continuous">
        <origin xyz="-0.034499999999999996 -0.03925 0.016750000000000043" rpy="-1.5707963267948966 -0.0 0.0" />
        <parent link="FR-Single-Motor1" />
        <child link="FR-Double-Motor1" />
        <axis xyz="-1.0 -2.465190328815662e-32 7.806255641895643e-18" />
    </joint>
    <joint name="FR-Double-Motor1_FR-Motor-Link1" type="continuous">
        <origin xyz="-0.08225 0.031400000000000004 -0.054386399999999994" rpy="-1.5707963267948968 -6.93334779979405e-33 -5.551115123125783e-17" />
        <parent link="FR-Double-Motor1" />
        <child link="FR-leg-link11" />
        <axis xyz="-2.7755575615628914e-17 0.8660249999999999 0.5000000000000001" />
    </joint>
    <joint name="FR-leg-link11_FR-Link1-Link2" type="continuous">
        <origin xyz="-0.09795199 0.05561083000000002 -0.07349235999999998" rpy="-2.356194490192348 -1.1102230246251565e-16 -5.551115123125785e-17" />
        <parent link="FR-leg-link11" />
        <child link="FR-leg-link21" />
        <axis xyz="0.47707499999999997 -0.5479299736736459 0.6871479851807744" />
    </joint>
    <joint name="FR-Double-Motor1_FR-Motor-Link4" type="continuous">
        <origin xyz="-0.08225 0.041000000000000016 -0.07101408" rpy="-1.5707963267948968 -6.93334779979405e-33 -5.551115123125783e-17" />
        <parent link="FR-Double-Motor1" />
        <child link="FR-leg-link41" />
        <axis xyz="-2.7755575615628914e-17 0.866025 0.5" />
    </joint>
    <joint name="FR-leg-link41_FR-Link4-Link3" type="continuous">
        <origin xyz="-0.007422009999999979 0.060158200000000016 -0.11976863000000001" rpy="-2.35619449019234 -5.551115123125783e-17 1.1102230246251568e-16" />
        <parent link="FR-leg-link41" />
        <child link="FR-leg-link31" />
        <axis xyz="0.7063949999999998 0.6912195060268473 -0.15238292555926752" />
    </joint>
    <joint name="FR-leg-link21_FR-Link2-Link3" type="continuous">
        <origin xyz="0.0058727100000000474 0.10703515651907282 0.08041971384375421" rpy="2.1862760354652835 -0.5235987755982939 -2.5261129449194093" />
        <parent link="FR-leg-link21" />
        <child link="FR-leg-link31" />
        <axis xyz="0.8697469977137005 0.15142800000000003 -0.4696914367624818" />
    </joint>
    <joint name="Body1_RR-Rigid" type="fixed">
        <origin xyz="0.044000000000000004 0.029500000000000002 0.012000000000000028" rpy="3.141592653589793 -0.0 0.0" />
        <parent link="Body1" />
        <child link="RR-Single-Motor1" />
    </joint>
    <joint name="RR-Single-Motor1_RR-Revolute" type="continuous">
        <origin xyz="0.034499999999999996 -0.03925 0.016750000000000043" rpy="-1.5707963267948966 -0.0 0.0" />
        <parent link="RR-Single-Motor1" />
        <child link="RR-Double-Motor1" />
        <axis xyz="0.9999999999999999 -3.851859888774472e-34 0.0" />
    </joint>
    <joint name="RR-Double-Motor1_RR-Motor-Link1" type="continuous">
        <origin xyz="0.08224999999999998 0.031400000000000004 -0.05438639999999999" rpy="-1.5707963267948968 -4.9303806576313227e-32 6.07716335728627e-64" />
        <parent link="RR-Double-Motor1" />
        <child link="RR-leg-link11" />
        <axis xyz="-4.2698329090251674e-32 0.8660249999999999 0.5000000000000002" />
    </joint>
    <joint name="RR-leg-link11_RR-Link1-Link2" type="continuous">
        <origin xyz="-0.05034087999999999 0.07198128000000002 -0.10184681999999995" rpy="-2.356194490192348 -5.551115123125783e-17 4.250565120907878e-32" />
        <parent link="RR-leg-link11" />
        <child link="RR-leg-link21" />
        <axis xyz="0.652478 -0.6124768019806968 0.44625721092717185" />
    </joint>
    <joint name="RR-Double-Motor1_Revolute_45" type="continuous">
        <origin xyz="0.08224999999999998 0.041000000000000016 -0.07101407999999998" rpy="-1.5707963267948966 -4.9303806576313227e-32 6.07716335728627e-64" />
        <parent link="RR-Double-Motor1" />
        <child link="RR-leg-link41" />
        <axis xyz="-4.2698329090251674e-32 0.866025 0.5000000000000001" />
    </joint>
    <joint name="RR-leg-link41_Revolute_46" type="continuous">
        <origin xyz="0.04960471999999999 0.05550153000000002 -0.11170303999999995" rpy="-2.35619449019234 5.551115123125783e-17 4.930380657631324e-32" />
        <parent link="RR-leg-link41" />
        <child link="RR-leg-link31" />
        <axis xyz="0.65408 0.6134773580760723 -0.4425215658021684" />
    </joint>
    <joint name="RR-leg-link21_Revolute_47" type="continuous">
        <origin xyz="0.049697599999999974 0.10385966724398457 0.0685686607596101" rpy="2.1862760354652835 -0.5235987755982938 -2.5261129449194093" />
        <parent link="RR-leg-link21" />
        <child link="RR-leg-link31" />
        <axis xyz="0.693352140078903 0.20589499999999997 -0.6905576540796612" />
    </joint> -->
</robot>