<?xml version='1.0' encoding='utf-8'?>
<robot name="Quadruped-IsaacSim">
    <link name="Body1">
        <inertial>
            <origin xyz="3.2699753365527856e-11 -0.0012499987421279188 -0.004750000038203694" rpy="0.0 0.0 0.0" />
            <mass value="0.5223502772293394" />
            <inertia ixx="0.000774574690005525" iyy="0.011438778897726667" izz="0.01205863802906395" ixy="-1.1564890962261062e-10" iyz="3.863476379095676e-13" ixz="2.9993621752067147e-12" />
        </inertial>
        <visual name="Body1_visual">
            <origin xyz="0.0 0.0 0.0" rpy="0.0 0.0 0.0" />
            <geometry>
                <mesh filename="meshes/Body1.stl" />
            </geometry>
        </visual>
        <collision name="Body1_collision">
            <origin xyz="0.0 0.0 0.0" rpy="0.0 0.0 0.0" />
            <geometry>
                <mesh filename="meshes/Body1.stl" />
            </geometry>
        </collision>
    </link>
    <link name="FL-Single-Motor1">
        <inertial>
            <origin xyz="-0.008058511743548396 0.024291032753734853 0.016750000002170324" rpy="0.0 -0.0 0.0" />
            <mass value="0.18505114928963637" />
            <inertia ixx="6.927157374956791e-05" iyy="5.2779060673292105e-05" izz="8.852045695425213e-05" ixy="1.5973926095205152e-07" iyz="4.3619621803436814e-15" ixz="1.0601762523432257e-14" />
        </inertial>
        <visual name="FL-Single-Motor1_visual">
            <origin xyz="-0.041749999999999954 0.039250000000000014 0.016749999999999973" rpy="-1.5707963267948968 -1.5707963267948966 0" />
            <geometry>
                <mesh filename="meshes/FL-Single-Motor1.stl" />
            </geometry>
        </visual>
        <collision name="FL-Single-Motor1_collision">
            <origin xyz="-0.041749999999999954 0.039250000000000014 0.016749999999999973" rpy="-1.5707963267948968 -1.5707963267948966 0" />
            <geometry>
                <mesh filename="meshes/FL-Single-Motor1.stl" />
            </geometry>
        </collision>
    </link>
    <link name="FL-Double-Motor1">
        <inertial>
            <origin xyz="-0.06716414766997797 0.00542494091347443 0.009451637209221975" rpy="0.0 -0.0 0.0" />
            <mass value="0.4782524941626558" />
            <inertia ixx="0.0003096692588512723" iyy="0.0008123248398218923" izz="0.0007226948848486764" ixy="-1.8409934400207006e-07" iyz="-7.691806622294427e-05" ixz="-7.498838760300702e-07" />
        </inertial>
        <visual name="FL-Double-Motor1_visual">
            <origin xyz="-0.08224999999999996 7.105427357601002e-17 1.7763568394002505e-17" rpy="7.351718556377353e-17 -0.5235987755982987 -1.5707963267948966" />
            <geometry>
                <mesh filename="meshes/FL-Double-Motor1.stl" />
            </geometry>
        </visual>
        <collision name="FL-Double-Motor1_collision">
            <origin xyz="-0.08224999999999996 7.105427357601002e-17 1.7763568394002505e-17" rpy="7.351718556377353e-17 -0.5235987755982987 -1.5707963267948966" />
            <geometry>
                <mesh filename="meshes/FL-Double-Motor1.stl" />
            </geometry>
        </collision>
    </link>
    <link name="FL-leg-link11">
        <inertial>
            <origin xyz="-0.026588560878802882 -0.028324789411553065 -0.0368242708699578" rpy="0.0 -0.0 0.0" />
            <mass value="0.04770813454279477" />
            <inertia ixx="8.040332324354971e-05" iyy="8.425272099893757e-05" izz="5.354180778901303e-05" ixy="-2.4582447605551354e-05" iyz="-3.624530825031661e-05" ixz="-3.6379365717220415e-05" />
        </inertial>
        <visual name="FL-leg-link11_visual">
            <origin xyz="1.7763568394002506e-16 -0.008660249395506962 0.005000000000000071" rpy="2.2845207057396624 -0.8480620789814812 0.7137243789447658" />
            <geometry>
                <mesh filename="meshes/FL-leg-link11.stl" />
            </geometry>
        </visual>
        <collision name="FL-leg-link11_collision">
            <origin xyz="1.7763568394002506e-16 -0.008660249395506962 0.005000000000000071" rpy="2.2845207057396624 -0.8480620789814812 0.7137243789447658" />
            <geometry>
                <mesh filename="meshes/FL-leg-link11.stl" />
            </geometry>
        </collision>
    </link>
    <link name="FL-leg-link31">
        <inertial>
            <origin xyz="-0.01905310207636772 0.05624531640513162 -0.037950671970839685" rpy="0.0 -0.0 0.0" />
            <mass value="0.030992351814191726" />
            <inertia ixx="4.6664070107512744e-05" iyy="2.3197876303545025e-05" izz="4.920114531297527e-05" ixy="1.8854772742317104e-05" iyz="1.776100160983163e-05" ixz="-8.713360876029642e-06" />
        </inertial>
        <visual name="FL-leg-link31_visual">
            <origin xyz="0.0013660220437389902 0.001271289564623217 0.000719584063776857" rpy="2.468049454150982 -0.9559805418721182 2.897999431670401" />
            <geometry>
                <mesh filename="meshes/FL-leg-link31.stl" />
            </geometry>
        </visual>
        <collision name="FL-leg-link31_collision">
            <origin xyz="0.0013660220437389902 0.001271289564623217 0.000719584063776857" rpy="2.468049454150982 -0.9559805418721182 2.897999431670401" />
            <geometry>
                <mesh filename="meshes/FL-leg-link31.stl" />
            </geometry>
        </collision>
    </link>
    <link name="FL-leg-link41">
        <inertial>
            <origin xyz="0.01484196064111952 -0.025382742577815167 -0.04879374594474811" rpy="0.0 -0.0 2.993496475303259e-49" />
            <mass value="0.049054688661482895" />
            <inertia ixx="0.00010194266572326541" iyy="9.510583647386397e-05" izz="2.5960160303558407e-05" ixy="1.043292056902194e-05" iyz="-3.5976034441175236e-05" ixz="2.4370471622598294e-05" />
        </inertial>
        <visual name="FL-leg-link41_visual">
            <origin xyz="-3.552713678800501e-17 0.007967430604493035 -0.0045999999999999375" rpy="-1.1493672327759905 0.9908942382701876 -1.078844115453079" />
            <geometry>
                <mesh filename="meshes/FL-leg-link41.stl" />
            </geometry>
        </visual>
        <collision name="FL-leg-link41_collision">
            <origin xyz="-3.552713678800501e-17 0.007967430604493035 -0.0045999999999999375" rpy="-1.1493672327759905 0.9908942382701876 -1.078844115453079" />
            <geometry>
                <mesh filename="meshes/FL-leg-link41.stl" />
            </geometry>
        </collision>
    </link>
    <link name="FL-leg-link21">
        <inertial>
            <origin xyz="0.02012448107328126 0.05938157219213881 -0.03965709281085294" rpy="0.0 -0.0 0.0" />
            <mass value="0.03786194092058064" />
            <inertia ixx="8.204825132324814e-05" iyy="3.5584080832527056e-05" izz="6.387739170150773e-05" ixy="-2.0181734380460142e-05" iyz="3.77243708234825e-05" ixz="1.3947319939547939e-05" />
        </inertial>
        <visual name="FL-leg-link21_visual">
            <origin xyz="-0.00122473999999972 0.001183009833485187 0.0010490413827217537" rpy="0.7641112300261985 -0.7104171459055233 0.24415811797886197" />
            <geometry>
                <mesh filename="meshes/FL-leg-link21.stl" />
            </geometry>
        </visual>
        <collision name="FL-leg-link21_collision">
            <origin xyz="-0.00122473999999972 0.001183009833485187 0.0010490413827217537" rpy="0.7641112300261985 -0.7104171459055233 0.24415811797886197" />
            <geometry>
                <mesh filename="meshes/FL-leg-link21.stl" />
            </geometry>
        </collision>
    </link>
    <link name="RL-Single-Motor1">
        <inertial>
            <origin xyz="0.00805851174354844 0.024291032753734853 0.01674999999782983" rpy="0.0 -0.0 0.0" />
            <mass value="0.18505114928963637" />
            <inertia ixx="6.92715737496026e-05" iyy="5.27790606733268e-05" izz="8.852045695425127e-05" ixy="-1.59739260951401e-07" iyz="-4.361094818605693e-15" ixz="1.0604364608646222e-14" />
        </inertial>
        <visual name="RL-Single-Motor1_visual">
            <origin xyz="0.04174999999999999 0.03925 0.016750000000000043" rpy="-1.5707963267948966 1.5707963267948966 0" />
            <geometry>
                <mesh filename="meshes/RL-Single-Motor1.stl" />
            </geometry>
        </visual>
        <collision name="RL-Single-Motor1_collision">
            <origin xyz="0.04174999999999999 0.03925 0.016750000000000043" rpy="-1.5707963267948966 1.5707963267948966 0" />
            <geometry>
                <mesh filename="meshes/RL-Single-Motor1.stl" />
            </geometry>
        </collision>
    </link>
    <link name="RL-Double-Motor1">
        <inertial>
            <origin xyz="0.06716414766997804 0.005472887473803425 0.009423955249709213" rpy="0.0 -0.0 0.0" />
            <mass value="0.4782524941626558" />
            <inertia ixx="0.0003096692588512723" iyy="0.000811715372951034" izz="0.0007233043517195503" ixy="5.573688145257828e-07" iyz="-7.726994208490275e-05" ixz="5.343766467458588e-07" />
        </inertial>
        <visual name="RL-Double-Motor1_visual">
            <origin xyz="0.08224999999999996 7.105427357601002e-17 -1.2434497875801754e-16" rpy="2.078412398804128e-15 0.5235987755982988 1.5707963267948972" />
            <geometry>
                <mesh filename="meshes/RL-Double-Motor1.stl" />
            </geometry>
        </visual>
        <collision name="RL-Double-Motor1_collision">
            <origin xyz="0.08224999999999996 7.105427357601002e-17 -1.2434497875801754e-16" rpy="2.078412398804128e-15 0.5235987755982988 1.5707963267948972" />
            <geometry>
                <mesh filename="meshes/RL-Double-Motor1.stl" />
            </geometry>
        </collision>
    </link>
    <link name="RL-leg-link11">
        <inertial>
            <origin xyz="-0.01818757513468505 -0.030283491560390594 -0.04021684250863885" rpy="0.0 -0.0 0.0" />
            <mass value="0.04770813454279477" />
            <inertia ixx="9.38577026527148e-05" iyy="8.048651015888503e-05" izz="4.3853639219900036e-05" ixy="-1.8171262861201755e-05" iyz="-4.2303675879477e-05" ixz="-2.7044549867742428e-05" />
        </inertial>
        <visual name="RL-leg-link11_visual">
            <origin xyz="2.486899575160351e-16 -0.008660249395506874 0.005000000000000285" rpy="2.105606086054014 -0.95065732066285 0.9415634402058406" />
            <geometry>
                <mesh filename="meshes/RL-leg-link11.stl" />
            </geometry>
        </visual>
        <collision name="RL-leg-link11_collision">
            <origin xyz="2.486899575160351e-16 -0.008660249395506874 0.005000000000000285" rpy="2.105606086054014 -0.95065732066285 0.9415634402058406" />
            <geometry>
                <mesh filename="meshes/RL-leg-link11.stl" />
            </geometry>
        </collision>
    </link>
    <link name="RL-leg-link31">
        <inertial>
            <origin xyz="-0.009870261189729704 0.05690024836879438 -0.04039492088141941" rpy="0.0 -0.0 0.0" />
            <mass value="0.030992351814191726" />
            <inertia ixx="5.096791650977895e-05" iyy="2.1690330766858775e-05" izz="4.640484444739298e-05" ixy="1.4384862073703142e-05" iyz="2.0948753158010893e-05" ixz="-7.649464180305467e-06" />
        </inertial>
        <visual name="RL-leg-link31_visual">
            <origin xyz="0.0012817170732536808 0.001211333935894885 0.0009433319697017773" rpy="2.4051505190755647 -0.7922522618340522 2.901130343152301" />
            <geometry>
                <mesh filename="meshes/RL-leg-link31.stl" />
            </geometry>
        </visual>
        <collision name="RL-leg-link31_collision">
            <origin xyz="0.0012817170732536808 0.001211333935894885 0.0009433319697017773" rpy="2.4051505190755647 -0.7922522618340522 2.901130343152301" />
            <geometry>
                <mesh filename="meshes/RL-leg-link31.stl" />
            </geometry>
        </collision>
    </link>
    <link name="RL-leg-link41">
        <inertial>
            <origin xyz="0.024158096806667615 -0.02367671112604448 -0.04583881279097092" rpy="0.0 -0.0 0.0" />
            <mass value="0.049054688661482895" />
            <inertia ixx="9.023066630052534e-05" iyy="9.740285502762326e-05" izz="3.5375141172549595e-05" ixy="1.5565954846623797e-05" iyz="-3.1268887151095735e-05" ixz="3.7316646857202696e-05" />
        </inertial>
        <visual name="RL-leg-link41_visual">
            <origin xyz="2.1316282072803005e-16 0.007967430604492929 -0.0045999999999999375" rpy="-0.938917503384533 0.9025114294229069 -0.8202511401795605" />
            <geometry>
                <mesh filename="meshes/RL-leg-link41.stl" />
            </geometry>
        </visual>
        <collision name="RL-leg-link41_collision">
            <origin xyz="2.1316282072803005e-16 0.007967430604492929 -0.0045999999999999375" rpy="-0.938917503384533 0.9025114294229069 -0.8202511401795605" />
            <geometry>
                <mesh filename="meshes/RL-leg-link41.stl" />
            </geometry>
        </collision>
    </link>
    <link name="RL-leg-link21">
        <inertial>
            <origin xyz="0.029139284884754917 0.058266056254820175 -0.03549393881780835" rpy="0.0 -0.0 0.0" />
            <mass value="0.03786194092058064" />
            <inertia ixx="7.448018286321028e-05" iyy="3.777207600386133e-05" izz="6.925746499021093e-05" ixy="-2.8046064299782884e-05" iyz="3.29207231039545e-05" ixz="1.756480597818023e-05" />
        </inertial>
        <visual name="RL-leg-link21_visual">
            <origin xyz="-0.0013289292056403745 0.001240834029132074 0.0008332303849794621" rpy="0.7066322582640221 -0.8741311024215515 0.23994368519397818" />
            <geometry>
                <mesh filename="meshes/RL-leg-link21.stl" />
            </geometry>
        </visual>
        <collision name="RL-leg-link21_collision">
            <origin xyz="-0.0013289292056403745 0.001240834029132074 0.0008332303849794621" rpy="0.7066322582640221 -0.8741311024215515 0.23994368519397818" />
            <geometry>
                <mesh filename="meshes/RL-leg-link21.stl" />
            </geometry>
        </collision>
    </link>
    <link name="FR-Single-Motor1">
        <inertial>
            <origin xyz="-0.008058511743548396 -0.02429103275373481 0.016749999997829692" rpy="0.0 -0.0 0.0" />
            <mass value="0.18505114928963637" />
            <inertia ixx="6.92715737495922e-05" iyy="5.277906067331986e-05" izz="8.852045695425062e-05" ixy="-1.5973926095205152e-07" iyz="4.361094818605693e-15" ixz="-1.0603497246908233e-14" />
        </inertial>
        <visual name="FR-Single-Motor1_visual">
            <origin xyz="-0.04174999999999992 -0.03924999999999997 0.016749999999999973" rpy="1.5707963267948966 1.5707963267948966 0" />
            <geometry>
                <mesh filename="meshes/FR-Single-Motor1.stl" />
            </geometry>
        </visual>
        <collision name="FR-Single-Motor1_collision">
            <origin xyz="-0.04174999999999992 -0.03924999999999997 0.016749999999999973" rpy="1.5707963267948966 1.5707963267948966 0" />
            <geometry>
                <mesh filename="meshes/FR-Single-Motor1.stl" />
            </geometry>
        </collision>
    </link>
    <link name="FR-Double-Motor1">
        <inertial>
            <origin xyz="-0.06716414766997794 0.005472887473803354 -0.009423955249709124" rpy="0.0 -0.0 0.0" />
            <mass value="0.4782524941626558" />
            <inertia ixx="0.00030966925885123064" iyy="0.0008117153729510305" izz="0.0007233043517194948" ixy="-5.573688145396604e-07" iyz="7.726994208490101e-05" ixz="5.343766467432569e-07" />
        </inertial>
        <visual name="FR-Double-Motor1_visual">
            <origin xyz="-0.08224999999999989 -1.4210854715202004e-16 1.7763568394002506e-16" rpy="-3.141592653589793 -0.5235987755982989 1.570796326794897" />
            <geometry>
                <mesh filename="meshes/FR-Double-Motor1.stl" />
            </geometry>
        </visual>
        <collision name="FR-Double-Motor1_collision">
            <origin xyz="-0.08224999999999989 -1.4210854715202004e-16 1.7763568394002506e-16" rpy="-3.141592653589793 -0.5235987755982989 1.570796326794897" />
            <geometry>
                <mesh filename="meshes/FR-Double-Motor1.stl" />
            </geometry>
        </collision>
    </link>
    <link name="FR-leg-link11">
        <inertial>
            <origin xyz="-0.026588560878794104 0.028324789411539958 -0.03682427086993464" rpy="0.0 -0.0 0.0" />
            <mass value="0.047708134542766116" />
            <inertia ixx="8.040332324348726e-05" iyy="8.425272099888553e-05" izz="5.3541807788991345e-05" ixy="2.458244760554073e-05" iyz="3.6245308250291905e-05" ixz="-3.637936571720175e-05" />
        </inertial>
        <visual name="FR-leg-link11_visual">
            <origin xyz="-1.0658141036401502e-16 0.008660249395506928 0.004999999999999929" rpy="0.8570719478501317 -0.8480620789814808 -0.7137243789447646" />
            <geometry>
                <mesh filename="meshes/FR-leg-link11.stl" />
            </geometry>
        </visual>
        <collision name="FR-leg-link11_collision">
            <origin xyz="-1.0658141036401502e-16 0.008660249395506928 0.004999999999999929" rpy="0.8570719478501317 -0.8480620789814808 -0.7137243789447646" />
            <geometry>
                <mesh filename="meshes/FR-leg-link11.stl" />
            </geometry>
        </collision>
    </link>
    <link name="FR-leg-link21">
        <inertial>
            <origin xyz="0.020124481066181376 0.059381572190366966 0.03965709281714366" rpy="0.0 -0.0 0.0" />
            <mass value="0.03786194092058894" />
            <inertia ixx="8.204825132820514e-05" iyy="3.5584080835806775e-05" izz="6.387739169339293e-05" ixy="-2.0181734373289073e-05" iyz="-3.772437082827056e-05" ixz="-1.394731993719296e-05" />
        </inertial>
        <visual name="FR-leg-link21_visual">
            <origin xyz="-0.001224739999999791 0.0011830098334851158 -0.0010490413827219313" rpy="-0.7641112299487501 0.7104171458115766 0.24415811809762278" />
            <geometry>
                <mesh filename="meshes/FR-leg-link21.stl" />
            </geometry>
        </visual>
        <collision name="FR-leg-link21_collision">
            <origin xyz="-0.001224739999999791 0.0011830098334851158 -0.0010490413827219313" rpy="-0.7641112299487501 0.7104171458115766 0.24415811809762278" />
            <geometry>
                <mesh filename="meshes/FR-leg-link21.stl" />
            </geometry>
        </collision>
    </link>
    <link name="FR-leg-link31">
        <inertial>
            <origin xyz="-0.01905310208430988 0.056245316406550505 0.037950671981707026" rpy="0.0 -0.0 0.0" />
            <mass value="0.030992351814247344" />
            <inertia ixx="4.666407010375708e-05" iyy="2.319787630919015e-05" izz="4.920114531166415e-05" ixy="1.885477274448457e-05" iyz="-1.7761001609722475e-05" ixz="8.713360878459256e-06" />
        </inertial>
        <visual name="FR-leg-link31_visual">
            <origin xyz="0.001366022042506696 0.0012712895705325167 -0.0007195840556747513" rpy="-2.4680494543172267 0.9559805419275919 2.8979994316028486" />
            <geometry>
                <mesh filename="meshes/FR-leg-link31.stl" />
            </geometry>
        </visual>
        <collision name="FR-leg-link31_collision">
            <origin xyz="0.001366022042506696 0.0012712895705325167 -0.0007195840556747513" rpy="-2.4680494543172267 0.9559805419275919 2.8979994316028486" />
            <geometry>
                <mesh filename="meshes/FR-leg-link31.stl" />
            </geometry>
        </collision>
    </link>
    <link name="FR-leg-link41">
        <inertial>
            <origin xyz="0.014841788781676168 0.02538275219326664 -0.04879374649240319" rpy="0.0 -0.0 0.0" />
            <mass value="0.04905477511303801" />
            <inertia ixx="0.0001019427444813887" iyy="9.510576097386883e-05" izz="2.596005091457616e-05" ixy="-1.0433009045056386e-05" iyz="3.5976067533053865e-05" ixz="2.4370706392173615e-05" />
        </inertial>
        <visual name="FR-leg-link41_visual">
            <origin xyz="-5.783107326351455e-13 -0.007967430604415552 -0.0046000000001343725" rpy="-1.9922254205299332 0.9908942383344376 1.0788441157146447" />
            <geometry>
                <mesh filename="meshes/FR-leg-link41.stl" />
            </geometry>
        </visual>
        <collision name="FR-leg-link41_collision">
            <origin xyz="-5.783107326351455e-13 -0.007967430604415552 -0.0046000000001343725" rpy="-1.9922254205299332 0.9908942383344376 1.0788441157146447" />
            <geometry>
                <mesh filename="meshes/FR-leg-link41.stl" />
            </geometry>
        </collision>
    </link>
    <link name="RR-Single-Motor1">
        <inertial>
            <origin xyz="0.008058511743548361 -0.024291032753734863 0.016750000002170466" rpy="0.0 -0.0 0.0" />
            <mass value="0.18505114928963637" />
            <inertia ixx="6.927157374958179e-05" iyy="5.277906067330945e-05" izz="8.852045695425148e-05" ixy="1.5973926095183468e-07" iyz="-4.360227456867705e-15" ixz="-1.060219620430125e-14" />
        </inertial>
        <visual name="RR-Single-Motor1_visual">
            <origin xyz="0.041749999999999884 -0.039250000000000014 0.016750000000000115" rpy="1.5707963267948968 -1.5707963267948966 0" />
            <geometry>
                <mesh filename="meshes/RR-Single-Motor1.stl" />
            </geometry>
        </visual>
        <collision name="RR-Single-Motor1_collision">
            <origin xyz="0.041749999999999884 -0.039250000000000014 0.016750000000000115" rpy="1.5707963267948968 -1.5707963267948966 0" />
            <geometry>
                <mesh filename="meshes/RR-Single-Motor1.stl" />
            </geometry>
        </collision>
    </link>
    <link name="RR-Double-Motor1">
        <inertial>
            <origin xyz="0.06716414766997786 0.0054249409134740035 -0.009451637209221868" rpy="0.0 -0.0 0.0" />
            <mass value="0.4782524941626558" />
            <inertia ixx="0.0003096692588513138" iyy="0.0008123248398218992" izz="0.0007226948848487317" ixy="1.8409934400900882e-07" iyz="7.691806622295466e-05" ixz="-7.498838760292002e-07" />
        </inertial>
        <visual name="RR-Double-Motor1_visual">
            <origin xyz="0.08224999999999977 -2.842170943040401e-16 5.329070518200751e-17" rpy="-3.141592653589793 0.5235987755982987 -1.570796326794897" />
            <geometry>
                <mesh filename="meshes/RR-Double-Motor1.stl" />
            </geometry>
        </visual>
        <collision name="RR-Double-Motor1_collision">
            <origin xyz="0.08224999999999977 -2.842170943040401e-16 5.329070518200751e-17" rpy="-3.141592653589793 0.5235987755982987 -1.570796326794897" />
            <geometry>
                <mesh filename="meshes/RR-Double-Motor1.stl" />
            </geometry>
        </collision>
    </link>
    <link name="RR-leg-link11">
        <inertial>
            <origin xyz="-0.01818757513462284 0.03028349156038793 -0.04021684250863366" rpy="0.0 -0.0 0.0" />
            <mass value="0.047708134542766116" />
            <inertia ixx="9.385770265272526e-05" iyy="8.04865101588139e-05" izz="4.385363921982765e-05" ixy="1.817126286114582e-05" iyz="4.230367587948351e-05" ixz="-2.7044549867657873e-05" />
        </inertial>
        <visual name="RR-leg-link11_visual">
            <origin xyz="-2.486899575160351e-16 0.008660249395507033 0.004999999999999716" rpy="1.035986567537188 -0.9506573206634452 -0.9415634402075749" />
            <geometry>
                <mesh filename="meshes/RR-leg-link11.stl" />
            </geometry>
        </visual>
        <collision name="RR-leg-link11_collision">
            <origin xyz="-2.486899575160351e-16 0.008660249395507033 0.004999999999999716" rpy="1.035986567537188 -0.9506573206634452 -0.9415634402075749" />
            <geometry>
                <mesh filename="meshes/RR-leg-link11.stl" />
            </geometry>
        </collision>
    </link>
    <link name="RR-leg-link21">
        <inertial>
            <origin xyz="0.029139284884780993 0.05826605625483126 0.035493938817888926" rpy="0.0 -0.0 0.0" />
            <mass value="0.03786194092058894" />
            <inertia ixx="7.448018286324411e-05" iyy="3.777207600391965e-05" izz="6.925746499024324e-05" ixy="-2.8046064299812476e-05" iyz="-3.2920723103980295e-05" ixz="-1.7564805978210438e-05" />
        </inertial>
        <visual name="RR-leg-link21_visual">
            <origin xyz="-0.0013289292056416358 0.001240834029147493 -0.000833230384921162" rpy="-0.7066322582629548 0.8741311024220161 0.23994368519484485" />
            <geometry>
                <mesh filename="meshes/RR-leg-link21.stl" />
            </geometry>
        </visual>
        <collision name="RR-leg-link21_collision">
            <origin xyz="-0.0013289292056416358 0.001240834029147493 -0.000833230384921162" rpy="-0.7066322582629548 0.8741311024220161 0.23994368519484485" />
            <geometry>
                <mesh filename="meshes/RR-leg-link21.stl" />
            </geometry>
        </collision>
    </link>
    <link name="RR-leg-link31">
        <inertial>
            <origin xyz="-0.009870261189700962 0.056900248368776975 0.04039492088140655" rpy="0.0 -0.0 0.0" />
            <mass value="0.030992351814247344" />
            <inertia ixx="5.096791650990992e-05" iyy="2.169033076713285e-05" izz="4.640484444756686e-05" ixy="1.4384862073610527e-05" iyz="-2.0948753157879257e-05" ixz="7.649464180235858e-06" />
        </inertial>
        <visual name="RR-leg-link31_visual">
            <origin xyz="0.0012817170732496665 0.0012113339359168408 -0.0009433319697064669" rpy="-2.4051505190761153 0.7922522618333213 2.9011303431519466" />
            <geometry>
                <mesh filename="meshes/RR-leg-link31.stl" />
            </geometry>
        </visual>
        <collision name="RR-leg-link31_collision">
            <origin xyz="0.0012817170732496665 0.0012113339359168408 -0.0009433319697064669" rpy="-2.4051505190761153 0.7922522618333213 2.9011303431519466" />
            <geometry>
                <mesh filename="meshes/RR-leg-link31.stl" />
            </geometry>
        </collision>
    </link>
    <link name="RR-leg-link41">
        <inertial>
            <origin xyz="0.02415792848360219 0.023676735620980553 -0.04583883911065378" rpy="0.0 -0.0 0.0" />
            <mass value="0.04905477511303801" />
            <inertia ixx="9.023065409482364e-05" iyy="9.740279616250562e-05" izz="3.5375106112511836e-05" ixy="-1.556605449322445e-05" iyz="3.126888437981731e-05" ixz="3.73168990897661e-05" />
        </inertial>
        <visual name="RR-leg-link41_visual">
            <origin xyz="-4.298783551348606e-15 -0.007967430604492875 -0.004600000000000506" rpy="-2.202675150204969 0.9025114294230409 0.8202511401793989" />
            <geometry>
                <mesh filename="meshes/RR-leg-link41.stl" />
            </geometry>
        </visual>
        <collision name="RR-leg-link41_collision">
            <origin xyz="-4.298783551348606e-15 -0.007967430604492875 -0.004600000000000506" rpy="-2.202675150204969 0.9025114294230409 0.8202511401793989" />
            <geometry>
                <mesh filename="meshes/RR-leg-link41.stl" />
            </geometry>
        </collision>
    </link>
    <joint name="Body1_FL-Rigid" type="fixed">
        <origin xyz="-0.044000000000000004 -0.032 0.012000000000000028" rpy="3.141592653589793 -0.0 0.0" />
        <parent link="Body1" />
        <child link="FL-Single-Motor1" />
    </joint>
    <joint name="FL-Single-Motor1_FL-Revolute" type="continuous">
        <origin xyz="-0.034499999999999996 0.03925 0.016750000000000043" rpy="-1.5707963267948966 -0.0 0.0" />
        <parent link="FL-Single-Motor1" />
        <child link="FL-Double-Motor1" />
        <axis xyz="-1.0 0.0 7.806255641895643e-18" />
    </joint>
    <joint name="FL-Double-Motor1_FL-Motor-Link1" type="continuous">
        <origin xyz="-0.08225 0.031400000000000004 0.054386399999999994" rpy="-1.5707963267948968 1.0785207688568522e-32 5.551115123125783e-17" />
        <parent link="FL-Double-Motor1" />
        <child link="FL-leg-link11" />
        <axis xyz="2.775557561562891e-17 -0.8660250000000002 0.4999999999999999" />
    </joint>
    <joint name="FL-leg-link11_FL-Link1-Link2" type="continuous">
        <origin xyz="-0.06577526000000003 -0.06826225 -0.09540526999999997" rpy="-0.7853981633974452 5.551115123125784e-17 -5.551115123125784e-17" />
        <parent link="FL-leg-link11" />
        <child link="FL-leg-link21" />
        <axis xyz="0.6123719999999999 -0.5915061361710475 -0.5245190823621178" />
    </joint>
    <joint name="FL-Double-Motor1_FL-Motor-Link4" type="continuous">
        <origin xyz="-0.08225 0.041000000000000016 0.07101408" rpy="-1.5707963267948968 1.0785207688568522e-32 5.551115123125783e-17" />
        <parent link="FL-Double-Motor1" />
        <child link="FL-leg-link41" />
        <axis xyz="2.775557561562891e-17 -0.866025 0.5" />
    </joint>
    <joint name="FL-leg-link41_FL-Link4-Link3" type="continuous">
        <origin xyz="0.033315729999999974 -0.05815736000000001 -0.11630306999999998" rpy="-0.7853981633974534 8.326672684688675e-17 -3.851859888774471e-33" />
        <parent link="FL-leg-link41" />
        <child link="FL-leg-link31" />
        <axis xyz="0.6830129999999999 0.6356458627730519 0.35978936529656114" />
    </joint>
    <joint name="FL-leg-link21_FL-Link2-Link3" type="continuous">
        <origin xyz="0.03741105000000001 0.10530386213388003 -0.07395845491998392" rpy="-2.1862760354652835 -0.5235987755982939 2.5261129449194093" />
        <parent link="FL-leg-link21" />
        <child link="FL-leg-link31" />
        <axis xyz="-0.6283202365199574 0.20095100000000005 0.7515533921315938" />
    </joint>
    <joint name="Body1_RL-Rigid" type="fixed">
        <origin xyz="0.044000000000000004 -0.032 0.012000000000000028" rpy="3.141592653589793 -0.0 0.0" />
        <parent link="Body1" />
        <child link="RL-Single-Motor1" />
    </joint>
    <joint name="RL-Single-Motor1_RL-Revolute" type="continuous">
        <origin xyz="0.034499999999999996 0.03925 0.016750000000000043" rpy="-1.5707963267948966 6.077163357286271e-64 0.0" />
        <parent link="RL-Single-Motor1" />
        <child link="RL-Double-Motor1" />
        <axis xyz="1.0 4.930380657631324e-32 -7.806255641895643e-18" />
    </joint>
    <joint name="RL-Double-Motor1_RL-Motor-Link1" type="continuous">
        <origin xyz="0.08225 0.031400000000000004 0.054386399999999994" rpy="-1.5707963267948968 -9.860761315262648e-32 1.2316099784104838e-47" />
        <parent link="RL-Double-Motor1" />
        <child link="RL-leg-link11" />
        <axis xyz="8.539665818050335e-32 -0.8660250000000002 0.4999999999999999" />
    </joint>
    <joint name="RL-leg-link11_RL-Link1-Link2" type="continuous">
        <origin xyz="-0.04450177 -0.07308624 -0.10376067" rpy="-0.7853981633974451 6.798155367234458e-33 -5.551115123125773e-17" />
        <parent link="RL-leg-link11" />
        <child link="RL-leg-link21" />
        <axis xyz="0.664463 -0.620419025346984 -0.416616708873394" />
    </joint>
    <joint name="RL-Double-Motor1_RL-Motor-Link4" type="continuous">
        <origin xyz="0.08225 0.041000000000000016 0.07101408" rpy="-1.5707963267948968 -9.860761315262648e-32 1.2316099784104838e-47" />
        <parent link="RL-Double-Motor1" />
        <child link="RL-leg-link41" />
        <axis xyz="8.539665818050335e-32 -0.866025 0.5" />
    </joint>
    <joint name="RL-leg-link41_RL-Link4-Link3" type="continuous">
        <origin xyz="0.055349129999999996 -0.054278770000000025 -0.10958516000000003" rpy="-0.7853981633974534 5.551115123125783e-17 9.860761315262648e-32" />
        <parent link="RL-leg-link41" />
        <child link="RL-leg-link31" />
        <axis xyz="0.640856 0.6056687778914289 0.4716663860023341" />
    </joint>
    <joint name="RL-leg-link21_RL-Link2-Link3" type="continuous">
        <origin xyz="0.053980549999999995 0.10323441514378828 -0.06623518009742323" rpy="0.9553166181245096 -0.5235987755982939 2.5261129449194097" />
        <parent link="RL-leg-link21" />
        <child link="RL-leg-link31" />
        <axis xyz="0.712322400804576 0.20534700000000003 0.6711405018682788" />
    </joint>
    <joint name="Body1_FR-Rigid" type="fixed">
        <origin xyz="-0.044000000000000004 0.029500000000000002 0.012000000000000028" rpy="3.141592653589793 -0.0 0.0" />
        <parent link="Body1" />
        <child link="FR-Single-Motor1" />
    </joint>
    <joint name="FR-Single-Motor1_FR-Revolute" type="continuous">
        <origin xyz="-0.034499999999999996 -0.03925 0.016750000000000043" rpy="-1.5707963267948966 -0.0 0.0" />
        <parent link="FR-Single-Motor1" />
        <child link="FR-Double-Motor1" />
        <axis xyz="-1.0 -2.465190328815662e-32 7.806255641895643e-18" />
    </joint>
    <joint name="FR-Double-Motor1_FR-Motor-Link1" type="continuous">
        <origin xyz="-0.08225 0.031400000000000004 -0.054386399999999994" rpy="-1.5707963267948968 -6.93334779979405e-33 -5.551115123125783e-17" />
        <parent link="FR-Double-Motor1" />
        <child link="FR-leg-link11" />
        <axis xyz="-2.7755575615628914e-17 0.8660249999999999 0.5000000000000001" />
    </joint>
    <joint name="FR-leg-link11_FR-Link1-Link2" type="continuous">
        <origin xyz="-0.06577526000000003 0.06826225000000002 -0.09540526999999997" rpy="-2.356194490192348 -5.551115123125782e-17 -5.551115123125784e-17" />
        <parent link="FR-leg-link11" />
        <child link="FR-leg-link21" />
        <axis xyz="0.612372 -0.5915061361710475 0.5245190823621178" />
    </joint>
    <joint name="FR-Double-Motor1_FR-Motor-Link4" type="continuous">
        <origin xyz="-0.08225 0.041000000000000016 -0.07101408" rpy="-1.5707963267948968 -6.93334779979405e-33 -5.551115123125783e-17" />
        <parent link="FR-Double-Motor1" />
        <child link="FR-leg-link41" />
        <axis xyz="-2.7755575615628914e-17 0.866025 0.5" />
    </joint>
    <joint name="FR-leg-link41_FR-Link4-Link3" type="continuous">
        <origin xyz="0.03331573000000001 0.05815736000000001 -0.11630306999999998" rpy="-2.35619449019234 -5.551115123125783e-17 5.551115123125783e-17" />
        <parent link="FR-leg-link41" />
        <child link="FR-leg-link31" />
        <axis xyz="0.683013 0.635645862773052 -0.3597893652965619" />
    </joint>
    <joint name="FR-leg-link21_FR-Link2-Link3" type="continuous">
        <origin xyz="0.037411049999999973 0.10530386213387996 0.07395845491998396" rpy="2.1862760354652835 -0.5235987755982939 -2.5261129449194097" />
        <parent link="FR-leg-link21" />
        <child link="FR-leg-link31" />
        <axis xyz="0.7515533921315871 0.20095100000000002 -0.6283202365199652" />
    </joint>
    <joint name="Body1_RR-Rigid" type="fixed">
        <origin xyz="0.044000000000000004 0.029500000000000002 0.012000000000000028" rpy="3.141592653589793 -0.0 0.0" />
        <parent link="Body1" />
        <child link="RR-Single-Motor1" />
    </joint>
    <joint name="RR-Single-Motor1_RR-Revolute" type="continuous">
        <origin xyz="0.034499999999999996 -0.03925 0.016750000000000043" rpy="-1.5707963267948966 -0.0 0.0" />
        <parent link="RR-Single-Motor1" />
        <child link="RR-Double-Motor1" />
        <axis xyz="0.9999999999999999 -3.851859888774472e-34 0.0" />
    </joint>
    <joint name="RR-Double-Motor1_RR-Motor-Link1" type="continuous">
        <origin xyz="0.08224999999999998 0.031400000000000004 -0.05438639999999999" rpy="-1.5707963267948968 -4.9303806576313227e-32 6.07716335728627e-64" />
        <parent link="RR-Double-Motor1" />
        <child link="RR-leg-link11" />
        <axis xyz="-4.2698329090251674e-32 0.8660249999999999 0.5000000000000002" />
    </joint>
    <joint name="RR-leg-link11_RR-Link1-Link2" type="continuous">
        <origin xyz="-0.04450177 0.07308624000000004 -0.10376066999999992" rpy="-2.356194490192348 -6.798155367234463e-33 5.551115123125789e-17" />
        <parent link="RR-leg-link11" />
        <child link="RR-leg-link21" />
        <axis xyz="0.664463 -0.620419025346984 0.4166167088733941" />
    </joint>
    <joint name="RR-Double-Motor1_Revolute_45" type="continuous">
        <origin xyz="0.08224999999999998 0.041000000000000016 -0.07101407999999998" rpy="-1.5707963267948966 -4.9303806576313227e-32 6.07716335728627e-64" />
        <parent link="RR-Double-Motor1" />
        <child link="RR-leg-link41" />
        <axis xyz="-4.2698329090251674e-32 0.866025 0.5000000000000001" />
    </joint>
    <joint name="RR-leg-link41_Revolute_46" type="continuous">
        <origin xyz="0.055349129999999996 0.054278770000000025 -0.10958515999999996" rpy="-2.35619449019234 -0.0 5.551115123125789e-17" />
        <parent link="RR-leg-link41" />
        <child link="RR-leg-link31" />
        <axis xyz="0.640856 0.6056687778914288 -0.4716663860023341" />
    </joint>
    <joint name="RR-leg-link21_Revolute_47" type="continuous">
        <origin xyz="0.053980550000000016 0.10323441514378821 0.06623518009742321" rpy="2.1862760354652835 -0.5235987755982938 -2.5261129449194093" />
        <parent link="RR-leg-link21" />
        <child link="RR-leg-link31" />
        <axis xyz="0.671140501868271 0.20534699999999995 -0.7123224008045831" />
    </joint>
</robot>