<?xml version="1.0" ?>
<!-- =================================================================================== -->
<!-- |    This document was autogenerated by xacro from robot_xacro/overconstrained_ov_vertical.xacro | -->
<!-- |    EDITING THIS FILE BY HAND IS NOT RECOMMENDED                                 | -->
<!-- =================================================================================== -->
<robot xmlns:xacro="http://www.ros.org/wiki/xacro" name="overconstrained_ov_v1_symmetric">
  <link name="base">
    <visual>
      <geometry>
        <mesh filename="./mesh/visual/frames/base_simplified_vertical_visual.stl" scale="0.001 0.001 0.001"/>
      </geometry>
    </visual>
    <collision>
      <geometry>
        <mesh filename="./mesh/collision/frames/vertical_frame_collision.obj" scale="0.001 0.001 0.001"/>
      </geometry>
    </collision>
    <inertial>
      <mass value="1.054"/>
      <origin xyz="0 0 -0.059045"/>
      <inertia ixx="0.007556" iyy="0.007556" izz="0.007431"/>
    </inertial>
  </link>
  <link name="a1-two_dof_module">
    <inertial>
      <origin xyz="-0.00028 0.01047 -0.01023" rpy="0 0 0"/>
      <mass value="0.246"/>
      <inertia ixx="0.00025" iyy="0.00010" izz="0.00020"/>
    </inertial>
    <visual>
      <origin xyz="0.0 0.0 0.019" rpy="0.0 0.0 0.0"/>
      <geometry>
        <mesh filename="../mesh/visual/overconstrained_v2/two_dof_module_simplified.stl" scale="0.001 0.001 0.001"/>
      </geometry>
    </visual>
    <collision>
      <origin xyz="0.0 0.0 0.019" rpy="0.0 0.0 0.0"/>
      <geometry>
        <mesh filename="../mesh/collision/overconstrained_v2/2dof_module_collision.STL" scale="0.001 0.001 0.001"/>
      </geometry>
    </collision>
  </link>
  <link name="a1-link1">
    <inertial>
      <origin xyz="0.0024455616 -0.0613330624 -0.0010832509" rpy="0 0 0"/>
      <mass value="0.0299338616"/>
      <inertia ixx="5.2023e-05" iyy="1.979e-06" izz="5.17237e-05" ixy="2.0911e-06" iyz="-5.3953e-06" ixz="4.522e-07"/>
    </inertial>
    <visual>
      <origin xyz="0.0 0.0 0.0" rpy="0.0 0.0 0.0"/>
      <geometry>
        <mesh filename="../mesh/visual/overconstrained/link1.obj" scale="0.001 0.001 0.001"/>
      </geometry>
    </visual>
    <collision>
      <origin xyz="0.0 0.0 0.0" rpy="0.0 0.0 0.0"/>
      <geometry>
        <mesh filename="../mesh/collision/overconstrained/link1.obj" scale="0.001 0.001 0.001"/>
      </geometry>
    </collision>
  </link>
  <link name="a1-link2">
    <inertial>
      <origin xyz="0.0018980449 -0.0447345749 0.0044846887" rpy="0 0 0"/>
      <mass value="0.0182756626"/>
      <inertia ixx="2.49722e-05" iyy="6.156e-07" izz="2.51424e-05" ixy="1.1778e-06" iyz="-7.091e-07" ixz="1.039e-07"/>
    </inertial>
    <visual>
      <origin xyz="0.0 0.0 0.0" rpy="0.0 0.0 0.0"/>
      <geometry>
        <mesh filename="../mesh/visual/overconstrained/link2.obj" scale="0.001 0.001 0.001"/>
      </geometry>
    </visual>
    <collision>
      <origin xyz="0.0 0.0 0.0" rpy="0.0 0.0 0.0"/>
      <geometry>
        <mesh filename="../mesh/collision/overconstrained/link2.obj" scale="0.001 0.001 0.001"/>
      </geometry>
    </collision>
  </link>
  <link name="a1-link4">
    <inertial>
      <origin xyz="-0.0026422902 -0.067590774 -0.0033849791" rpy="0 0 0"/>
      <mass value="0.0275608119"/>
      <inertia ixx="3.84633e-05" iyy="1.4218e-06" izz="3.88256e-05" ixy="-1.6444e-06" iyz="4.345e-07" ixz="-2.013e-07"/>
    </inertial>
    <visual>
      <origin xyz="0.0 0.0 0.0" rpy="0.0 0.0 0.0"/>
      <geometry>
        <mesh filename="../mesh/visual/overconstrained/link4.obj" scale="0.001 0.001 0.001"/>
      </geometry>
    </visual>
    <collision>
      <origin xyz="0.0 0.0 0.0" rpy="0.0 0.0 0.0"/>
      <geometry>
        <mesh filename="../mesh/collision/overconstrained/link4.obj" scale="0.001 0.001 0.001"/>
      </geometry>
    </collision>
  </link>
  <link name="a1-link3">
    <inertial>
      <origin xyz="0.002386501 -0.0533785592 -0.0003073645" rpy="0 0 0"/>
      <mass value="0.0217645964"/>
      <inertia ixx="3.57111e-05" iyy="1.2113e-06" izz="3.54138e-05" ixy="1.7199e-06" iyz="-4.1867e-06" ixz="1.471e-07"/>
    </inertial>
    <visual>
      <origin xyz="0.0 0.0 0.0" rpy="0.0 0.0 0.0"/>
      <geometry>
        <mesh filename="../mesh/visual/overconstrained/link3.obj" scale="0.001 0.001 0.001"/>
      </geometry>
    </visual>
    <collision>
      <origin xyz="0.0 0.0 0.0" rpy="0.0 0.0 0.0"/>
      <geometry>
        <mesh filename="../mesh/collision/overconstrained/link3.obj" scale="0.001 0.001 0.001"/>
      </geometry>
    </collision>
  </link>
  <link name="a1-tip_bearings">
    <inertial>
      <origin xyz="0.0 -0.0 0.0053378354" rpy="0 0 0"/>
      <mass value="0.0102057874"/>
      <inertia ixx="6.785e-07" iyy="6.785e-07" izz="9.84e-08" ixy="0.0" iyz="0.0" ixz="0.0"/>
    </inertial>
    <visual>
      <origin xyz="0.0 0.0 0.0" rpy="0.0 0.0 0.0"/>
      <geometry>
        <mesh filename="../mesh/visual/overconstrained/tip_bearings.obj" scale="0.001 0.001 0.001"/>
      </geometry>
    </visual>
    <collision>
      <origin xyz="0.0 0.0 0.0" rpy="0.0 0.0 0.0"/>
      <geometry>
        <mesh filename="../mesh/collision/overconstrained/tip_bearings.obj" scale="0.001 0.001 0.001"/>
      </geometry>
    </collision>
  </link>
  <link name="a1-fingertip_frame">
    <inertial>
      <origin xyz="0.0 -0.0 0.0053378354" rpy="0 0 0"/>
      <mass value="0.002"/>
      <inertia ixx="9.2e-08" iyy="9.2e-08" izz="7.89e-08" ixy="0.0" iyz="0.0" ixz="0.0"/>
    </inertial>
    <visual>
      <origin xyz="0.0 0.0 0.0" rpy="0.0 0.0 0.0"/>
      <geometry>
        <mesh filename="../mesh/visual/overconstrained_v2/fingertip_visual.obj" scale="0.001 0.001 0.001"/>
      </geometry>
    </visual>
    <collision>
      <origin xyz="0.0 0.0 0.0" rpy="0.0 0.0 0.0"/>
      <geometry>
        <mesh filename="../mesh/collision/overconstrained_v2/fingertip_tip_only_collision.obj" scale="0.001 0.001 0.001"/>
      </geometry>
    </collision>
  </link>
  <joint name="a1-dof1" type="revolute">
    <parent link="base"/>
    <child link="a1-two_dof_module"/>
    <origin xyz="-0.1 0.0 -0.1369" rpy="1.570796325 0 -1.570796325"/>
    <axis xyz="0 1 0"/>
    <limit effort="1000" lower="-3.14159265" upper="3.14159265" velocity="1000"/>
  </joint>
  <joint name="a1-dof2" type="revolute">
    <parent link="a1-two_dof_module"/>
    <child link="a1-link4"/>
    <axis xyz="0 0 -1"/>
    <limit effort="1000" lower="-3.14159265" upper="3.14159265" velocity="1000"/>
    <origin xyz="0 0 0.0558" rpy="0 0 0"/>
  </joint>
  <joint name="a1-dof3" type="revolute">
    <parent link="a1-two_dof_module"/>
    <child link="a1-link1"/>
    <axis xyz="0 0 -1"/>
    <limit effort="1000" lower="-3.14159265" upper="3.14159265" velocity="1000"/>
    <origin xyz="0 0 0.057800000000000004" rpy="0 0 0"/>
  </joint>
  <joint name="a1-link4_to_link3" type="revolute">
    <parent link="a1-link4"/>
    <child link="a1-link3"/>
    <axis xyz="0 0 1"/>
    <limit effort="1000" lower="-3.14159265" upper="3.14159265" velocity="1000"/>
    <origin xyz="0.000707 -0.1 0.001707" rpy="0 0.7853981625 0"/>
  </joint>
  <joint name="a1-link1_to_link2" type="revolute">
    <parent link="a1-link1"/>
    <child link="a1-link2"/>
    <axis xyz="0 0 1"/>
    <limit effort="1000" lower="-3.14159265" upper="3.14159265" velocity="1000"/>
    <origin xyz="-0.000707 -0.1 -0.000293" rpy="0 -0.7853981625 0"/>
  </joint>
  <joint name="a1-tip_bearings_fixed" type="fixed">
    <parent link="a1-link2"/>
    <child link="a1-tip_bearings"/>
    <origin xyz="0 -0.1 -0.001" rpy="0 0.7853981625 0"/>
  </joint>
  <joint name="a1-closed_chain_revolute" type="revolute">
    <parent link="a1-link3"/>
    <child link="a1-tip_bearings"/>
    <origin xyz="0 -0.1 -0.001" rpy="0 -0.7853981625 0"/>
    <axis xyz="0 0 1"/>
    <limit effort="1000" lower="-3.14159265" upper="3.14159265" velocity="1000"/>
  </joint>
  <joint name="a1-fingertip_frame_fix" type="fixed">
    <parent link="a1-link3"/>
    <child link="a1-fingertip_frame"/>
    <!-- <origin xyz="0.004243 -0.127 -0.005243" rpy="0 0 0"/> -->
    <origin xyz="0.004243 -0.13 -0.005243" rpy="0 0 0"/>
  </joint>
  <link name="a3-two_dof_module">
    <inertial>
      <origin xyz="-0.00028 0.01047 -0.01023" rpy="0 0 0"/>
      <mass value="0.246"/>
      <inertia ixx="0.00025" iyy="0.00010" izz="0.00020"/>
    </inertial>
    <visual>
      <origin xyz="0.0 0.0 0.019" rpy="0.0 0.0 0.0"/>
      <geometry>
        <mesh filename="../mesh/visual/overconstrained_v2/two_dof_module_simplified.stl" scale="0.001 0.001 0.001"/>
      </geometry>
    </visual>
    <collision>
      <origin xyz="0.0 0.0 0.019" rpy="0.0 0.0 0.0"/>
      <geometry>
        <mesh filename="../mesh/collision/overconstrained_v2/2dof_module_collision.STL" scale="0.001 0.001 0.001"/>
      </geometry>
    </collision>
  </link>
  <link name="a3-link1">
    <inertial>
      <origin xyz="0.0024455616 -0.0613330624 -0.0010832509" rpy="0 0 0"/>
      <mass value="0.0299338616"/>
      <inertia ixx="5.2023e-05" iyy="1.979e-06" izz="5.17237e-05" ixy="2.0911e-06" iyz="-5.3953e-06" ixz="4.522e-07"/>
    </inertial>
    <visual>
      <origin xyz="0.0 0.0 0.0" rpy="0.0 0.0 0.0"/>
      <geometry>
        <mesh filename="../mesh/visual/overconstrained/link1.obj" scale="0.001 0.001 0.001"/>
      </geometry>
    </visual>
    <collision>
      <origin xyz="0.0 0.0 0.0" rpy="0.0 0.0 0.0"/>
      <geometry>
        <mesh filename="../mesh/collision/overconstrained/link1.obj" scale="0.001 0.001 0.001"/>
      </geometry>
    </collision>
  </link>
  <link name="a3-link2_right">
    <inertial>
      <origin xyz="-0.0023861897 -0.0533785446 -0.0003074935" rpy="0 0 0"/>
      <mass value="0.0217645905"/>
      <inertia ixx="3.57112e-05" iyy="1.2113e-06" izz="3.54138e-05" ixy="-1.7195e-06" iyz="-4.186e-06" ixz="-1.471e-07"/>
    </inertial>
    <visual>
      <origin xyz="0.0 0.0 0.0" rpy="0.0 0.0 0.0"/>
      <geometry>
        <mesh filename="../mesh/visual/overconstrained/link2_right.obj" scale="0.001 0.001 0.001"/>
      </geometry>
    </visual>
    <collision>
      <origin xyz="0.0 0.0 0.0" rpy="0.0 0.0 0.0"/>
      <geometry>
        <mesh filename="../mesh/collision/overconstrained/link2_right.obj" scale="0.001 0.001 0.001"/>
      </geometry>
    </collision>
  </link>
  <link name="a3-link4">
    <inertial>
      <origin xyz="-0.0026422902 -0.067590774 -0.0033849791" rpy="0 0 0"/>
      <mass value="0.0275608119"/>
      <inertia ixx="3.84633e-05" iyy="1.4218e-06" izz="3.88256e-05" ixy="-1.6444e-06" iyz="4.345e-07" ixz="-2.013e-07"/>
    </inertial>
    <visual>
      <origin xyz="0.0 0.0 0.0" rpy="0.0 0.0 0.0"/>
      <geometry>
        <mesh filename="../mesh/visual/overconstrained/link4.obj" scale="0.001 0.001 0.001"/>
      </geometry>
    </visual>
    <collision>
      <origin xyz="0.0 0.0 0.0" rpy="0.0 0.0 0.0"/>
      <geometry>
        <mesh filename="../mesh/collision/overconstrained/link4.obj" scale="0.001 0.001 0.001"/>
      </geometry>
    </collision>
  </link>
  <link name="a3-link3_right">
    <inertial>
      <origin xyz="-0.0018978282 -0.0447345749 0.0044846887" rpy="0 0 0"/>
      <mass value="0.0182756626"/>
      <inertia ixx="2.49722e-05" iyy="6.156e-07" izz="2.51424e-05" ixy="-1.1767e-06" iyz="-7.091e-07" ixz="-1.039e-07"/>
    </inertial>
    <visual>
      <origin xyz="0.0 0.0 0.0" rpy="0.0 0.0 0.0"/>
      <geometry>
        <mesh filename="../mesh/visual/overconstrained/link3_right.obj" scale="0.001 0.001 0.001"/>
      </geometry>
    </visual>
    <collision>
      <origin xyz="0.0 0.0 0.0" rpy="0.0 0.0 0.0"/>
      <geometry>
        <mesh filename="../mesh/collision/overconstrained/link3_right.obj" scale="0.001 0.001 0.001"/>
      </geometry>
    </collision>
  </link>
  <link name="a3-tip_bearings">
    <inertial>
      <origin xyz="0.0 -0.0 0.0053378354" rpy="0 0 0"/>
      <mass value="0.0102057874"/>
      <inertia ixx="6.785e-07" iyy="6.785e-07" izz="9.84e-08" ixy="0.0" iyz="0.0" ixz="0.0"/>
    </inertial>
    <visual>
      <origin xyz="0.0 0.0 0.0" rpy="0.0 0.0 0.0"/>
      <geometry>
        <mesh filename="../mesh/visual/overconstrained/tip_bearings.obj" scale="0.001 0.001 0.001"/>
      </geometry>
    </visual>
    <collision>
      <origin xyz="0.0 0.0 0.0" rpy="0.0 0.0 0.0"/>
      <geometry>
        <mesh filename="../mesh/collision/overconstrained/tip_bearings.obj" scale="0.001 0.001 0.001"/>
      </geometry>
    </collision>
  </link>
  <link name="a3-fingertip_frame">
    <inertial>
      <origin xyz="0.0 -0.0 0.0053378354" rpy="0 0 0"/>
      <mass value="0.002"/>
      <inertia ixx="9.2e-08" iyy="9.2e-08" izz="7.89e-08" ixy="0.0" iyz="0.0" ixz="0.0"/>
    </inertial>
    <visual>
      <origin xyz="0.0 0.0 0.0" rpy="0.0 0.0 0.0"/>
      <geometry>
        <mesh filename="../mesh/visual/overconstrained_v2/fingertip_visual.obj" scale="0.001 0.001 0.001"/>
      </geometry>
    </visual>
    <collision>
      <origin xyz="0.0 0.0 0.0" rpy="0.0 0.0 0.0"/>
      <geometry>
        <mesh filename="../mesh/collision/overconstrained_v2/fingertip_tip_only_collision.obj" scale="0.001 0.001 0.001"/>
      </geometry>
    </collision>
  </link>
  <joint name="a3-dof1" type="revolute">
    <parent link="base"/>
    <child link="a3-two_dof_module"/>
    <origin xyz="0.0 -0.1 -0.1369" rpy="1.570796325 0 0"/>
    <axis xyz="0 1 0"/>
  </joint>
  <joint name="a3-dof2" type="revolute">
    <parent link="a3-two_dof_module"/>
    <child link="a3-link4"/>
    <axis xyz="0 0 -1"/>
    <limit effort="1000" lower="-3.14159265" upper="3.14159265" velocity="1000"/>
    <origin xyz="0 0 0.0558" rpy="0 0 0"/>
  </joint>
  <joint name="a3-dof3" type="revolute">
    <parent link="a3-two_dof_module"/>
    <child link="a3-link1"/>
    <axis xyz="0 0 -1"/>
    <limit effort="1000" lower="-3.14159265" upper="3.14159265" velocity="1000"/>
    <origin xyz="0 0 0.057800000000000004" rpy="0 0 0"/>
  </joint>
  <joint name="a3-link4_to_link3_right" type="revolute">
    <parent link="a3-link4"/>
    <child link="a3-link3_right"/>
    <axis xyz="0 0 1"/>
    <limit effort="1000" lower="-3.14159265" upper="3.14159265" velocity="1000"/>
    <origin xyz="0.000707 -0.1 0.001707" rpy="0 0.7853981625 0"/>
  </joint>
  <joint name="a3-link1_to_link2_right" type="revolute">
    <parent link="a3-link1"/>
    <child link="a3-link2_right"/>
    <axis xyz="0 0 1"/>
    <limit effort="1000" lower="-3.14159265" upper="3.14159265" velocity="1000"/>
    <origin xyz="-0.000707 -0.1 -0.000293" rpy="0 -0.7853981625 0"/>
  </joint>
  <joint name="a3-tip_bearings_fixed" type="fixed">
    <parent link="a3-link3_right"/>
    <child link="a3-tip_bearings"/>
    <origin xyz="0 -0.1 -0.001" rpy="0 -0.7853981625 0"/>
  </joint>
  <joint name="a3-closed_chain_revolute" type="revolute">
    <parent link="a3-link2_right"/>
    <child link="a3-tip_bearings"/>
    <axis xyz="0 0 1"/>
    <origin xyz="0 -0.1 -0.001" rpy="0 0.7853981625 0"/>
    <limit effort="1000" lower="-3.14159265" upper="3.14159265" velocity="1000"/>
  </joint>
  <joint name="a3-fingertip_frame_fix" type="fixed">
    <parent link="a3-link2_right"/>
    <child link="a3-fingertip_frame"/>
    <!-- <origin xyz="0.004243 -0.127 -0.005243" rpy="0 0 -${PI}"/> -->
    <origin xyz="-0.004243 -0.13 -0.005243" rpy="0 0 0"/>
  </joint>
  <link name="a2-two_dof_module">
    <inertial>
      <origin xyz="-0.00028 0.01047 -0.01023" rpy="0 0 0"/>
      <mass value="0.246"/>
      <inertia ixx="0.00025" iyy="0.00010" izz="0.00020"/>
    </inertial>
    <visual>
      <origin xyz="0.0 0.0 0.019" rpy="0.0 0.0 0.0"/>
      <geometry>
        <mesh filename="../mesh/visual/overconstrained_v2/two_dof_module_simplified.stl" scale="0.001 0.001 0.001"/>
      </geometry>
    </visual>
    <collision>
      <origin xyz="0.0 0.0 0.019" rpy="0.0 0.0 0.0"/>
      <geometry>
        <mesh filename="../mesh/collision/overconstrained_v2/2dof_module_collision.STL" scale="0.001 0.001 0.001"/>
      </geometry>
    </collision>
  </link>
  <link name="a2-link1">
    <inertial>
      <origin xyz="0.0024455616 -0.0613330624 -0.0010832509" rpy="0 0 0"/>
      <mass value="0.0299338616"/>
      <inertia ixx="5.2023e-05" iyy="1.979e-06" izz="5.17237e-05" ixy="2.0911e-06" iyz="-5.3953e-06" ixz="4.522e-07"/>
    </inertial>
    <visual>
      <origin xyz="0.0 0.0 0.0" rpy="0.0 0.0 0.0"/>
      <geometry>
        <mesh filename="../mesh/visual/overconstrained/link1.obj" scale="0.001 0.001 0.001"/>
      </geometry>
    </visual>
    <collision>
      <origin xyz="0.0 0.0 0.0" rpy="0.0 0.0 0.0"/>
      <geometry>
        <mesh filename="../mesh/collision/overconstrained/link1.obj" scale="0.001 0.001 0.001"/>
      </geometry>
    </collision>
  </link>
  <link name="a2-link2_right">
    <inertial>
      <origin xyz="-0.0023861897 -0.0533785446 -0.0003074935" rpy="0 0 0"/>
      <mass value="0.0217645905"/>
      <inertia ixx="3.57112e-05" iyy="1.2113e-06" izz="3.54138e-05" ixy="-1.7195e-06" iyz="-4.186e-06" ixz="-1.471e-07"/>
    </inertial>
    <visual>
      <origin xyz="0.0 0.0 0.0" rpy="0.0 0.0 0.0"/>
      <geometry>
        <mesh filename="../mesh/visual/overconstrained/link2_right.obj" scale="0.001 0.001 0.001"/>
      </geometry>
    </visual>
    <collision>
      <origin xyz="0.0 0.0 0.0" rpy="0.0 0.0 0.0"/>
      <geometry>
        <mesh filename="../mesh/collision/overconstrained/link2_right.obj" scale="0.001 0.001 0.001"/>
      </geometry>
    </collision>
  </link>
  <link name="a2-link4">
    <inertial>
      <origin xyz="-0.0026422902 -0.067590774 -0.0033849791" rpy="0 0 0"/>
      <mass value="0.0275608119"/>
      <inertia ixx="3.84633e-05" iyy="1.4218e-06" izz="3.88256e-05" ixy="-1.6444e-06" iyz="4.345e-07" ixz="-2.013e-07"/>
    </inertial>
    <visual>
      <origin xyz="0.0 0.0 0.0" rpy="0.0 0.0 0.0"/>
      <geometry>
        <mesh filename="../mesh/visual/overconstrained/link4.obj" scale="0.001 0.001 0.001"/>
      </geometry>
    </visual>
    <collision>
      <origin xyz="0.0 0.0 0.0" rpy="0.0 0.0 0.0"/>
      <geometry>
        <mesh filename="../mesh/collision/overconstrained/link4.obj" scale="0.001 0.001 0.001"/>
      </geometry>
    </collision>
  </link>
  <link name="a2-link3_right">
    <inertial>
      <origin xyz="-0.0018978282 -0.0447345749 0.0044846887" rpy="0 0 0"/>
      <mass value="0.0182756626"/>
      <inertia ixx="2.49722e-05" iyy="6.156e-07" izz="2.51424e-05" ixy="-1.1767e-06" iyz="-7.091e-07" ixz="-1.039e-07"/>
    </inertial>
    <visual>
      <origin xyz="0.0 0.0 0.0" rpy="0.0 0.0 0.0"/>
      <geometry>
        <mesh filename="../mesh/visual/overconstrained/link3_right.obj" scale="0.001 0.001 0.001"/>
      </geometry>
    </visual>
    <collision>
      <origin xyz="0.0 0.0 0.0" rpy="0.0 0.0 0.0"/>
      <geometry>
        <mesh filename="../mesh/collision/overconstrained/link3_right.obj" scale="0.001 0.001 0.001"/>
      </geometry>
    </collision>
  </link>
  <link name="a2-tip_bearings">
    <inertial>
      <origin xyz="0.0 -0.0 0.0053378354" rpy="0 0 0"/>
      <mass value="0.0102057874"/>
      <inertia ixx="6.785e-07" iyy="6.785e-07" izz="9.84e-08" ixy="0.0" iyz="0.0" ixz="0.0"/>
    </inertial>
    <visual>
      <origin xyz="0.0 0.0 0.0" rpy="0.0 0.0 0.0"/>
      <geometry>
        <mesh filename="../mesh/visual/overconstrained/tip_bearings.obj" scale="0.001 0.001 0.001"/>
      </geometry>
    </visual>
    <collision>
      <origin xyz="0.0 0.0 0.0" rpy="0.0 0.0 0.0"/>
      <geometry>
        <mesh filename="../mesh/collision/overconstrained/tip_bearings.obj" scale="0.001 0.001 0.001"/>
      </geometry>
    </collision>
  </link>
  <link name="a2-fingertip_frame">
    <inertial>
      <origin xyz="0.0 -0.0 0.0053378354" rpy="0 0 0"/>
      <mass value="0.002"/>
      <inertia ixx="9.2e-08" iyy="9.2e-08" izz="7.89e-08" ixy="0.0" iyz="0.0" ixz="0.0"/>
    </inertial>
    <visual>
      <origin xyz="0.0 0.0 0.0" rpy="0.0 0.0 0.0"/>
      <geometry>
        <mesh filename="../mesh/visual/overconstrained_v2/fingertip_visual.obj" scale="0.001 0.001 0.001"/>
      </geometry>
    </visual>
    <collision>
      <origin xyz="0.0 0.0 0.0" rpy="0.0 0.0 0.0"/>
      <geometry>
        <mesh filename="../mesh/collision/overconstrained_v2/fingertip_tip_only_collision.obj" scale="0.001 0.001 0.001"/>
      </geometry>
    </collision>
  </link>
  <joint name="a2-dof1" type="revolute">
    <parent link="base"/>
    <child link="a2-two_dof_module"/>
    <origin xyz="0.0 0.1 -0.1369" rpy="1.570796325 0 3.14159265"/>
    <axis xyz="0 1 0"/>
  </joint>
  <joint name="a2-dof2" type="revolute">
    <parent link="a2-two_dof_module"/>
    <child link="a2-link4"/>
    <axis xyz="0 0 -1"/>
    <limit effort="1000" lower="-3.14159265" upper="3.14159265" velocity="1000"/>
    <origin xyz="0 0 0.0558" rpy="0 0 0"/>
  </joint>
  <joint name="a2-dof3" type="revolute">
    <parent link="a2-two_dof_module"/>
    <child link="a2-link1"/>
    <axis xyz="0 0 -1"/>
    <limit effort="1000" lower="-3.14159265" upper="3.14159265" velocity="1000"/>
    <origin xyz="0 0 0.057800000000000004" rpy="0 0 0"/>
  </joint>
  <joint name="a2-link4_to_link3_right" type="revolute">
    <parent link="a2-link4"/>
    <child link="a2-link3_right"/>
    <axis xyz="0 0 1"/>
    <limit effort="1000" lower="-3.14159265" upper="3.14159265" velocity="1000"/>
    <origin xyz="0.000707 -0.1 0.001707" rpy="0 0.7853981625 0"/>
  </joint>
  <joint name="a2-link1_to_link2_right" type="revolute">
    <parent link="a2-link1"/>
    <child link="a2-link2_right"/>
    <axis xyz="0 0 1"/>
    <limit effort="1000" lower="-3.14159265" upper="3.14159265" velocity="1000"/>
    <origin xyz="-0.000707 -0.1 -0.000293" rpy="0 -0.7853981625 0"/>
  </joint>
  <joint name="a2-tip_bearings_fixed" type="fixed">
    <parent link="a2-link3_right"/>
    <child link="a2-tip_bearings"/>
    <origin xyz="0 -0.1 -0.001" rpy="0 -0.7853981625 0"/>
  </joint>
  <joint name="a2-closed_chain_revolute" type="revolute">
    <parent link="a2-link2_right"/>
    <child link="a2-tip_bearings"/>
    <axis xyz="0 0 1"/>
    <origin xyz="0 -0.1 -0.001" rpy="0 0.7853981625 0"/>
    <limit effort="1000" lower="-3.14159265" upper="3.14159265" velocity="1000"/>
  </joint>
  <joint name="a2-fingertip_frame_fix" type="fixed">
    <parent link="a2-link2_right"/>
    <child link="a2-fingertip_frame"/>
    <!-- <origin xyz="0.004243 -0.127 -0.005243" rpy="0 0 -${PI}"/> -->
    <origin xyz="-0.004243 -0.13 -0.005243" rpy="0 0 0"/>
  </joint>
  <link name="a4-two_dof_module">
    <inertial>
      <origin xyz="-0.00028 0.01047 -0.01023" rpy="0 0 0"/>
      <mass value="0.246"/>
      <inertia ixx="0.00025" iyy="0.00010" izz="0.00020"/>
    </inertial>
    <visual>
      <origin xyz="0.0 0.0 0.019" rpy="0.0 0.0 0.0"/>
      <geometry>
        <mesh filename="../mesh/visual/overconstrained_v2/two_dof_module_simplified.stl" scale="0.001 0.001 0.001"/>
      </geometry>
    </visual>
    <collision>
      <origin xyz="0.0 0.0 0.019" rpy="0.0 0.0 0.0"/>
      <geometry>
        <mesh filename="../mesh/collision/overconstrained_v2/2dof_module_collision.STL" scale="0.001 0.001 0.001"/>
      </geometry>
    </collision>
  </link>
  <link name="a4-link1">
    <inertial>
      <origin xyz="0.0024455616 -0.0613330624 -0.0010832509" rpy="0 0 0"/>
      <mass value="0.0299338616"/>
      <inertia ixx="5.2023e-05" iyy="1.979e-06" izz="5.17237e-05" ixy="2.0911e-06" iyz="-5.3953e-06" ixz="4.522e-07"/>
    </inertial>
    <visual>
      <origin xyz="0.0 0.0 0.0" rpy="0.0 0.0 0.0"/>
      <geometry>
        <mesh filename="../mesh/visual/overconstrained/link1.obj" scale="0.001 0.001 0.001"/>
      </geometry>
    </visual>
    <collision>
      <origin xyz="0.0 0.0 0.0" rpy="0.0 0.0 0.0"/>
      <geometry>
        <mesh filename="../mesh/collision/overconstrained/link1.obj" scale="0.001 0.001 0.001"/>
      </geometry>
    </collision>
  </link>
  <link name="a4-link2">
    <inertial>
      <origin xyz="0.0018980449 -0.0447345749 0.0044846887" rpy="0 0 0"/>
      <mass value="0.0182756626"/>
      <inertia ixx="2.49722e-05" iyy="6.156e-07" izz="2.51424e-05" ixy="1.1778e-06" iyz="-7.091e-07" ixz="1.039e-07"/>
    </inertial>
    <visual>
      <origin xyz="0.0 0.0 0.0" rpy="0.0 0.0 0.0"/>
      <geometry>
        <mesh filename="../mesh/visual/overconstrained/link2.obj" scale="0.001 0.001 0.001"/>
      </geometry>
    </visual>
    <collision>
      <origin xyz="0.0 0.0 0.0" rpy="0.0 0.0 0.0"/>
      <geometry>
        <mesh filename="../mesh/collision/overconstrained/link2.obj" scale="0.001 0.001 0.001"/>
      </geometry>
    </collision>
  </link>
  <link name="a4-link4">
    <inertial>
      <origin xyz="-0.0026422902 -0.067590774 -0.0033849791" rpy="0 0 0"/>
      <mass value="0.0275608119"/>
      <inertia ixx="3.84633e-05" iyy="1.4218e-06" izz="3.88256e-05" ixy="-1.6444e-06" iyz="4.345e-07" ixz="-2.013e-07"/>
    </inertial>
    <visual>
      <origin xyz="0.0 0.0 0.0" rpy="0.0 0.0 0.0"/>
      <geometry>
        <mesh filename="../mesh/visual/overconstrained/link4.obj" scale="0.001 0.001 0.001"/>
      </geometry>
    </visual>
    <collision>
      <origin xyz="0.0 0.0 0.0" rpy="0.0 0.0 0.0"/>
      <geometry>
        <mesh filename="../mesh/collision/overconstrained/link4.obj" scale="0.001 0.001 0.001"/>
      </geometry>
    </collision>
  </link>
  <link name="a4-link3">
    <inertial>
      <origin xyz="0.002386501 -0.0533785592 -0.0003073645" rpy="0 0 0"/>
      <mass value="0.0217645964"/>
      <inertia ixx="3.57111e-05" iyy="1.2113e-06" izz="3.54138e-05" ixy="1.7199e-06" iyz="-4.1867e-06" ixz="1.471e-07"/>
    </inertial>
    <visual>
      <origin xyz="0.0 0.0 0.0" rpy="0.0 0.0 0.0"/>
      <geometry>
        <mesh filename="../mesh/visual/overconstrained/link3.obj" scale="0.001 0.001 0.001"/>
      </geometry>
    </visual>
    <collision>
      <origin xyz="0.0 0.0 0.0" rpy="0.0 0.0 0.0"/>
      <geometry>
        <mesh filename="../mesh/collision/overconstrained/link3.obj" scale="0.001 0.001 0.001"/>
      </geometry>
    </collision>
  </link>
  <link name="a4-tip_bearings">
    <inertial>
      <origin xyz="0.0 -0.0 0.0053378354" rpy="0 0 0"/>
      <mass value="0.0102057874"/>
      <inertia ixx="6.785e-07" iyy="6.785e-07" izz="9.84e-08" ixy="0.0" iyz="0.0" ixz="0.0"/>
    </inertial>
    <visual>
      <origin xyz="0.0 0.0 0.0" rpy="0.0 0.0 0.0"/>
      <geometry>
        <mesh filename="../mesh/visual/overconstrained/tip_bearings.obj" scale="0.001 0.001 0.001"/>
      </geometry>
    </visual>
    <collision>
      <origin xyz="0.0 0.0 0.0" rpy="0.0 0.0 0.0"/>
      <geometry>
        <mesh filename="../mesh/collision/overconstrained/tip_bearings.obj" scale="0.001 0.001 0.001"/>
      </geometry>
    </collision>
  </link>
  <link name="a4-fingertip_frame">
    <inertial>
      <origin xyz="0.0 -0.0 0.0053378354" rpy="0 0 0"/>
      <mass value="0.002"/>
      <inertia ixx="9.2e-08" iyy="9.2e-08" izz="7.89e-08" ixy="0.0" iyz="0.0" ixz="0.0"/>
    </inertial>
    <visual>
      <origin xyz="0.0 0.0 0.0" rpy="0.0 0.0 0.0"/>
      <geometry>
        <mesh filename="../mesh/visual/overconstrained_v2/fingertip_visual.obj" scale="0.001 0.001 0.001"/>
      </geometry>
    </visual>
    <collision>
      <origin xyz="0.0 0.0 0.0" rpy="0.0 0.0 0.0"/>
      <geometry>
        <mesh filename="../mesh/collision/overconstrained_v2/fingertip_tip_only_collision.obj" scale="0.001 0.001 0.001"/>
      </geometry>
    </collision>
  </link>
  <joint name="a4-dof1" type="revolute">
    <parent link="base"/>
    <child link="a4-two_dof_module"/>
    <origin xyz="0.1 0.0 -0.1369" rpy="1.570796325 0 1.570796325"/>
    <axis xyz="0 1 0"/>
    <limit effort="1000" lower="-3.14159265" upper="3.14159265" velocity="1000"/>
  </joint>
  <joint name="a4-dof2" type="revolute">
    <parent link="a4-two_dof_module"/>
    <child link="a4-link4"/>
    <axis xyz="0 0 -1"/>
    <limit effort="1000" lower="-3.14159265" upper="3.14159265" velocity="1000"/>
    <origin xyz="0 0 0.0558" rpy="0 0 0"/>
  </joint>
  <joint name="a4-dof3" type="revolute">
    <parent link="a4-two_dof_module"/>
    <child link="a4-link1"/>
    <axis xyz="0 0 -1"/>
    <limit effort="1000" lower="-3.14159265" upper="3.14159265" velocity="1000"/>
    <origin xyz="0 0 0.057800000000000004" rpy="0 0 0"/>
  </joint>
  <joint name="a4-link4_to_link3" type="revolute">
    <parent link="a4-link4"/>
    <child link="a4-link3"/>
    <axis xyz="0 0 1"/>
    <limit effort="1000" lower="-3.14159265" upper="3.14159265" velocity="1000"/>
    <origin xyz="0.000707 -0.1 0.001707" rpy="0 0.7853981625 0"/>
  </joint>
  <joint name="a4-link1_to_link2" type="revolute">
    <parent link="a4-link1"/>
    <child link="a4-link2"/>
    <axis xyz="0 0 1"/>
    <limit effort="1000" lower="-3.14159265" upper="3.14159265" velocity="1000"/>
    <origin xyz="-0.000707 -0.1 -0.000293" rpy="0 -0.7853981625 0"/>
  </joint>
  <joint name="a4-tip_bearings_fixed" type="fixed">
    <parent link="a4-link2"/>
    <child link="a4-tip_bearings"/>
    <origin xyz="0 -0.1 -0.001" rpy="0 0.7853981625 0"/>
  </joint>
  <joint name="a4-closed_chain_revolute" type="revolute">
    <parent link="a4-link3"/>
    <child link="a4-tip_bearings"/>
    <origin xyz="0 -0.1 -0.001" rpy="0 -0.7853981625 0"/>
    <axis xyz="0 0 1"/>
    <limit effort="1000" lower="-3.14159265" upper="3.14159265" velocity="1000"/>
  </joint>
  <joint name="a4-fingertip_frame_fix" type="fixed">
    <parent link="a4-link3"/>
    <child link="a4-fingertip_frame"/>
    <!-- <origin xyz="0.004243 -0.127 -0.005243" rpy="0 0 0"/> -->
    <origin xyz="0.004243 -0.13 -0.005243" rpy="0 0 0"/>
  </joint>
</robot>
