<?xml version="1.0" ?>
<!-- =================================================================================== -->
<!-- |    This document was autogenerated by xacro from robot_xacro/overconstrained_ov_v1_symmetric.urdf.xacro | -->
<!-- |    EDITING THIS FILE BY HAND IS NOT RECOMMENDED                                 | -->
<!-- =================================================================================== -->
<robot xmlns:xacro="http://www.ros.org/wiki/xacro" name="overconstrained_ov_v1_symmetric">
  <link name="base">
    <visual>
      <geometry>
        <mesh filename="./mesh/visual/frames/base_simplified.stl" scale="0.001 0.001 0.001"/>
      </geometry>
    </visual>
    <collision>
      <geometry>
        <mesh filename="./mesh/collision/frames/quadruped_horizontal.obj" scale="0.001 0.001 0.001"/>
      </geometry>
    </collision>
    <inertial>
      <mass value="0.838"/>
      <origin xyz="0 0 0.004575"/>
      <inertia ixx="0.00440" iyy="0.00145" izz="0.00512" ixy="0.0" ixz="0.0" iyz="0.0"/>
    </inertial>
  </link>
  <link name="a1-two_dof_module">
    <inertial>
      <origin xyz="-0.00028 0.01047 -0.01023" rpy="0 0 0"/>
      <mass value="0.246"/>
      <inertia ixx="0.00025" iyy="0.00010" izz="0.00020" ixy="0.0" ixz="0.0" iyz="0.0"/>
    </inertial>
    <visual>
      <origin xyz="0.0 0.0 0.019" rpy="0.0 0.0 0.0"/>
      <geometry>
        <mesh filename="../mesh/visual/overconstrained_v2/two_dof_module_simplified.stl" scale="0.001 0.001 0.001"/>
      </geometry>
    </visual>
    <collision>
      <origin xyz="0.0 0.0 0.019" rpy="0.0 0.0 0.0"/>
      <geometry>
        <mesh filename="../mesh/collision/overconstrained_v2/2dof_module_collision.STL" scale="0.001 0.001 0.001"/>
      </geometry>
    </collision>
  </link>
  <link name="a1-link1">
    <inertial>
      <origin xyz="0.0024 -0.0614 -0.0011" rpy="0 0 0"/>
      <mass value="0.0299"/>
      <inertia ixx="5.1956e-05" iyy="1.979e-06" izz="5.1656e-05" ixy="2.088e-06" iyz="-5.394e-06" ixz="4.522e-07"/>
    </inertial>
    <visual>
      <origin xyz="0.0 0.0 0.0" rpy="0.0 0.0 0.0"/>
      <geometry>
        <mesh filename="../mesh/visual/overconstrained/link1.obj" scale="0.001 0.001 0.001"/>
      </geometry>
    </visual>
    <collision>
      <origin xyz="0.0 0.0 0.0" rpy="0.0 0.0 0.0"/>
      <geometry>
        <mesh filename="../mesh/collision/overconstrained/link1.obj" scale="0.001 0.001 0.001"/>
      </geometry>
    </collision>
  </link>
  <link name="a1-link2">
    <inertial>
      <origin xyz="0.00257 -0.06454 0.00387" rpy="0 0 0"/>
      <mass value="0.0285"/>
      <inertia ixx="4.538e-05" iyy="1.336e-06" izz="4.555e-05" ixy="1.857e-06" iyz="-1.328e-06" ixz="-1.65e-07"/>
    </inertial>
    <visual>
      <origin xyz="0.0 0.0 0.0" rpy="0.0 0.0 0.0"/>
      <geometry>
        <mesh filename="../mesh/visual/overconstrained/link2.obj" scale="0.001 0.001 0.001"/>
      </geometry>
    </visual>
    <collision>
      <origin xyz="0.0 0.0 0.0" rpy="0.0 0.0 0.0"/>
      <geometry>
        <mesh filename="../mesh/collision/overconstrained/link2.obj" scale="0.001 0.001 0.001"/>
      </geometry>
    </collision>
  </link>
  <link name="a1-link4">
    <inertial>
      <origin xyz="-0.00264 -0.06759 -0.00339" rpy="0 0 0"/>
      <mass value="0.0276"/>
      <inertia ixx="3.8455e-05" iyy="1.4216e-06" izz="3.8817e-05" ixy="-1.644e-06" iyz="4.34e-07" ixz="-2.01e-07"/>
    </inertial>
    <visual>
      <origin xyz="0.0 0.0 0.0" rpy="0.0 0.0 0.0"/>
      <geometry>
        <mesh filename="../mesh/visual/overconstrained/link4.obj" scale="0.001 0.001 0.001"/>
      </geometry>
    </visual>
    <collision>
      <origin xyz="0.0 0.0 0.0" rpy="0.0 0.0 0.0"/>
      <geometry>
        <mesh filename="../mesh/collision/overconstrained/link4.obj" scale="0.001 0.001 0.001"/>
      </geometry>
    </collision>
  </link>
  <link name="a1-link3">
    <inertial>
      <origin xyz="0.00239 -0.05338 -0.00031" rpy="0 0 0"/>
      <mass value="0.0218"/>
      <inertia ixx="3.5710e-05" iyy="1.210e-06" izz="3.5412e-05" ixy="1.720e-06" iyz="-4.186e-06" ixz="1.474e-07"/>
    </inertial>
    <visual>
      <origin xyz="0.0 0.0 0.0" rpy="0.0 0.0 0.0"/>
      <geometry>
        <mesh filename="../mesh/visual/overconstrained/link3.obj" scale="0.001 0.001 0.001"/>
      </geometry>
    </visual>
    <collision>
      <origin xyz="0.0 0.0 0.0" rpy="0.0 0.0 0.0"/>
      <geometry>
        <mesh filename="../mesh/collision/overconstrained/link3.obj" scale="0.001 0.001 0.001"/>
      </geometry>
    </collision>
  </link>
  <link name="a1-tip_bearings">
    <inertial>
      <origin xyz="0.0 0.0 0.00534" rpy="0 0 0"/>
      <mass value="0.0102"/>
      <inertia ixx="6.78e-07" iyy="6.78e-07" izz="9.8e-08" ixy="0.0" iyz="0.0" ixz="0.0"/>
    </inertial>
    <visual>
      <origin xyz="0.0 0.0 0.0" rpy="0.0 0.0 0.0"/>
      <geometry>
        <mesh filename="../mesh/visual/overconstrained/tip_bearings.obj" scale="0.001 0.001 0.001"/>
      </geometry>
    </visual>
    <collision>
      <origin xyz="0.0 0.0 0.0" rpy="0.0 0.0 0.0"/>
      <geometry>
        <mesh filename="../mesh/collision/overconstrained/tip_bearings.obj" scale="0.001 0.001 0.001"/>
      </geometry>
    </collision>
  </link>
  <link name="a1-fingertip_frame">
    <inertial>
      <origin xyz="0.0 -0.0 0.01" rpy="0 0 0"/>
      <mass value="0.002"/>
      <inertia ixx="9.2e-08" iyy="9.2e-08" izz="7.9e-08" ixy="0.0" iyz="0.0" ixz="0.0"/>
    </inertial>
    <visual>
      <origin xyz="0.0 0.0 0.0" rpy="0.0 0.0 0.0"/>
      <geometry>
        <mesh filename="../mesh/visual/overconstrained_v2/fingertip_visual.obj" scale="0.001 0.001 0.001"/>
      </geometry>
    </visual>
    <collision>
      <origin xyz="0.0 0.0 0.0" rpy="0.0 0.0 0.0"/>
      <geometry>
        <mesh filename="../mesh/collision/overconstrained_v2/fingertip_tip_only_collision.obj" scale="0.001 0.001 0.001"/>
      </geometry>
    </collision>
  </link>
  <joint name="a1-dof1" type="revolute">
    <parent link="base"/>
    <child link="a1-two_dof_module"/>
    <origin xyz="-0.03875 0.13540 0.0" rpy="3.14159265 0.7853981625 0"/>
    <axis xyz="0 1 0"/>
    <limit effort="1000" lower="-3.14159265" upper="3.14159265" velocity="3.35"/>
  </joint>
  <joint name="a1-dof2" type="revolute">
    <parent link="a1-two_dof_module"/>
    <child link="a1-link4"/>
    <axis xyz="0 0 -1"/>
    <limit effort="1000" lower="-3.14159265" upper="3.14159265" velocity="3.35"/>
    <origin xyz="0 0 0.0558" rpy="0 0 0"/>
  </joint>
  <joint name="a1-dof3" type="revolute">
    <parent link="a1-two_dof_module"/>
    <child link="a1-link1"/>
    <axis xyz="0 0 -1"/>
    <limit effort="1000" lower="-3.14159265" upper="3.14159265" velocity="3.35"/>
    <origin xyz="0 0 0.057800000000000004" rpy="0 0 0"/>
  </joint>
  <joint name="a1-link4_to_link3" type="revolute">
    <parent link="a1-link4"/>
    <child link="a1-link3"/>
    <axis xyz="0 0 1"/>
    <limit effort="1000" lower="-3.14159265" upper="3.14159265" velocity="1000"/>
    <origin xyz="0.000707 -0.1 0.001707" rpy="0 0.7853981625 0"/>
  </joint>
  <joint name="a1-link1_to_link2" type="revolute">
    <parent link="a1-link1"/>
    <child link="a1-link2"/>
    <axis xyz="0 0 1"/>
    <limit effort="1000" lower="-3.14159265" upper="3.14159265" velocity="1000"/>
    <origin xyz="-0.000707 -0.1 -0.000293" rpy="0 -0.7853981625 0"/>
  </joint>
  <joint name="a1-tip_bearings_fixed" type="fixed">
    <parent link="a1-link2"/>
    <child link="a1-tip_bearings"/>
    <origin xyz="0 -0.1 -0.001" rpy="0 0.7853981625 0"/>
  </joint>
  <joint name="a1-closed_chain_revolute" type="revolute">
    <parent link="a1-link3"/>
    <child link="a1-tip_bearings"/>
    <origin xyz="0 -0.1 -0.001" rpy="0 -0.7853981625 0"/>
    <axis xyz="0 0 1"/>
    <limit effort="1000" lower="-3.14159265" upper="3.14159265" velocity="1000"/>
  </joint>
  <joint name="a1-fingertip_frame_fix" type="fixed">
    <parent link="a1-link3"/>
    <child link="a1-fingertip_frame"/>
    <!-- <origin xyz="0.004243 -0.127 -0.005243" rpy="0 0 0"/> -->
    <origin xyz="0.004243 -0.13 -0.005243" rpy="0 0 0"/>
  </joint>
  <link name="a3-two_dof_module">
    <inertial>
      <origin xyz="-0.00028 0.01047 -0.01023" rpy="0 0 0"/>
      <mass value="0.246"/>
      <inertia ixx="0.00025" iyy="0.00010" izz="0.00020" ixy="0.0" ixz="0.0" iyz="0.0"/>
    </inertial>
    <visual>
      <origin xyz="0.0 0.0 0.019" rpy="0.0 0.0 0.0"/>
      <geometry>
        <mesh filename="../mesh/visual/overconstrained_v2/two_dof_module_simplified.stl" scale="0.001 0.001 0.001"/>
      </geometry>
    </visual>
    <collision>
      <origin xyz="0.0 0.0 0.019" rpy="0.0 0.0 0.0"/>
      <geometry>
        <mesh filename="../mesh/collision/overconstrained_v2/2dof_module_collision.STL" scale="0.001 0.001 0.001"/>
      </geometry>
    </collision>
  </link>
  <link name="a3-link1">
    <inertial>
      <origin xyz="0.0024 -0.0614 -0.0011" rpy="0 0 0"/>
      <mass value="0.0299"/>
      <inertia ixx="5.1956e-05" iyy="1.979e-06" izz="5.1656e-05" ixy="2.088e-06" iyz="-5.394e-06" ixz="4.522e-07"/>
    </inertial>
    <visual>
      <origin xyz="0.0 0.0 0.0" rpy="0.0 0.0 0.0"/>
      <geometry>
        <mesh filename="../mesh/visual/overconstrained/link1.obj" scale="0.001 0.001 0.001"/>
      </geometry>
    </visual>
    <collision>
      <origin xyz="0.0 0.0 0.0" rpy="0.0 0.0 0.0"/>
      <geometry>
        <mesh filename="../mesh/collision/overconstrained/link1.obj" scale="0.001 0.001 0.001"/>
      </geometry>
    </collision>
  </link>
  <link name="a3-link2_right">
    <inertial>
      <origin xyz="-0.00239 -0.05338 -0.00031" rpy="0 0 0"/>
      <mass value="0.0218"/>
      <inertia ixx="3.571e-05" iyy="1.210e-06" izz="3.541e-05" ixy="-1.720e-06" iyz="-4.186e-06" ixz="-1.471e-07"/>
    </inertial>
    <visual>
      <origin xyz="0.0 0.0 0.0" rpy="0.0 0.0 0.0"/>
      <geometry>
        <mesh filename="../mesh/visual/overconstrained/link2_right.obj" scale="0.001 0.001 0.001"/>
      </geometry>
    </visual>
    <collision>
      <origin xyz="0.0 0.0 0.0" rpy="0.0 0.0 0.0"/>
      <geometry>
        <mesh filename="../mesh/collision/overconstrained/link2_right.obj" scale="0.001 0.001 0.001"/>
      </geometry>
    </collision>
  </link>
  <link name="a3-link4">
    <inertial>
      <origin xyz="-0.00264 -0.06759 -0.00339" rpy="0 0 0"/>
      <mass value="0.0276"/>
      <inertia ixx="3.8455e-05" iyy="1.4216e-06" izz="3.8817e-05" ixy="-1.644e-06" iyz="4.34e-07" ixz="-2.01e-07"/>
    </inertial>
    <visual>
      <origin xyz="0.0 0.0 0.0" rpy="0.0 0.0 0.0"/>
      <geometry>
        <mesh filename="../mesh/visual/overconstrained/link4.obj" scale="0.001 0.001 0.001"/>
      </geometry>
    </visual>
    <collision>
      <origin xyz="0.0 0.0 0.0" rpy="0.0 0.0 0.0"/>
      <geometry>
        <mesh filename="../mesh/collision/overconstrained/link4.obj" scale="0.001 0.001 0.001"/>
      </geometry>
    </collision>
  </link>
  <link name="a3-link3_right">
    <inertial>
      <origin xyz="-0.00257 -0.06454 0.003872" rpy="0 0 0"/>
      <mass value="0.0285"/>
      <inertia ixx="4.538e-05" iyy="1.336e-06" izz="4.555e-05" ixy="-1.856e-06" iyz="-1.328e-06" ixz="1.65e-07"/>
    </inertial>
    <visual>
      <origin xyz="0.0 0.0 0.0" rpy="0.0 0.0 0.0"/>
      <geometry>
        <mesh filename="../mesh/visual/overconstrained/link3_right.obj" scale="0.001 0.001 0.001"/>
      </geometry>
    </visual>
    <collision>
      <origin xyz="0.0 0.0 0.0" rpy="0.0 0.0 0.0"/>
      <geometry>
        <mesh filename="../mesh/collision/overconstrained/link3_right.obj" scale="0.001 0.001 0.001"/>
      </geometry>
    </collision>
  </link>
  <link name="a3-tip_bearings">
    <inertial>
      <origin xyz="0.0 0.0 0.00534" rpy="0 0 0"/>
      <mass value="0.0102"/>
      <inertia ixx="6.78e-07" iyy="6.78e-07" izz="9.8e-08" ixy="0.0" iyz="0.0" ixz="0.0"/>
    </inertial>
    <visual>
      <origin xyz="0.0 0.0 0.0" rpy="0.0 0.0 0.0"/>
      <geometry>
        <mesh filename="../mesh/visual/overconstrained/tip_bearings.obj" scale="0.001 0.001 0.001"/>
      </geometry>
    </visual>
    <collision>
      <origin xyz="0.0 0.0 0.0" rpy="0.0 0.0 0.0"/>
      <geometry>
        <mesh filename="../mesh/collision/overconstrained/tip_bearings.obj" scale="0.001 0.001 0.001"/>
      </geometry>
    </collision>
  </link>
  <link name="a3-fingertip_frame">
    <inertial>
      <origin xyz="0.0 -0.0 0.01" rpy="0 0 0"/>
      <mass value="0.002"/>
      <inertia ixx="9.2e-08" iyy="9.2e-08" izz="7.9e-08" ixy="0.0" iyz="0.0" ixz="0.0"/>
    </inertial>
    <visual>
      <origin xyz="0.0 0.0 0.0" rpy="0.0 0.0 0.0"/>
      <geometry>
        <mesh filename="../mesh/visual/overconstrained_v2/fingertip_visual.obj" scale="0.001 0.001 0.001"/>
      </geometry>
    </visual>
    <collision>
      <origin xyz="0.0 0.0 0.0" rpy="0.0 0.0 0.0"/>
      <geometry>
        <mesh filename="../mesh/collision/overconstrained_v2/fingertip_tip_only_collision.obj" scale="0.001 0.001 0.001"/>
      </geometry>
    </collision>
  </link>
  <joint name="a3-dof1" type="revolute">
    <parent link="base"/>
    <child link="a3-two_dof_module"/>
    <origin xyz="-0.03875 -0.13540 0.0" rpy="0 -2.3561944875000003 0"/>
    <axis xyz="0 1 0"/>
    <limit effort="1000" lower="-3.14159265" upper="3.14159265" velocity="3.35"/>
  </joint>
  <joint name="a3-dof2" type="revolute">
    <parent link="a3-two_dof_module"/>
    <child link="a3-link4"/>
    <axis xyz="0 0 -1"/>
    <limit effort="1000" lower="-3.14159265" upper="3.14159265" velocity="3.35"/>
    <origin xyz="0 0 0.0558" rpy="0 0 0"/>
  </joint>
  <joint name="a3-dof3" type="revolute">
    <parent link="a3-two_dof_module"/>
    <child link="a3-link1"/>
    <axis xyz="0 0 -1"/>
    <limit effort="1000" lower="-3.14159265" upper="3.14159265" velocity="3.35"/>
    <origin xyz="0 0 0.057800000000000004" rpy="0 0 0"/>
  </joint>
  <joint name="a3-link4_to_link3_right" type="revolute">
    <parent link="a3-link4"/>
    <child link="a3-link3_right"/>
    <axis xyz="0 0 1"/>
    <limit effort="1000" lower="-3.14159265" upper="3.14159265" velocity="1000"/>
    <origin xyz="0.000707 -0.1 0.001707" rpy="0 0.7853981625 0"/>
  </joint>
  <joint name="a3-link1_to_link2_right" type="revolute">
    <parent link="a3-link1"/>
    <child link="a3-link2_right"/>
    <axis xyz="0 0 1"/>
    <limit effort="1000" lower="-3.14159265" upper="3.14159265" velocity="1000"/>
    <origin xyz="-0.000707 -0.1 -0.000293" rpy="0 -0.7853981625 0"/>
  </joint>
  <joint name="a3-tip_bearings_fixed" type="fixed">
    <parent link="a3-link3_right"/>
    <child link="a3-tip_bearings"/>
    <origin xyz="0 -0.1 -0.001" rpy="0 -0.7853981625 0"/>
  </joint>
  <joint name="a3-closed_chain_revolute" type="revolute">
    <parent link="a3-link2_right"/>
    <child link="a3-tip_bearings"/>
    <axis xyz="0 0 1"/>
    <origin xyz="0 -0.1 -0.001" rpy="0 0.7853981625 0"/>
    <limit effort="1000" lower="-3.14159265" upper="3.14159265" velocity="1000"/>
  </joint>
  <joint name="a3-fingertip_frame_fix" type="fixed">
    <parent link="a3-link2_right"/>
    <child link="a3-fingertip_frame"/>
    <!-- <origin xyz="0.004243 -0.127 -0.005243" rpy="0 0 -${PI}"/> -->
    <origin xyz="-0.004243 -0.13 -0.005243" rpy="0 0 0"/>
  </joint>
  <link name="a2-two_dof_module">
    <inertial>
      <origin xyz="-0.00028 0.01047 -0.01023" rpy="0 0 0"/>
      <mass value="0.246"/>
      <inertia ixx="0.00025" iyy="0.00010" izz="0.00020" ixy="0.0" ixz="0.0" iyz="0.0"/>
    </inertial>
    <visual>
      <origin xyz="0.0 0.0 0.019" rpy="0.0 0.0 0.0"/>
      <geometry>
        <mesh filename="../mesh/visual/overconstrained_v2/two_dof_module_simplified.stl" scale="0.001 0.001 0.001"/>
      </geometry>
    </visual>
    <collision>
      <origin xyz="0.0 0.0 0.019" rpy="0.0 0.0 0.0"/>
      <geometry>
        <mesh filename="../mesh/collision/overconstrained_v2/2dof_module_collision.STL" scale="0.001 0.001 0.001"/>
      </geometry>
    </collision>
  </link>
  <link name="a2-link1">
    <inertial>
      <origin xyz="0.0024 -0.0614 -0.0011" rpy="0 0 0"/>
      <mass value="0.0299"/>
      <inertia ixx="5.1956e-05" iyy="1.979e-06" izz="5.1656e-05" ixy="2.088e-06" iyz="-5.394e-06" ixz="4.522e-07"/>
    </inertial>
    <visual>
      <origin xyz="0.0 0.0 0.0" rpy="0.0 0.0 0.0"/>
      <geometry>
        <mesh filename="../mesh/visual/overconstrained/link1.obj" scale="0.001 0.001 0.001"/>
      </geometry>
    </visual>
    <collision>
      <origin xyz="0.0 0.0 0.0" rpy="0.0 0.0 0.0"/>
      <geometry>
        <mesh filename="../mesh/collision/overconstrained/link1.obj" scale="0.001 0.001 0.001"/>
      </geometry>
    </collision>
  </link>
  <link name="a2-link2_right">
    <inertial>
      <origin xyz="-0.00239 -0.05338 -0.00031" rpy="0 0 0"/>
      <mass value="0.0218"/>
      <inertia ixx="3.571e-05" iyy="1.210e-06" izz="3.541e-05" ixy="-1.720e-06" iyz="-4.186e-06" ixz="-1.471e-07"/>
    </inertial>
    <visual>
      <origin xyz="0.0 0.0 0.0" rpy="0.0 0.0 0.0"/>
      <geometry>
        <mesh filename="../mesh/visual/overconstrained/link2_right.obj" scale="0.001 0.001 0.001"/>
      </geometry>
    </visual>
    <collision>
      <origin xyz="0.0 0.0 0.0" rpy="0.0 0.0 0.0"/>
      <geometry>
        <mesh filename="../mesh/collision/overconstrained/link2_right.obj" scale="0.001 0.001 0.001"/>
      </geometry>
    </collision>
  </link>
  <link name="a2-link4">
    <inertial>
      <origin xyz="-0.00264 -0.06759 -0.00339" rpy="0 0 0"/>
      <mass value="0.0276"/>
      <inertia ixx="3.8455e-05" iyy="1.4216e-06" izz="3.8817e-05" ixy="-1.644e-06" iyz="4.34e-07" ixz="-2.01e-07"/>
    </inertial>
    <visual>
      <origin xyz="0.0 0.0 0.0" rpy="0.0 0.0 0.0"/>
      <geometry>
        <mesh filename="../mesh/visual/overconstrained/link4.obj" scale="0.001 0.001 0.001"/>
      </geometry>
    </visual>
    <collision>
      <origin xyz="0.0 0.0 0.0" rpy="0.0 0.0 0.0"/>
      <geometry>
        <mesh filename="../mesh/collision/overconstrained/link4.obj" scale="0.001 0.001 0.001"/>
      </geometry>
    </collision>
  </link>
  <link name="a2-link3_right">
    <inertial>
      <origin xyz="-0.00257 -0.06454 0.003872" rpy="0 0 0"/>
      <mass value="0.0285"/>
      <inertia ixx="4.538e-05" iyy="1.336e-06" izz="4.555e-05" ixy="-1.856e-06" iyz="-1.328e-06" ixz="1.65e-07"/>
    </inertial>
    <visual>
      <origin xyz="0.0 0.0 0.0" rpy="0.0 0.0 0.0"/>
      <geometry>
        <mesh filename="../mesh/visual/overconstrained/link3_right.obj" scale="0.001 0.001 0.001"/>
      </geometry>
    </visual>
    <collision>
      <origin xyz="0.0 0.0 0.0" rpy="0.0 0.0 0.0"/>
      <geometry>
        <mesh filename="../mesh/collision/overconstrained/link3_right.obj" scale="0.001 0.001 0.001"/>
      </geometry>
    </collision>
  </link>
  <link name="a2-tip_bearings">
    <inertial>
      <origin xyz="0.0 0.0 0.00534" rpy="0 0 0"/>
      <mass value="0.0102"/>
      <inertia ixx="6.78e-07" iyy="6.78e-07" izz="9.8e-08" ixy="0.0" iyz="0.0" ixz="0.0"/>
    </inertial>
    <visual>
      <origin xyz="0.0 0.0 0.0" rpy="0.0 0.0 0.0"/>
      <geometry>
        <mesh filename="../mesh/visual/overconstrained/tip_bearings.obj" scale="0.001 0.001 0.001"/>
      </geometry>
    </visual>
    <collision>
      <origin xyz="0.0 0.0 0.0" rpy="0.0 0.0 0.0"/>
      <geometry>
        <mesh filename="../mesh/collision/overconstrained/tip_bearings.obj" scale="0.001 0.001 0.001"/>
      </geometry>
    </collision>
  </link>
  <link name="a2-fingertip_frame">
    <inertial>
      <origin xyz="0.0 -0.0 0.01" rpy="0 0 0"/>
      <mass value="0.002"/>
      <inertia ixx="9.2e-08" iyy="9.2e-08" izz="7.9e-08" ixy="0.0" iyz="0.0" ixz="0.0"/>
    </inertial>
    <visual>
      <origin xyz="0.0 0.0 0.0" rpy="0.0 0.0 0.0"/>
      <geometry>
        <mesh filename="../mesh/visual/overconstrained_v2/fingertip_visual.obj" scale="0.001 0.001 0.001"/>
      </geometry>
    </visual>
    <collision>
      <origin xyz="0.0 0.0 0.0" rpy="0.0 0.0 0.0"/>
      <geometry>
        <mesh filename="../mesh/collision/overconstrained_v2/fingertip_tip_only_collision.obj" scale="0.001 0.001 0.001"/>
      </geometry>
    </collision>
  </link>
  <joint name="a2-dof1" type="revolute">
    <parent link="base"/>
    <child link="a2-two_dof_module"/>
    <origin xyz="0.03875 0.13540 0.0" rpy="3.14159265 -0.7853981625 0"/>
    <axis xyz="0 1 0"/>
    <limit effort="1000" lower="-3.14159265" upper="3.14159265" velocity="3.35"/>
  </joint>
  <joint name="a2-dof2" type="revolute">
    <parent link="a2-two_dof_module"/>
    <child link="a2-link4"/>
    <axis xyz="0 0 -1"/>
    <limit effort="1000" lower="-3.14159265" upper="3.14159265" velocity="3.35"/>
    <origin xyz="0 0 0.0558" rpy="0 0 0"/>
  </joint>
  <joint name="a2-dof3" type="revolute">
    <parent link="a2-two_dof_module"/>
    <child link="a2-link1"/>
    <axis xyz="0 0 -1"/>
    <limit effort="1000" lower="-3.14159265" upper="3.14159265" velocity="3.35"/>
    <origin xyz="0 0 0.057800000000000004" rpy="0 0 0"/>
  </joint>
  <joint name="a2-link4_to_link3_right" type="revolute">
    <parent link="a2-link4"/>
    <child link="a2-link3_right"/>
    <axis xyz="0 0 1"/>
    <limit effort="1000" lower="-3.14159265" upper="3.14159265" velocity="1000"/>
    <origin xyz="0.000707 -0.1 0.001707" rpy="0 0.7853981625 0"/>
  </joint>
  <joint name="a2-link1_to_link2_right" type="revolute">
    <parent link="a2-link1"/>
    <child link="a2-link2_right"/>
    <axis xyz="0 0 1"/>
    <limit effort="1000" lower="-3.14159265" upper="3.14159265" velocity="1000"/>
    <origin xyz="-0.000707 -0.1 -0.000293" rpy="0 -0.7853981625 0"/>
  </joint>
  <joint name="a2-tip_bearings_fixed" type="fixed">
    <parent link="a2-link3_right"/>
    <child link="a2-tip_bearings"/>
    <origin xyz="0 -0.1 -0.001" rpy="0 -0.7853981625 0"/>
  </joint>
  <joint name="a2-closed_chain_revolute" type="revolute">
    <parent link="a2-link2_right"/>
    <child link="a2-tip_bearings"/>
    <axis xyz="0 0 1"/>
    <origin xyz="0 -0.1 -0.001" rpy="0 0.7853981625 0"/>
    <limit effort="1000" lower="-3.14159265" upper="3.14159265" velocity="1000"/>
  </joint>
  <joint name="a2-fingertip_frame_fix" type="fixed">
    <parent link="a2-link2_right"/>
    <child link="a2-fingertip_frame"/>
    <!-- <origin xyz="0.004243 -0.127 -0.005243" rpy="0 0 -${PI}"/> -->
    <origin xyz="-0.004243 -0.13 -0.005243" rpy="0 0 0"/>
  </joint>
  <link name="a4-two_dof_module">
    <inertial>
      <origin xyz="-0.00028 0.01047 -0.01023" rpy="0 0 0"/>
      <mass value="0.246"/>
      <inertia ixx="0.00025" iyy="0.00010" izz="0.00020" ixy="0.0" ixz="0.0" iyz="0.0"/>
    </inertial>
    <visual>
      <origin xyz="0.0 0.0 0.019" rpy="0.0 0.0 0.0"/>
      <geometry>
        <mesh filename="../mesh/visual/overconstrained_v2/two_dof_module_simplified.stl" scale="0.001 0.001 0.001"/>
      </geometry>
    </visual>
    <collision>
      <origin xyz="0.0 0.0 0.019" rpy="0.0 0.0 0.0"/>
      <geometry>
        <mesh filename="../mesh/collision/overconstrained_v2/2dof_module_collision.STL" scale="0.001 0.001 0.001"/>
      </geometry>
    </collision>
  </link>
  <link name="a4-link1">
    <inertial>
      <origin xyz="0.0024 -0.0614 -0.0011" rpy="0 0 0"/>
      <mass value="0.0299"/>
      <inertia ixx="5.1956e-05" iyy="1.979e-06" izz="5.1656e-05" ixy="2.088e-06" iyz="-5.394e-06" ixz="4.522e-07"/>
    </inertial>
    <visual>
      <origin xyz="0.0 0.0 0.0" rpy="0.0 0.0 0.0"/>
      <geometry>
        <mesh filename="../mesh/visual/overconstrained/link1.obj" scale="0.001 0.001 0.001"/>
      </geometry>
    </visual>
    <collision>
      <origin xyz="0.0 0.0 0.0" rpy="0.0 0.0 0.0"/>
      <geometry>
        <mesh filename="../mesh/collision/overconstrained/link1.obj" scale="0.001 0.001 0.001"/>
      </geometry>
    </collision>
  </link>
  <link name="a4-link2">
    <inertial>
      <origin xyz="0.00257 -0.06454 0.00387" rpy="0 0 0"/>
      <mass value="0.0285"/>
      <inertia ixx="4.538e-05" iyy="1.336e-06" izz="4.555e-05" ixy="1.857e-06" iyz="-1.328e-06" ixz="-1.65e-07"/>
    </inertial>
    <visual>
      <origin xyz="0.0 0.0 0.0" rpy="0.0 0.0 0.0"/>
      <geometry>
        <mesh filename="../mesh/visual/overconstrained/link2.obj" scale="0.001 0.001 0.001"/>
      </geometry>
    </visual>
    <collision>
      <origin xyz="0.0 0.0 0.0" rpy="0.0 0.0 0.0"/>
      <geometry>
        <mesh filename="../mesh/collision/overconstrained/link2.obj" scale="0.001 0.001 0.001"/>
      </geometry>
    </collision>
  </link>
  <link name="a4-link4">
    <inertial>
      <origin xyz="-0.00264 -0.06759 -0.00339" rpy="0 0 0"/>
      <mass value="0.0276"/>
      <inertia ixx="3.8455e-05" iyy="1.4216e-06" izz="3.8817e-05" ixy="-1.644e-06" iyz="4.34e-07" ixz="-2.01e-07"/>
    </inertial>
    <visual>
      <origin xyz="0.0 0.0 0.0" rpy="0.0 0.0 0.0"/>
      <geometry>
        <mesh filename="../mesh/visual/overconstrained/link4.obj" scale="0.001 0.001 0.001"/>
      </geometry>
    </visual>
    <collision>
      <origin xyz="0.0 0.0 0.0" rpy="0.0 0.0 0.0"/>
      <geometry>
        <mesh filename="../mesh/collision/overconstrained/link4.obj" scale="0.001 0.001 0.001"/>
      </geometry>
    </collision>
  </link>
  <link name="a4-link3">
    <inertial>
      <origin xyz="0.00239 -0.05338 -0.00031" rpy="0 0 0"/>
      <mass value="0.0218"/>
      <inertia ixx="3.5710e-05" iyy="1.210e-06" izz="3.5412e-05" ixy="1.720e-06" iyz="-4.186e-06" ixz="1.474e-07"/>
    </inertial>
    <visual>
      <origin xyz="0.0 0.0 0.0" rpy="0.0 0.0 0.0"/>
      <geometry>
        <mesh filename="../mesh/visual/overconstrained/link3.obj" scale="0.001 0.001 0.001"/>
      </geometry>
    </visual>
    <collision>
      <origin xyz="0.0 0.0 0.0" rpy="0.0 0.0 0.0"/>
      <geometry>
        <mesh filename="../mesh/collision/overconstrained/link3.obj" scale="0.001 0.001 0.001"/>
      </geometry>
    </collision>
  </link>
  <link name="a4-tip_bearings">
    <inertial>
      <origin xyz="0.0 0.0 0.00534" rpy="0 0 0"/>
      <mass value="0.0102"/>
      <inertia ixx="6.78e-07" iyy="6.78e-07" izz="9.8e-08" ixy="0.0" iyz="0.0" ixz="0.0"/>
    </inertial>
    <visual>
      <origin xyz="0.0 0.0 0.0" rpy="0.0 0.0 0.0"/>
      <geometry>
        <mesh filename="../mesh/visual/overconstrained/tip_bearings.obj" scale="0.001 0.001 0.001"/>
      </geometry>
    </visual>
    <collision>
      <origin xyz="0.0 0.0 0.0" rpy="0.0 0.0 0.0"/>
      <geometry>
        <mesh filename="../mesh/collision/overconstrained/tip_bearings.obj" scale="0.001 0.001 0.001"/>
      </geometry>
    </collision>
  </link>
  <link name="a4-fingertip_frame">
    <inertial>
      <origin xyz="0.0 -0.0 0.01" rpy="0 0 0"/>
      <mass value="0.002"/>
      <inertia ixx="9.2e-08" iyy="9.2e-08" izz="7.9e-08" ixy="0.0" iyz="0.0" ixz="0.0"/>
    </inertial>
    <visual>
      <origin xyz="0.0 0.0 0.0" rpy="0.0 0.0 0.0"/>
      <geometry>
        <mesh filename="../mesh/visual/overconstrained_v2/fingertip_visual.obj" scale="0.001 0.001 0.001"/>
      </geometry>
    </visual>
    <collision>
      <origin xyz="0.0 0.0 0.0" rpy="0.0 0.0 0.0"/>
      <geometry>
        <mesh filename="../mesh/collision/overconstrained_v2/fingertip_tip_only_collision.obj" scale="0.001 0.001 0.001"/>
      </geometry>
    </collision>
  </link>
  <joint name="a4-dof1" type="revolute">
    <parent link="base"/>
    <child link="a4-two_dof_module"/>
    <origin xyz="0.03875 -0.13540 0.0" rpy="0 2.3561944875000003 0"/>
    <axis xyz="0 1 0"/>
    <limit effort="1000" lower="-3.14159265" upper="3.14159265" velocity="3.35"/>
  </joint>
  <joint name="a4-dof2" type="revolute">
    <parent link="a4-two_dof_module"/>
    <child link="a4-link4"/>
    <axis xyz="0 0 -1"/>
    <limit effort="1000" lower="-3.14159265" upper="3.14159265" velocity="3.35"/>
    <origin xyz="0 0 0.0558" rpy="0 0 0"/>
  </joint>
  <joint name="a4-dof3" type="revolute">
    <parent link="a4-two_dof_module"/>
    <child link="a4-link1"/>
    <axis xyz="0 0 -1"/>
    <limit effort="1000" lower="-3.14159265" upper="3.14159265" velocity="3.35"/>
    <origin xyz="0 0 0.057800000000000004" rpy="0 0 0"/>
  </joint>
  <joint name="a4-link4_to_link3" type="revolute">
    <parent link="a4-link4"/>
    <child link="a4-link3"/>
    <axis xyz="0 0 1"/>
    <limit effort="1000" lower="-3.14159265" upper="3.14159265" velocity="1000"/>
    <origin xyz="0.000707 -0.1 0.001707" rpy="0 0.7853981625 0"/>
  </joint>
  <joint name="a4-link1_to_link2" type="revolute">
    <parent link="a4-link1"/>
    <child link="a4-link2"/>
    <axis xyz="0 0 1"/>
    <limit effort="1000" lower="-3.14159265" upper="3.14159265" velocity="1000"/>
    <origin xyz="-0.000707 -0.1 -0.000293" rpy="0 -0.7853981625 0"/>
  </joint>
  <joint name="a4-tip_bearings_fixed" type="fixed">
    <parent link="a4-link2"/>
    <child link="a4-tip_bearings"/>
    <origin xyz="0 -0.1 -0.001" rpy="0 0.7853981625 0"/>
  </joint>
  <joint name="a4-closed_chain_revolute" type="revolute">
    <parent link="a4-link3"/>
    <child link="a4-tip_bearings"/>
    <origin xyz="0 -0.1 -0.001" rpy="0 -0.7853981625 0"/>
    <axis xyz="0 0 1"/>
    <limit effort="1000" lower="-3.14159265" upper="3.14159265" velocity="1000"/>
  </joint>
  <joint name="a4-fingertip_frame_fix" type="fixed">
    <parent link="a4-link3"/>
    <child link="a4-fingertip_frame"/>
    <!-- <origin xyz="0.004243 -0.127 -0.005243" rpy="0 0 0"/> -->
    <origin xyz="0.004243 -0.13 -0.005243" rpy="0 0 0"/>
  </joint>
</robot>
