<?xml version='1.0' encoding='utf-8'?>
<robot name="bennett">
    <link name="Basic_Body">
        <inertial>
            <origin xyz="3.269975336552785e-11 -0.0012499987421279188 -0.004750000038203694" rpy="0.0 0.0 0.0" />
            <mass value="3.578209936079509" />
            <inertia ixx="0.005306000538019551" iyy="0.07835805606453539" izz="0.08260422228557268" ixy="-7.922195039377751e-10" iyz="2.646563090208387e-12" ixz="2.0546265609645002e-11" />
        </inertial>
        <visual name="Body1_visual">
            <origin xyz="0.0 0.0 0.0" rpy="0.0 0.0 0.0" />
            <geometry>\
                <mesh filename="meshes/Body1.stl" />
            </geometry>
        </visual>
        <collision name="Body1_collision">
            <origin xyz="0.0 0.0 0.0" rpy="0.0 0.0 0.0" />
            <geometry>
                <mesh filename="meshes/Body1.stl" />
            </geometry>
        </collision>
    </link>
    <link name="FL-Single-Motor1">
        <inertial>
            <origin xyz="-0.008058511743548387 0.02429103275373483 0.01675000000217054" rpy="0.0 -0.0 0.0" />
            <mass value="0.7011939191100404" />
            <inertia ixx="0.0002624831375912101" iyy="0.0001999898760020602" izz="0.0003354208086328251" ixy="6.052823711328627e-07" iyz="1.6545792513866786e-14" ixz="4.015711374538711e-14" />
        </inertial>
        <visual name="FL-Single-Motor1_visual">
            <origin xyz="-0.041749999999999954 0.039250000000000014 0.016749999999999973" rpy="-1.5707963267948968 -1.5707963267948966 0" />
            <geometry>
                <mesh filename="meshes/FL-Single-Motor1.stl" />
            </geometry>
        </visual>
        <collision name="FL-Single-Motor1_collision">
            <origin xyz="-0.041749999999999954 0.039250000000000014 0.016749999999999973" rpy="-1.5707963267948968 -1.5707963267948966 0" />
            <geometry>
                <mesh filename="meshes/FL-Single-Motor1.stl" />
            </geometry>
        </collision>
    </link>
    <link name="FL-Double-Motor1">
        <inertial>
            <origin xyz="-0.06716414766997808 0.005424940913474359 0.009451637209221939" rpy="0.0 -0.0 0.0" />
            <mass value="2.4365544485369104" />
            <inertia ixx="0.0015776729226480435" iyy="0.004138553852375479" izz="0.0036819158459298618" ixy="-9.379314924728993e-07" iyz="-0.000391874707849696" ixz="-3.820435682685987e-06" />
        </inertial>
        <visual name="FL-Double-Motor1_visual">
            <origin xyz="-0.08224999999999996 7.105427357601002e-17 1.7763568394002505e-17" rpy="7.351718556377353e-17 -0.5235987755982987 -1.5707963267948966" />
            <geometry>
                <mesh filename="meshes/FL-Double-Motor1.stl" />
            </geometry>
        </visual>
        <!-- <collision name="FL-Double-Motor1_collision">
            <origin xyz="-0.08224999999999996 7.105427357601002e-17 1.7763568394002505e-17" rpy="7.351718556377353e-17 -0.5235987755982987 -1.5707963267948966" />
            <geometry>
                <mesh filename="meshes/FL-Double-Motor1.stl" />
            </geometry>
        </collision> -->
    </link>
    <link name="FL-leg-link11">
        <inertial>
            <origin xyz="-0.03429140259846331 -0.025620270865074807 -0.032139907337445095" rpy="0.0 -0.0 0.0" />
            <mass value="0.2812248770831842" />
            <inertia ixx="0.00037508091472133326" iyy="0.0005245373338503209" izz="0.0003865914241693823" ixy="-0.00016684321788432152" iyz="-0.00016900890290520024" ixz="-0.00024298630532138338" />
        </inertial>
        <visual name="FL-leg-link11_visual">
            <origin xyz="3.552713678800501e-17 -0.00866024939550707 0.005" rpy="2.4113673972429335 -0.7233643550425849 0.5349780765624936" />
            <geometry>
                <mesh filename="meshes/FL-leg-link11.stl" />
            </geometry>
        </visual>
        <collision name="FL-leg-link11_collision">
            <origin xyz="3.552713678800501e-17 -0.00866024939550707 0.005" rpy="2.4113673972429335 -0.7233643550425849 0.5349780765624936" />
            <geometry>
                <mesh filename="meshes/FL-leg-link11.stl" />
            </geometry>
        </collision>
    </link>
    <!-- <link name="FL-leg-link31">
        <inertial>
            <origin xyz="-0.02778400628485059 0.055168276262979175 -0.03393111131620757" rpy="0.0 -0.0 0.0" />
            <mass value="0.24917982527134377" />
            <inertia ixx="0.00033605593511459874" iyy="0.00020182024318858463" izz="0.0004193961374581041" ixy="0.00018081273401551588" iyz="0.00011104261942490137" ixz="-6.702549647197783e-05" />
        </inertial>
        <visual name="FL-leg-link31_visual">
            <origin xyz="0.0014091637734288832 0.0013351061748942783 0.00048140935420729395" rpy="2.5539983614180954 -1.1216409235946698 2.8696449517481084" />
            <geometry>
                <mesh filename="meshes/FL-leg-link31.stl" />
            </geometry>
        </visual>
        <collision name="FL-leg-link31_collision">
            <origin xyz="0.0014091637734288832 0.0013351061748942783 0.00048140935420729395" rpy="2.5539983614180954 -1.1216409235946698 2.8696449517481084" />
            <geometry>
                <mesh filename="meshes/FL-leg-link31.stl" />
            </geometry>
        </collision> 
    </link>
    <link name="FL-leg-link41">
        <inertial>
            <origin xyz="0.004921954583490891 -0.02626073054336221 -0.05031446570950962" rpy="0.0 -0.0 2.993496475303259e-49" />
            <mass value="0.30627894117127225" />
            <inertia ixx="0.0006760949920983014" iyy="0.0005858945834961368" izz="0.00013039225143291616" ixy="2.301365044248166e-05" iyz="-0.00024062034116102" ixz="5.226532165235328e-05" />
        </inertial>
        <visual name="FL-leg-link41_visual">
            <origin xyz="1.0658141036401502e-16 0.007967430604493071 -0.004600000000000009" rpy="-1.425522688459402 1.0410402069617724 -1.4028497870582188" />
            <geometry>
                <mesh filename="meshes/FL-leg-link41.stl" />
            </geometry>
        </visual>
        <collision name="FL-leg-link41_collision">
            <origin xyz="1.0658141036401502e-16 0.007967430604493071 -0.004600000000000009" rpy="-1.425522688459402 1.0410402069617724 -1.4028497870582188" />
            <geometry>
                <mesh filename="meshes/FL-leg-link41.stl" />
            </geometry>
        </collision> 
    </link> -->
    <link name="FL-leg-link21">
        <inertial>
            <origin xyz="0.010346172100577498 0.06008226076579483 -0.042272090850962056" rpy="0.0 -0.0 0.0" />
            <mass value="0.2812427717615869" />
            <inertia ixx="0.0006486758892672133" iyy="0.0002536070255569554" izz="0.0004459918063894514" ixy="-8.262971134321397e-05" iyz="0.0003040341934080505" ixz="6.0740625769847965e-05" />
        </inertial>
        <visual name="FL-leg-link21_visual">
            <origin xyz="-0.0010808984164838976 0.0011299930161795403 0.0012469101556211726" rpy="0.8167077041448609 -0.5445881822840094 0.2591490785230335" />
            <geometry>
                <mesh filename="meshes/FL-leg-link21.stl" />
            </geometry>
        </visual>
        <collision name="FL-leg-link21_collision">
            <origin xyz="-0.0010808984164838976 0.0011299930161795403 0.0012469101556211726" rpy="0.8167077041448609 -0.5445881822840094 0.2591490785230335" />
            <geometry>
                <mesh filename="meshes/FL-leg-link21.stl" />
            </geometry>
        </collision>
    </link>
    <link name="RL-Single-Motor1">
        <inertial>
            <origin xyz="0.008058511743548413 0.02429103275373483 0.01674999999782962" rpy="0.0 -0.0 0.0" />
            <mass value="0.7011939191100404" />
            <inertia ixx="0.00026248313759107134" iyy="0.00019998987600190754" izz="0.00033542080863282423" ixy="-6.052823711306943e-07" iyz="-1.6524975832155064e-14" ixz="4.018139987405078e-14" />
        </inertial>
        <visual name="RL-Single-Motor1_visual">
            <origin xyz="0.04174999999999999 0.03925 0.016750000000000043" rpy="-1.5707963267948966 1.5707963267948966 0" />
            <geometry>
                <mesh filename="meshes/RL-Single-Motor1.stl" />
            </geometry>
        </visual>
        <!-- <collision name="RL-Single-Motor1_collision">
            <origin xyz="0.04174999999999999 0.03925 0.016750000000000043" rpy="-1.5707963267948966 1.5707963267948966 0" />
            <geometry>
                <mesh filename="meshes/RL-Single-Motor1.stl" />
            </geometry>
        </collision> -->
    </link>
    <link name="RL-Double-Motor1">
        <inertial>
            <origin xyz="0.06716414766997808 0.004894133636625355 0.009737088157981173" rpy="0.0 -0.0 0.0" />
            <mass value="2.4365544485369104" />
            <inertia ixx="0.0015776729226481545" iyy="0.004181240515524223" izz="0.0036392291827812007" ixy="2.6701378276206005e-06" iyz="-0.000363663694475408" ixz="2.8889112605144524e-06" />
        </inertial>
        <visual name="RL-Double-Motor1_visual">
            <origin xyz="0.08224999999999996 0.0 5.062616992290714e-16" rpy="2.01526633129011e-15 0.463207708438608 1.5707963267948977" />
            <geometry>
                <mesh filename="meshes/RL-Double-Motor1.stl" />
            </geometry>
        </visual>
        <!-- <collision name="RL-Double-Motor1_collision">
            <origin xyz="0.08224999999999996 0.0 5.062616992290714e-16" rpy="2.01526633129011e-15 0.463207708438608 1.5707963267948977" />
            <geometry>
                <mesh filename="meshes/RL-Double-Motor1.stl" />
            </geometry>
        </collision> -->
    </link>
    <link name="RL-leg-link11">
        <inertial>
            <origin xyz="-0.018187575134684993 -0.0278010245702095 -0.04197126709316429" rpy="0.0 -0.0 0.0" />
            <mass value="0.2812248770831842" />
            <inertia ixx="0.0005532624812261897" iyy="0.000503702724717614" izz="0.00022924446679721365" ixy="-9.72971211322419e-05" iyz="-0.00023454139194335752" ixz="-0.00016559353942991427" />
        </inertial>
        <visual name="RL-leg-link11_visual">
            <origin xyz="2.486899575160351e-16 -0.008946235112596668 0.004468202786253741" rpy="2.17124332610022 -0.9985218448045559 0.8872287946654374" />
            <geometry>
                <mesh filename="meshes/RL-leg-link11.stl" />
            </geometry>
        </visual>
        <collision name="RL-leg-link11_collision">
            <origin xyz="2.486899575160351e-16 -0.008946235112596668 0.004468202786253741" rpy="2.17124332610022 -0.9985218448045559 0.8872287946654374" />
            <geometry>
                <mesh filename="meshes/RL-leg-link11.stl" />
            </geometry>
        </collision>
    </link>
    <!-- <link name="RL-leg-link31">
        <inertial>
            <origin xyz="-0.009870261189729525 0.05923453093001441 -0.03688710288419682" rpy="0.0 -0.0 0.0" />
            <mass value="0.24917982527134377" />
            <inertia ixx="0.00040978421406971666" iyy="0.0001548212244949916" izz="0.00039266687719654767" ixy="0.00011915598009649316" iyz="0.00015523091457711867" ixz="-5.4409621433531865e-05" />
        </inertial>
        <visual name="RL-leg-link31_visual">
            <origin xyz="0.0012817170732537875 0.0011521926129546502 0.001014721809617587" rpy="2.320489800622202 -0.8048584932280782 2.9617957951061364" />
            <geometry>
                <mesh filename="meshes/RL-leg-link31.stl" />
            </geometry>
        </visual>
         <collision name="RL-leg-link31_collision">
            <origin xyz="0.0012817170732537875 0.0011521926129546502 0.001014721809617587" rpy="2.320489800622202 -0.8048584932280782 2.9617957951061364" />
            <geometry>
                <mesh filename="meshes/RL-leg-link31.stl" />
            </geometry>
        </collision> 
    </link>
    <link name="RL-leg-link41">
        <inertial>
            <origin xyz="0.02415809680666765 -0.020866977631660184 -0.04718424430272244" rpy="0.0 -0.0 0.0" />
            <mass value="0.30627894117127225" />
            <inertia ixx="0.0005633661876117899" iyy="0.000630259047136407" izz="0.00019875659227917494" ixy="8.294874178688648e-05" iyz="-0.0001704775157100047" ixz="0.00023843202023224666" />
        </inertial>
        <visual name="RL-leg-link41_visual">
            <origin xyz="2.1316282072803005e-16 0.008230534887403315 -0.004110747213746322" rpy="-0.8685317926765391 0.9455253589537899 -0.764059848904591" />
            <geometry>
                <mesh filename="meshes/RL-leg-link41.stl" />
            </geometry>
        </visual>
         <collision name="RL-leg-link41_collision">
            <origin xyz="2.1316282072803005e-16 0.008230534887403315 -0.004110747213746322" rpy="-0.8685317926765391 0.9455253589537899 -0.764059848904591" />
            <geometry>
                <mesh filename="meshes/RL-leg-link41.stl" />
            </geometry>
        </collision> 
    </link> -->
    <link name="RL-leg-link21">
        <inertial>
            <origin xyz="0.029139284884755003 0.060302052863784684 -0.03191261917070122" rpy="0.0 -0.0 0.0" />
            <mass value="0.2812427717615869" />
            <inertia ixx="0.000553247207101662" iyy="0.00025196301394682776" izz="0.0005430645001651321" ixy="-0.00021582418743294136" iyz="0.0002286675423824151" ixz="0.00011766192609661392" />
        </inertial>
        <visual name="RL-leg-link21_visual">
            <origin xyz="-0.0013289292056403214 0.0011882835980298269 0.0009066050031298012" rpy="0.7994953932588053 -0.8863852112506413 0.16833296756001442" />
            <geometry>
                <mesh filename="meshes/RL-leg-link21.stl" />
            </geometry>
        </visual>
        <collision name="RL-leg-link21_collision">
            <origin xyz="-0.0013289292056403214 0.0011882835980298269 0.0009066050031298012" rpy="0.7994953932588053 -0.8863852112506413 0.16833296756001442" />
            <geometry>
                <mesh filename="meshes/RL-leg-link21.stl" />
            </geometry>
        </collision>
    </link>
    <link name="FR-Single-Motor1">
        <inertial>
            <origin xyz="-0.00805851174354837 -0.0242910327537348 0.01674999999782962" rpy="0.0 -0.0 0.0" />
            <mass value="0.7011939191100404" />
            <inertia ixx="0.0002624831375910991" iyy="0.00019998987600196305" izz="0.0003354208086328225" ixy="-6.052823711328627e-07" iyz="1.652671055563104e-14" ixz="-4.018313459752676e-14" />
        </inertial>
        <visual name="FR-Single-Motor1_visual">
            <origin xyz="-0.04174999999999992 -0.03924999999999997 0.016749999999999973" rpy="1.5707963267948966 1.5707963267948966 0" />
            <geometry>
                <mesh filename="meshes/FR-Single-Motor1.stl" />
            </geometry>
        </visual>
        <!-- <collision name="FR-Single-Motor1_collision">
            <origin xyz="-0.04174999999999992 -0.03924999999999997 0.016749999999999973" rpy="1.5707963267948966 1.5707963267948966 0" />
            <geometry>
                <mesh filename="meshes/FR-Single-Motor1.stl" />
            </geometry>
        </collision> -->
    </link>
    <link name="FR-Double-Motor1">
        <inertial>
            <origin xyz="-0.06716414766997802 0.005472887473802999 -0.009423955249709097" rpy="0.0 -0.0 0.0" />
            <mass value="2.4365544485369104" />
            <inertia ixx="0.0015776729226482655" iyy="0.004135448799639604" izz="0.0036850208986659583" ixy="-2.8396286085030638e-06" iyz="0.00039366741088266144" ixz="2.722490340806282e-06" />
        </inertial>
        <visual name="FR-Double-Motor1_visual">
            <origin xyz="-0.08224999999999989 -1.4210854715202004e-16 1.7763568394002506e-16" rpy="-3.141592653589793 -0.5235987755982989 1.570796326794897" />
            <geometry>
                <mesh filename="meshes/FR-Double-Motor1.stl" />
            </geometry>
        </visual>
        <!-- <collision name="FR-Double-Motor1_collision">
            <origin xyz="-0.08224999999999989 -1.4210854715202004e-16 1.7763568394002506e-16" rpy="-3.141592653589793 -0.5235987755982989 1.570796326794897" />
            <geometry>
                <mesh filename="meshes/FR-Double-Motor1.stl" />
            </geometry>
        </collision> -->
    </link>
    <link name="FR-leg-link11">
        <inertial>
            <origin xyz="-0.0392504534288604 0.02323732059089055 -0.02801251639064752" rpy="0.0 -0.0 0.0" />
            <mass value="0.28122487708301536" />
            <inertia ixx="0.00029818879728155806" iyy="0.0005465103669082677" izz="0.00044151050855044047" ixy="0.00017097341899937476" iyz="0.0001341259240028592" ixz="-0.00024413013609389522" />
        </inertial>
        <visual name="FR-leg-link11_visual">
            <origin xyz="-7.105427357601002e-17 0.008660249395506928 0.004999999999999787" rpy="0.6637961054570317 -0.6240105391945766 -0.42869167538801345" />
            <geometry>
                <mesh filename="meshes/FR-leg-link11.stl" />
            </geometry>
        </visual>
        <collision name="FR-leg-link11_collision">
            <origin xyz="-7.105427357601002e-17 0.008660249395506928 0.004999999999999787" rpy="0.6637961054570317 -0.6240105391945766 -0.42869167538801345" />
            <geometry>
                <mesh filename="meshes/FR-leg-link11.stl" />
            </geometry>
        </collision>
    </link>
    <link name="FR-leg-link21">
        <inertial>
            <origin xyz="0.0029824732745502304 0.06030582122666932 0.04310642215126426" rpy="0.0 -0.0 0.0" />
            <mass value="0.2812427717616486" />
            <inertia ixx="0.0006630451916206821" iyy="0.000249810563271771" izz="0.0004354189663220967" ixy="-3.04226894329931e-05" iyz="-0.0003125349804577101" ixz="-2.326116161548564e-05" />
        </inertial>
        <visual name="FR-leg-link21_visual">
            <origin xyz="-0.0009541540325433574 0.0010958606223879742 -0.0013743016819035957" rpy="-0.8539855599227406 0.42399626641840427 0.2753025393609303" />
            <geometry>
                <mesh filename="meshes/FR-leg-link21.stl" />
            </geometry>
        </visual>
        <collision name="FR-leg-link21_collision">
            <origin xyz="-0.0009541540325433574 0.0010958606223879742 -0.0013743016819035957" rpy="-0.8539855599227406 0.42399626641840427 0.2753025393609303" />
            <geometry>
                <mesh filename="meshes/FR-leg-link21.stl" />
            </geometry>
        </collision>
    </link>
    <!-- <link name="FR-leg-link31">
        <inertial>
            <origin xyz="-0.03362474629608322 0.05413827562982711 0.030087095432696158" rpy="0.0 -0.0 0.0" />
            <mass value="0.24917982527179094" />
            <inertia ixx="0.0003077249358880116" iyy="0.00021449923517371632" izz="0.0004350481447042427" ixy="0.00019691164716753427" iyz="-8.52863269350496e-05" ixz="5.7109621810001504e-05" />
        </inertial>
        <visual name="FR-leg-link31_visual">
            <origin xyz="0.001412790401899251 0.0013824369479977605 -0.0003047696924419974" rpy="-2.6513921813390615 1.2411943749583882 2.812912790352554" />
            <geometry>
                <mesh filename="meshes/FR-leg-link31.stl" />
            </geometry>
        </visual>
         <collision name="FR-leg-link31_collision">
            <origin xyz="0.001412790401899251 0.0013824369479977605 -0.0003047696924419974" rpy="-2.6513921813390615 1.2411943749583882 2.812912790352554" />
            <geometry>
                <mesh filename="meshes/FR-leg-link31.stl" />
            </geometry>
        </collision> 
    </link>
    <link name="FR-leg-link41">
        <inertial>
            <origin xyz="-0.0024380763075627955 0.026341203667214295 -0.05045383314626662" rpy="0.0 -0.0 0.0" />
            <mass value="0.30627948094211754" />
            <inertia ixx="0.0006799630374169086" iyy="0.0005850633123570537" izz="0.00012735481461243273" ixy="1.0258067461963921e-05" iyz="0.00024221667678551995" ixz="-2.5324243666417054e-05" />
        </inertial>
        <visual name="FR-leg-link41_visual">
            <origin xyz="-6.392042450897862e-13 -0.007967430607364606 -0.004600000001657989" rpy="-1.4932782866955108 1.0454576602664718 1.6603364301662176" />
            <geometry>
                <mesh filename="meshes/FR-leg-link41.stl" />
            </geometry>
        </visual>
         <collision name="FR-leg-link41_collision">
            <origin xyz="-6.392042450897862e-13 -0.007967430607364606 -0.004600000001657989" rpy="-1.4932782866955108 1.0454576602664718 1.6603364301662176" />
            <geometry>
                <mesh filename="meshes/FR-leg-link41.stl" />
            </geometry>
        </collision> 
    </link> -->
    <link name="RR-Single-Motor1">
        <inertial>
            <origin xyz="0.008058511743548342 -0.024291032753734853 0.01675000000217061" rpy="0.0 -0.0 0.0" />
            <mass value="0.7011939191100404" />
            <inertia ixx="0.0002624831375911546" iyy="0.00019998987600203244" izz="0.0003354208086328251" ixy="6.052823711315616e-07" iyz="-1.652671055563104e-14" ixz="-4.016578736276699e-14" />
        </inertial>
        <visual name="RR-Single-Motor1_visual">
            <origin xyz="0.041749999999999884 -0.039250000000000014 0.016750000000000115" rpy="1.5707963267948968 -1.5707963267948966 0" />
            <geometry>
                <mesh filename="meshes/RR-Single-Motor1.stl" />
            </geometry>
        </visual>
        <!-- <collision name="RR-Single-Motor1_collision">
            <origin xyz="0.041749999999999884 -0.039250000000000014 0.016750000000000115" rpy="1.5707963267948968 -1.5707963267948966 0" />
            <geometry>
                <mesh filename="meshes/RR-Single-Motor1.stl" />
            </geometry>
        </collision> -->
    </link>
    <link name="RR-Double-Motor1">
        <inertial>
            <origin xyz="0.06716414766997787 0.005424940913473932 -0.009451637209221887" rpy="0.0 -0.0 0.0" />
            <mass value="2.4365544485369104" />
            <inertia ixx="0.001577672922648043" iyy="0.004138553852375534" izz="0.0036819158459299164" ixy="9.379314924173875e-07" iyz="0.0003918747078497236" ixz="-3.820435682679034e-06" />
        </inertial>
        <visual name="RR-Double-Motor1_visual">
            <origin xyz="0.08224999999999977 -2.842170943040401e-16 5.329070518200751e-17" rpy="-3.141592653589793 0.5235987755982987 -1.570796326794897" />
            <geometry>
                <mesh filename="meshes/RR-Double-Motor1.stl" />
            </geometry>
        </visual>
        <!-- <collision name="RR-Double-Motor1_collision">
            <origin xyz="0.08224999999999977 -2.842170943040401e-16 5.329070518200751e-17" rpy="-3.141592653589793 0.5235987755982987 -1.570796326794897" />
            <geometry>
                <mesh filename="meshes/RR-Double-Motor1.stl" />
            </geometry>
        </collision> -->
    </link>
    <link name="RR-leg-link11">
        <inertial>
            <origin xyz="-0.02049529540828065 0.0298328178022809 -0.039436252661954045" rpy="0.0 -0.0 0.0" />
            <mass value="0.28122487708301536" />
            <inertia ixx="0.0005344411734715534" iyy="0.00047970456321442384" izz="0.00027206393605428065" ixy="0.00011856870817845982" iyz="0.0002408964592439216" ixz="-0.0001763833273962981" />
        </inertial>
        <visual name="RR-leg-link11_visual">
            <origin xyz="-3.1974423109204507e-16 0.008660249395507247 0.0049999999999996445" rpy="0.9821746740840134 -0.9258276201676335 -0.8748561591377285" />
            <geometry>
                <mesh filename="meshes/RR-leg-link11.stl" />
            </geometry>
        </visual>
        <collision name="RR-leg-link11_collision">
            <origin xyz="-3.1974423109204507e-16 0.008660249395507247 0.0049999999999996445" rpy="0.9821746740840134 -0.9258276201676335 -0.8748561591377285" />
            <geometry>
                <mesh filename="meshes/RR-leg-link11.stl" />
            </geometry>
        </collision>
    </link>
    <link name="RR-leg-link21">
        <inertial>
            <origin xyz="0.026808419669417525 0.05860346298938396 0.0367531518286212" rpy="0.0 -0.0 0.0" />
            <mass value="0.2812427717616486" />
            <inertia ixx="0.0005696082764745855" iyy="0.00027572600879786024" izz="0.0005029404359420936" ixy="-0.00019366529327096194" iyz="-0.0002551299391259355" ixz="-0.0001250816239023662" />
        </inertial>
        <visual name="RR-leg-link21_visual">
            <origin xyz="-0.0013049509610227794 0.0012249511105342492 -0.0008925123095268539" rpy="-0.7228732455792783 0.8304127646811991 0.2397761024208059" />
            <geometry>
                <mesh filename="meshes/RR-leg-link21.stl" />
            </geometry>
        </visual>
        <collision name="RR-leg-link21_collision">
            <origin xyz="-0.0013049509610227794 0.0012249511105342492 -0.0008925123095268539" rpy="-0.7228732455792783 0.8304127646811991 0.2397761024208059" />
            <geometry>
                <mesh filename="meshes/RR-leg-link21.stl" />
            </geometry>
        </collision>
    </link>
    <!-- <link name="RR-leg-link31">
        <inertial>
            <origin xyz="-0.012362829956947223 0.05676616941385852 0.039894526685076065" rpy="0.0 -0.0 0.0" />
            <mass value="0.24917982527179094" />
            <inertia ixx="0.00040117977297781174" iyy="0.00017730460699922848" izz="0.0003787879357889241" ixy="0.00012586757924598098" iyz="-0.00016222988676884643" ixz="6.482889493774683e-05" />
        </inertial>
        <visual name="RR-leg-link31_visual">
            <origin xyz="0.0013081595516952049 0.0012269555689081813 -0.0008850359659596663" rpy="-2.420738693439757 0.8359679143132223 2.9018544437780833" />
            <geometry>
                <mesh filename="meshes/RR-leg-link31.stl" />
            </geometry>
        </visual>
         <collision name="RR-leg-link31_collision">
            <origin xyz="0.0013081595516952049 0.0012269555689081813 -0.0008850359659596663" rpy="-2.420738693439757 0.8359679143132223 2.9018544437780833" />
            <geometry>
                <mesh filename="meshes/RR-leg-link31.stl" />
            </geometry>
        </collision> 
    </link>
    <link name="RR-leg-link41">
        <inertial>
            <origin xyz="0.02173134003684602 0.024211367327731034 -0.04676484839008325" rpy="0.0 -0.0 0.0" />
            <mass value="0.30627948094211754" />
            <inertia ixx="0.0005857639805119804" iyy="0.0006037849431802939" izz="0.00020283224069415917" ixy="-8.985418831293156e-05" iyz="0.00020421481275573894" ixz="0.00021369071333026201" />
        </inertial>
        <visual name="RR-leg-link41_visual">
            <origin xyz="-4.405364961712621e-15 -0.007967430604493 -0.004600000000000293" rpy="-2.1528358059330697 0.9290985520356033 0.883082812773521" />
            <geometry>
                <mesh filename="meshes/RR-leg-link41.stl" />
            </geometry>
        </visual>
         <collision name="RR-leg-link41_collision">
            <origin xyz="-4.405364961712621e-15 -0.007967430604493 -0.004600000000000293" rpy="-2.1528358059330697 0.9290985520356033 0.883082812773521" />
            <geometry>
                <mesh filename="meshes/RR-leg-link41.stl" />
            </geometry>
        </collision> 
    </link> -->
    <joint name="Basic_Body_FL-Rigid" type="fixed">
        <origin xyz="-0.044000000000000004 -0.032 0.012000000000000028" rpy="3.141592653589793 -0.0 0.0" />
        <parent link="Basic_Body" />
        <child link="FL-Single-Motor1" />
    </joint>
    <joint name="FL-Single-Motor1_FL-Revolute_joint" type="continuous">
        <origin xyz="-0.034499999999999996 0.03925 0.016750000000000043" rpy="-1.5707963267948966 -0.0 0.0" />
        <parent link="FL-Single-Motor1" />
        <child link="FL-Double-Motor1" />
        <axis xyz="-1.0 0.0 7.806255641895643e-18" />
        <limit effort="12" lower="-1.570795" upper="1.570795" velocity="50"/>
        <dynamics damping="0" friction="0"/>
        
    </joint>
    <joint name="FL-Double-Motor1_FL-Motor-Link1_joint" type="continuous">
        <origin xyz="-0.08225 0.031400000000000004 0.054386399999999994" rpy="-1.5707963267948968 1.0785207688568522e-32 5.551115123125783e-17" />
        <parent link="FL-Double-Motor1" />
        <child link="FL-leg-link11" />
        <axis xyz="2.775557561562891e-17 -0.8660250000000002 0.4999999999999999" />
        <limit effort="12" lower="-1.570795" upper="1.570795" velocity="50"/>
        <dynamics damping="0" friction="0"/>
    </joint>
    <joint name="FL-leg-link11_FL-Link1-Link2_joint" type="continuous">
        <origin xyz="-0.08532916 -0.06154961999999999 -0.08377865" rpy="-0.7853981633974452 -0.0 -3.851859888774472e-33" />
        <parent link="FL-leg-link11" />
        <child link="FL-leg-link21" />
        <axis xyz="0.540447 -0.5649967029443643 -0.6234546347586148" />
        <limit effort="12" lower="-1.570795" upper="1.570795" velocity="50"/>
        <dynamics damping="0" friction="0"/>
    </joint>
    <!-- <joint name="FL-Double-Motor1_FL-Motor-Link4" type="continuous">
        <origin xyz="-0.08225 0.041000000000000016 0.07101408" rpy="-1.5707963267948968 1.0785207688568522e-32 5.551115123125783e-17" />
        <parent link="FL-Double-Motor1" />
        <child link="FL-leg-link41" />
        <axis xyz="2.775557561562891e-17 -0.866025 0.5" />
    </joint>
    <joint name="FL-leg-link41_FL-Link4-Link3" type="continuous">
        <origin xyz="0.009909659999999968 -0.06007759 -0.11962901" rpy="-0.7853981633974534 5.551115123125783e-17 -3.851859888774471e-33" />
        <parent link="FL-leg-link41" />
        <child link="FL-leg-link31" />
        <axis xyz="0.7045800000000001 0.6675540562740957 0.2407062193837161" />
    </joint>
    <joint name="FL-leg-link21_FL-Link2-Link3" type="continuous">
        <origin xyz="0.019425109999999995 0.10661083588181829 -0.07883614820728686" rpy="-2.1862760354652835 -0.523598775598294 2.5261129449194097" />
        <parent link="FL-leg-link21" />
        <child link="FL-leg-link31" />
        <axis xyz="-0.5376733898125287 0.17866800000000002 0.8240049671455295" />
    </joint> -->
    <joint name="Basic_Body_RL-Rigid" type="fixed">
        <origin xyz="0.044000000000000004 -0.032 0.012000000000000028" rpy="3.141592653589793 -0.0 0.0" />
        <parent link="Basic_Body" />
        <child link="RL-Single-Motor1" />
    </joint>
    <joint name="RL-Single-Motor1_RL-Revolute_joint" type="continuous">
        <origin xyz="0.034499999999999996 0.03925 0.016750000000000043" rpy="-1.5707963267948966 6.077163357286271e-64 0.0" />
        <parent link="RL-Single-Motor1" />
        <child link="RL-Double-Motor1" />
        <axis xyz="1.0 4.930380657631324e-32 -7.806255641895643e-18" />
        <limit effort="12" lower="-1.570795" upper="1.570795" velocity="50"/>
        <dynamics damping="0" friction="0"/>
    </joint>
    <joint name="RL-Double-Motor1_RL-Motor-Link1_joint" type="continuous">
        <origin xyz="0.08225 0.0280603 0.05618238" rpy="-1.5707963267948968 1.4791141972893971e-31 -1.8474149676157256e-47" />
        <parent link="RL-Double-Motor1" />
        <child link="RL-leg-link11" />
        <axis xyz="-1.3232510596358296e-31 -0.894624 0.4468199999999999" />
        <limit effort="12" lower="-1.570795" upper="1.570795" velocity="50"/>
        <dynamics damping="0" friction="0"/>
    </joint>
    <joint name="RL-leg-link11_RL-Link1-Link2_joint" type="continuous">
        <origin xyz="-0.04450177 -0.06669059999999999 -0.10798259000000002" rpy="-0.7853981633974452 5.551115123125783e-17 -1.4111326436170527e-31" />
        <parent link="RL-leg-link11" />
        <child link="RL-leg-link21" />
        <axis xyz="0.664463 -0.594142937358092 -0.4533028228949145" />
        <limit effort="12" lower="-1.570795" upper="1.570795" velocity="50"/>
        <dynamics damping="0" friction="0"/>
    </joint>
    <!-- <joint name="RL-Double-Motor1_RL-Motor-Link4" type="continuous">
        <origin xyz="0.08225 0.03663924999999999 0.07335915" rpy="-1.5707963267948968 1.4791141972893971e-31 -1.8474149676157256e-47" />
        <parent link="RL-Double-Motor1" />
        <child link="RL-leg-link41" />
        <axis xyz="-1.3232510596358296e-31 -0.894624 0.44682" />
    </joint>
    <joint name="RL-leg-link41_RL-Link4-Link3" type="continuous">
        <origin xyz="0.055349129999999996 -0.047565880000000005 -0.11266135" rpy="-0.7853981633974534 -5.551115123125783e-17 -1.4791141972893971e-31" />
        <parent link="RL-leg-link41" />
        <child link="RL-leg-link31" />
        <axis xyz="0.640856 0.5760968651954262 0.5073618434234122" />
    </joint>
    <joint name="RL-leg-link21_RL-Link2-Link3" type="continuous">
        <origin xyz="0.053980549999999995 0.10704380443500675 -0.05988378435424599" rpy="0.9553166181245095 -0.523598775598294 2.5261129449194093" />
        <parent link="RL-leg-link21" />
        <child link="RL-leg-link31" />
        <axis xyz="0.7022977479676944 0.2640149999999999 0.6611158490313971" />
    </joint> -->
    <joint name="Basic_Body_FR-Rigid" type="fixed">
        <origin xyz="-0.044000000000000004 0.029500000000000002 0.012000000000000028" rpy="3.141592653589793 -0.0 0.0" />
        <parent link="Basic_Body" />
        <child link="FR-Single-Motor1" />
    </joint>
    <joint name="FR-Single-Motor1_FR-Revolute_joint" type="continuous">
        <origin xyz="-0.034499999999999996 -0.03925 0.016750000000000043" rpy="-1.5707963267948966 -0.0 0.0" />
        <parent link="FR-Single-Motor1" />
        <child link="FR-Double-Motor1" />
        <axis xyz="-1.0 -2.465190328815662e-32 7.806255641895643e-18" />
        <limit effort="12" lower="-1.570795" upper="1.570795" velocity="50"/>
        <dynamics damping="0" friction="0"/>
    </joint>
    <joint name="FR-Double-Motor1_FR-Motor-Link1_joint" type="continuous">
        <origin xyz="-0.08225 0.031400000000000004 -0.054386399999999994" rpy="-1.5707963267948968 -6.93334779979405e-33 -5.551115123125783e-17" />
        <parent link="FR-Double-Motor1" />
        <child link="FR-leg-link11" />
        <axis xyz="-2.7755575615628914e-17 0.8660249999999999 0.5000000000000001" />
        <limit effort="12" lower="-1.570795" upper="1.570795" velocity="50"/>
        <dynamics damping="0" friction="0"/>
    </joint>
    <joint name="FR-leg-link11_FR-Link1-Link2_joint" type="continuous">
        <origin xyz="-0.09795199 0.05561083000000002 -0.07349235999999998" rpy="-2.356194490192348 -1.1102230246251565e-16 -5.551115123125785e-17" />
        <parent link="FR-leg-link11" />
        <child link="FR-leg-link21" />
        <axis xyz="0.47707499999999997 -0.5479299736736459 0.6871479851807744" />
        <limit effort="12" lower="-1.570795" upper="1.570795" velocity="50"/>
        <dynamics damping="0" friction="0"/>
    </joint>
    <!-- <joint name="FR-Double-Motor1_FR-Motor-Link4" type="continuous">
        <origin xyz="-0.08225 0.041000000000000016 -0.07101408" rpy="-1.5707963267948968 -6.93334779979405e-33 -5.551115123125783e-17" />
        <parent link="FR-Double-Motor1" />
        <child link="FR-leg-link41" />
        <axis xyz="-2.7755575615628914e-17 0.866025 0.5" />
    </joint>
    <joint name="FR-leg-link41_FR-Link4-Link3" type="continuous">
        <origin xyz="-0.007422009999999979 0.060158200000000016 -0.11976863000000001" rpy="-2.35619449019234 -5.551115123125783e-17 1.1102230246251568e-16" />
        <parent link="FR-leg-link41" />
        <child link="FR-leg-link31" />
        <axis xyz="0.7063949999999998 0.6912195060268473 -0.15238292555926752" />
    </joint>
    <joint name="FR-leg-link21_FR-Link2-Link3" type="continuous">
        <origin xyz="0.0058727100000000474 0.10703515651907282 0.08041971384375421" rpy="2.1862760354652835 -0.5235987755982939 -2.5261129449194093" />
        <parent link="FR-leg-link21" />
        <child link="FR-leg-link31" />
        <axis xyz="0.8697469977137005 0.15142800000000003 -0.4696914367624818" />
    </joint> -->
    <joint name="Basic_Body_RR-Rigid" type="fixed">
        <origin xyz="0.044000000000000004 0.029500000000000002 0.012000000000000028" rpy="3.141592653589793 -0.0 0.0" />
        <parent link="Basic_Body" />
        <child link="RR-Single-Motor1" />
    </joint>
    <joint name="RR-Single-Motor1_RR-Revolute_joint" type="continuous">
        <origin xyz="0.034499999999999996 -0.03925 0.016750000000000043" rpy="-1.5707963267948966 -0.0 0.0" />
        <parent link="RR-Single-Motor1" />
        <child link="RR-Double-Motor1" />
        <axis xyz="0.9999999999999999 -3.851859888774472e-34 0.0" />
        <limit effort="12" lower="-1.570795" upper="1.570795" velocity="50"/>
        <dynamics damping="0" friction="0"/>
        
    </joint>
    <joint name="RR-Double-Motor1_RR-Motor-Link1_joint" type="continuous">
        <origin xyz="0.08224999999999998 0.031400000000000004 -0.05438639999999999" rpy="-1.5707963267948968 -4.9303806576313227e-32 6.07716335728627e-64" />
        <parent link="RR-Double-Motor1" />
        <child link="RR-leg-link11" />
        <axis xyz="-4.2698329090251674e-32 0.8660249999999999 0.5000000000000002" />
        <limit effort="12" lower="-1.570795" upper="1.570795" velocity="50"/>
        <dynamics damping="0" friction="0"/>
    </joint>
    <joint name="RR-leg-link11_RR-Link1-Link2_joint" type="continuous">
        <origin xyz="-0.05034087999999999 0.07198128000000002 -0.10184681999999995" rpy="-2.356194490192348 -5.551115123125783e-17 4.250565120907878e-32" />
        <parent link="RR-leg-link11" />
        <child link="RR-leg-link21" />
        <axis xyz="0.652478 -0.6124768019806968 0.44625721092717185" />
        <limit effort="12" lower="-1.570795" upper="1.570795" velocity="50"/>
        <dynamics damping="0" friction="0"/>
    </joint>
    <!-- <joint name="RR-Double-Motor1_Revolute_45" type="continuous">
        <origin xyz="0.08224999999999998 0.041000000000000016 -0.07101407999999998" rpy="-1.5707963267948966 -4.9303806576313227e-32 6.07716335728627e-64" />
        <parent link="RR-Double-Motor1" />
        <child link="RR-leg-link41" />
        <axis xyz="-4.2698329090251674e-32 0.866025 0.5000000000000001" />
    </joint>
    <joint name="RR-leg-link41_Revolute_46" type="continuous">
        <origin xyz="0.04960471999999999 0.05550153000000002 -0.11170303999999995" rpy="-2.35619449019234 5.551115123125783e-17 4.930380657631324e-32" />
        <parent link="RR-leg-link41" />
        <child link="RR-leg-link31" />
        <axis xyz="0.65408 0.6134773580760723 -0.4425215658021684" />
    </joint>
    <joint name="RR-leg-link21_Revolute_47" type="continuous">
        <origin xyz="0.049697599999999974 0.10385966724398457 0.0685686607596101" rpy="2.1862760354652835 -0.5235987755982938 -2.5261129449194093" />
        <parent link="RR-leg-link21" />
        <child link="RR-leg-link31" />
        <axis xyz="0.693352140078903 0.20589499999999997 -0.6905576540796612" />
    </joint> -->
</robot>