<?xml version='1.0' encoding='utf-8'?>
<robot name="Quadruped-IsaacSim-with_foot">
    <link name="Body1">
        <inertial>
            <origin xyz="3.269975336552785e-11 -0.0012499987421279188 -0.004750000038203694" rpy="0.0 0.0 0.0" />
            <mass value="3.578209936079509" />
            <inertia ixx="0.005306000538019551" iyy="0.07835805606453539" izz="0.08260422228557268" ixy="-7.922195039377751e-10" iyz="2.646563090208387e-12" ixz="2.0546265609645002e-11" />
        </inertial>
        <visual name="Body1_visual">
            <origin xyz="0.0 0.0 0.0" rpy="0.0 0.0 0.0" />
            <geometry>
                <mesh filename="meshes/Body1.stl" />
            </geometry>
        </visual>
        <collision name="Body1_collision">
            <origin xyz="0.0 0.0 0.0" rpy="0.0 0.0 0.0" />
            <geometry>
                <mesh filename="meshes/Body1.stl" />
            </geometry>
        </collision>
    </link>
    <link name="FR-Single-Motor1">
        <inertial>
            <origin xyz="-0.00805851174354837 -0.024291032753734693 0.01674999999782962" rpy="0.0 -0.0 0.0" />
            <mass value="0.7011939191100404" />
            <inertia ixx="0.0002624831375910436" iyy="0.00019998987600192142" izz="0.0003354208086328277" ixy="-6.052823711328627e-07" iyz="1.652671055563104e-14" ixz="-4.0179665150574806e-14" />
        </inertial>
        <visual name="FR-Single-Motor1_visual">
            <origin xyz="-0.04174999999999985 -0.03924999999999984 0.016749999999999973" rpy="1.5707963267948966 1.5707963267948966 0" />
            <geometry>
                <mesh filename="meshes/FR-Single-Motor1.stl" />
            </geometry>
        </visual>
        <collision name="FR-Single-Motor1_collision">
            <origin xyz="-0.04174999999999985 -0.03924999999999984 0.016749999999999973" rpy="1.5707963267948966 1.5707963267948966 0" />
            <geometry>
                <mesh filename="meshes/FR-Single-Motor1.stl" />
            </geometry>
        </collision>
    </link>
    <link name="FR-Double-Motor1">
        <inertial>
            <origin xyz="-0.06716414766997802 0.005472887473803354 -0.009423955249709097" rpy="0.0 -0.0 0.0" />
            <mass value="2.4365544485369104" />
            <inertia ixx="0.0015776729226479325" iyy="0.004135448799639618" izz="0.0036850208986657917" ixy="-2.839628608558575e-06" iyz="0.0003936674108826198" ixz="2.722490340806282e-06" />
        </inertial>
        <visual name="FR-Double-Motor1_visual">
            <origin xyz="-0.08224999999999989 7.105427357601002e-17 1.7763568394002506e-16" rpy="3.141592653589793 -0.5235987755982986 1.5707963267948966" />
            <geometry>
                <mesh filename="meshes/FR-Double-Motor1.stl" />
            </geometry>
        </visual>
        <collision name="FR-Double-Motor1_collision">
            <origin xyz="-0.08224999999999989 7.105427357601002e-17 1.7763568394002506e-16" rpy="3.141592653589793 -0.5235987755982986 1.5707963267948966" />
            <geometry>
                <mesh filename="meshes/FR-Double-Motor1.stl" />
            </geometry>
        </collision>
    </link>
    <link name="FR-leg-link11">
        <inertial>
            <origin xyz="-0.02247358678943286 0.02939583922569563 -0.03867938356548962" rpy="0.0 -0.0 0.0" />
            <mass value="0.28122487708301536" />
            <inertia ixx="0.0005165189299498052" iyy="0.0004847173138124368" izz="0.0002849734289780034" ixy="0.0001277965102248237" iyz="0.00023282864027589226" ixz="-0.00018990692557538724" />
        </inertial>
        <visual name="FR-leg-link11_visual">
            <origin xyz="1.4210854715202004e-16 0.00866024939550682 0.004999999999999929" rpy="0.9389175033845312 -0.9025114294229039 -0.8202511401795636" />
            <geometry>
                <mesh filename="meshes/FR-leg-link11.stl" />
            </geometry>
        </visual>
        <collision name="FR-leg-link11_collision">
            <origin xyz="1.4210854715202004e-16 0.00866024939550682 0.004999999999999929" rpy="0.9389175033845312 -0.9025114294229039 -0.8202511401795636" />
            <geometry>
                <mesh filename="meshes/FR-leg-link11.stl" />
            </geometry>
        </collision>
    </link>
    <link name="FR-leg-link21">
        <inertial>
            <origin xyz="0.024469073724158186 -0.05830924423033302 -0.03738848445530797" rpy="0.0 -0.0 0.0" />
            <mass value="0.2791876465674252" />
            <inertia ixx="0.0005654857993487895" iyy="0.00026381557065543304" izz="0.0004785788601074198" ixy="0.0001747353622693864" iyz="-0.0002556191175188255" ixz="0.00011557189657592125" />
        </inertial>
        <visual name="FR-leg-link21_visual">
            <origin xyz="-0.0012817170732535744 -0.0012113339358941033 0.0009433319697006581" rpy="-0.7364421345142296 -0.7922522618340606 -0.2404623104375031" />
            <geometry>
                <mesh filename="meshes/FR-leg-link21.stl" />
            </geometry>
        </visual>
        <collision name="FR-leg-link21_collision">
            <origin xyz="-0.0012817170732535744 -0.0012113339358941033 0.0009433319697006581" rpy="-0.7364421345142296 -0.7922522618340606 -0.2404623104375031" />
            <geometry>
                <mesh filename="meshes/FR-leg-link21.stl" />
            </geometry>
        </collision>
    </link>
    <link name="FR-leg-link31">
        <inertial>
            <origin xyz="-0.014516920226974506 0.056624665353771565 0.03936643680559522" rpy="0.0 -0.0 0.0" />
            <mass value="0.24917982527179094" />
            <inertia ixx="0.00039325097772332693" iyy="0.00018004533517305285" izz="0.00038397600286958387" ixy="0.00013442922393302749" iyz="-0.00015642054917907545" ixz="6.7130242425061e-05" />
        </inertial>
        <visual name="FR-leg-link31_visual">
            <origin xyz="0.0013289292056399482 0.0012408340291326426 -0.0008332303849810785" rpy="-2.4349603953257617 0.8741311024215337 2.9016489683958175" />
            <geometry>
                <mesh filename="meshes/FR-leg-link31.stl" />
            </geometry>
        </visual>
        <collision name="FR-leg-link31_collision">
            <origin xyz="0.0013289292056399482 0.0012408340291326426 -0.0008332303849810785" rpy="-2.4349603953257617 0.8741311024215337 2.9016489683958175" />
            <geometry>
                <mesh filename="meshes/FR-leg-link31.stl" />
            </geometry>
        </collision>
    </link>
    <link name="FR-leg-link41">
        <inertial>
            <origin xyz="0.019574344929142704 0.02463143176735578 -0.04749242134194574" rpy="0.0 -0.0 0.0" />
            <mass value="0.30627948094211754" />
            <inertia ixx="0.0006036922042004858" iyy="0.0006002739129147838" izz="0.00018841504727109756" ixy="-8.267758138273164e-05" iyz="0.0002114173394110186" ixz="0.000195396983562416" />
        </inertial>
        <visual name="FR-leg-link41_visual">
            <origin xyz="1.7763568394002506e-16 -0.007967430604493017 -0.0045999999999999375" rpy="-2.105606086054032 0.9506573206628401 0.9415634402058215" />
            <geometry>
                <mesh filename="meshes/FR-leg-link41.stl" />
            </geometry>
        </visual>
        <collision name="FR-leg-link41_collision">
            <origin xyz="1.7763568394002506e-16 -0.007967430604493017 -0.0045999999999999375" rpy="-2.105606086054032 0.9506573206628401 0.9415634402058215" />
            <geometry>
                <mesh filename="meshes/FR-leg-link41.stl" />
            </geometry>
        </collision>
    </link>
    <link name="FR-fingertip_frame1">
        <inertial>
            <origin xyz="0.0006605930276234951 0.00034164020410095477 0.0017212028979326987" rpy="0.0 -0.0 1.540743955509789e-33" />
            <mass value="0.0020551252007295867" />
            <inertia ixx="1.4223022853552224e-08" iyy="1.3566064604466317e-08" izz="1.941456977821998e-08" ixy="4.6380514042549347e-10" iyz="1.208460521030158e-09" ixz="2.336698681933407e-09" />
        </inertial>
        <visual name="FR-fingertip_frame1_visual">
            <origin xyz="1.0667202410274967e-09 4.730631957272635e-09 3.1877894457466026e-09" rpy="-3.0387364516592315 0.39537945362812915 0.739127615120215" />
            <geometry>
                <mesh filename="meshes/FR-fingertip_frame1.stl" />
            </geometry>
        </visual>
        <collision name="FR-fingertip_frame1_collision">
            <origin xyz="1.0667202410274967e-09 4.730631957272635e-09 3.1877894457466026e-09" rpy="-3.0387364516592315 0.39537945362812915 0.739127615120215" />
            <geometry>
                <mesh filename="meshes/FR-fingertip_frame1.stl" />
            </geometry>
        </collision>
    </link>
    <link name="FL-Single-Motor1">
        <inertial>
            <origin xyz="-0.008058511743548404 0.0242910327537348 0.01675000000217054" rpy="0.0 -0.0 0.0" />
            <mass value="0.7011939191100404" />
            <inertia ixx="0.000262483137591224" iyy="0.00019998987600210183" izz="0.00033542080863282423" ixy="6.052823711302606e-07" iyz="1.6545792513866786e-14" ixz="4.016231791581504e-14" />
        </inertial>
        <visual name="FL-Single-Motor1_visual">
            <origin xyz="-0.04174999999999992 0.03924999999999998 0.0167499999999999" rpy="-1.5707963267948968 -1.5707963267948966 0" />
            <geometry>
                <mesh filename="meshes/FL-Single-Motor1.stl" />
            </geometry>
        </visual>
        <collision name="FL-Single-Motor1_collision">
            <origin xyz="-0.04174999999999992 0.03924999999999998 0.0167499999999999" rpy="-1.5707963267948968 -1.5707963267948966 0" />
            <geometry>
                <mesh filename="meshes/FL-Single-Motor1.stl" />
            </geometry>
        </collision>
    </link>
    <link name="FL-Double-Motor1">
        <inertial>
            <origin xyz="-0.06716414766997798 0.0054249409134745005 0.009451637209221877" rpy="0.0 -0.0 0.0" />
            <mass value="2.4365544485369104" />
            <inertia ixx="0.001577672922648154" iyy="0.004138553852375507" izz="0.003681915845929861" ixy="-9.379314924451436e-07" iyz="-0.00039187470784970985" ixz="-3.820435682679046e-06" />
        </inertial>
        <visual name="FL-Double-Motor1_visual">
            <origin xyz="-0.08224999999999988 2.842170943040401e-16 -4.4408920985006264e-17" rpy="-7.601905174270248e-16 -0.5235987755982989 -1.5707963267948968" />
            <geometry>
                <mesh filename="meshes/FL-Double-Motor1.stl" />
            </geometry>
        </visual>
        <collision name="FL-Double-Motor1_collision">
            <origin xyz="-0.08224999999999988 2.842170943040401e-16 -4.4408920985006264e-17" rpy="-7.601905174270248e-16 -0.5235987755982989 -1.5707963267948968" />
            <geometry>
                <mesh filename="meshes/FL-Double-Motor1.stl" />
            </geometry>
        </collision>
    </link>
    <link name="FL-leg-link11">
        <inertial>
            <origin xyz="-0.0224735867894395 -0.02939583922570904 -0.038679383565513134" rpy="0.0 -0.0 0.0" />
            <mass value="0.2812248770831842" />
            <inertia ixx="0.000516518929950173" iyy="0.0004847173138127354" izz="0.0002849734289781142" ixy="-0.00012779651022487047" iyz="-0.00023282864027604833" ixz="-0.00018990692557547403" />
        </inertial>
        <visual name="FL-leg-link11_visual">
            <origin xyz="2.486899575160351e-16 -0.008660249395506928 0.0050000000000002135" rpy="2.2026751502052635 -0.9025114294229044 0.8202511401795622" />
            <geometry>
                <mesh filename="meshes/FL-leg-link11.stl" />
            </geometry>
        </visual>
        <collision name="FL-leg-link11_collision">
            <origin xyz="2.486899575160351e-16 -0.008660249395506928 0.0050000000000002135" rpy="2.2026751502052635 -0.9025114294229044 0.8202511401795622" />
            <geometry>
                <mesh filename="meshes/FL-leg-link11.stl" />
            </geometry>
        </collision>
    </link>
    <link name="FL-leg-link21">
        <inertial>
            <origin xyz="0.024469073724151115 0.05830924423031825 -0.03738848445529801" rpy="0.0 -0.0 0.0" />
            <mass value="0.27918764656736367" />
            <inertia ixx="0.0005654857993483801" iyy="0.0002638155706552648" izz="0.00047857886010709195" ixy="-0.00017473536226925634" iyz="0.0002556191175186399" ixz="0.00011557189657583297" />
        </inertial>
        <visual name="FL-leg-link21_visual">
            <origin xyz="-0.001281717073253752 0.0012113339358941744 0.0009433319697006937" rpy="0.7364421345142306 -0.7922522618340612 0.2404623104375082" />
            <geometry>
                <mesh filename="meshes/FL-leg-link21.stl" />
            </geometry>
        </visual>
        <collision name="FL-leg-link21_collision">
            <origin xyz="-0.001281717073253752 0.0012113339358941744 0.0009433319697006937" rpy="0.7364421345142306 -0.7922522618340612 0.2404623104375082" />
            <geometry>
                <mesh filename="meshes/FL-leg-link21.stl" />
            </geometry>
        </collision>
    </link>
    <link name="FL-leg-link31">
        <inertial>
            <origin xyz="-0.014516920226988752 0.05662466535378759 -0.039366436805639754" rpy="0.0 -0.0 0.0" />
            <mass value="0.24917982527134377" />
            <inertia ixx="0.00039325097772218917" iyy="0.00018004533517108483" izz="0.00038397600286802885" ixy="0.00013442922393376838" iyz="0.00015642054918024715" ixz="-6.713024242573117e-05" />
        </inertial>
        <visual name="FL-leg-link31_visual">
            <origin xyz="0.0013289292056399126 0.0012408340291327846 0.0008332303849814338" rpy="2.4349603953257644 -0.8741311024215314 2.901648968395818" />
            <geometry>
                <mesh filename="meshes/FL-leg-link31.stl" />
            </geometry>
        </visual>
        <collision name="FL-leg-link31_collision">
            <origin xyz="0.0013289292056399126 0.0012408340291327846 0.0008332303849814338" rpy="2.4349603953257644 -0.8741311024215314 2.901648968395818" />
            <geometry>
                <mesh filename="meshes/FL-leg-link31.stl" />
            </geometry>
        </collision>
    </link>
    <link name="FL-leg-link41">
        <inertial>
            <origin xyz="0.01957451566570944 -0.02463141467424272 -0.04749240784261659" rpy="0.0 -0.0 0.0" />
            <mass value="0.30627894117127225" />
            <inertia ixx="0.0006036919908114988" iyy="0.0006002743338964361" izz="0.00018841550231942124" ixy="8.267698249256415e-05" iyz="-0.0002114172422549715" ixz="0.00019539544119652474" />
        </inertial>
        <visual name="FL-leg-link41_visual">
            <origin xyz="2.1316282072803005e-16 0.007967430604493017 -0.0045999999999999375" rpy="-1.0359865675357622 0.9506573206628434 -0.9415634402058206" />
            <geometry>
                <mesh filename="meshes/FL-leg-link41.stl" />
            </geometry>
        </visual>
        <collision name="FL-leg-link41_collision">
            <origin xyz="2.1316282072803005e-16 0.007967430604493017 -0.0045999999999999375" rpy="-1.0359865675357622 0.9506573206628434 -0.9415634402058206" />
            <geometry>
                <mesh filename="meshes/FL-leg-link41.stl" />
            </geometry>
        </collision>
    </link>
    <link name="FL-fingertip_frame1">
        <inertial>
            <origin xyz="0.0006605918396481414 -0.00034163959023299385 0.0017211998034084887" rpy="0.0 -6.162975822039156e-33 1.540743955509789e-33" />
            <mass value="0.0020551252007295867" />
            <inertia ixx="1.4223020632631833e-08" iyy="1.3566067010947906e-08" izz="1.9414569592631674e-08" ixy="-4.638054482033856e-10" iyz="-1.2084599247528434e-09" ixz="2.3366994736517157e-09" />
        </inertial>
        <visual name="FL-fingertip_frame1_visual">
            <origin xyz="-1.2094970358589308e-10 -4.116401086662336e-09 9.32200805436878e-11" rpy="3.038736451659272 0.39537945362809046 -0.7391276151201677" />
            <geometry>
                <mesh filename="meshes/FL-fingertip_frame1.stl" />
            </geometry>
        </visual>
        <collision name="FL-fingertip_frame1_collision">
            <origin xyz="-1.2094970358589308e-10 -4.116401086662336e-09 9.32200805436878e-11" rpy="3.038736451659272 0.39537945362809046 -0.7391276151201677" />
            <geometry>
                <mesh filename="meshes/FL-fingertip_frame1.stl" />
            </geometry>
        </collision>
    </link>
    <link name="RR-Single-Motor1">
        <inertial>
            <origin xyz="-0.007941488256451539 0.02429103275373476 -0.016750000002170324" rpy="0.0 -0.0 0.0" />
            <mass value="0.7011939191100404" />
            <inertia ixx="0.0002624831375912101" iyy="0.0001999898760021157" izz="0.0003354208086328277" ixy="-6.05282371132429e-07" iyz="-1.6535354101302995e-14" ixz="4.015884860326277e-14" />
        </inertial>
        <visual name="RR-Single-Motor1_visual">
            <origin xyz="0.025749999999999974 0.039249999999999924 -0.016749999999999758" rpy="-1.5707963267948966 1.5707963267948966 0" />
            <geometry>
                <mesh filename="meshes/RR-Single-Motor1.stl" />
            </geometry>
        </visual>
        <collision name="RR-Single-Motor1_collision">
            <origin xyz="0.025749999999999974 0.039249999999999924 -0.016749999999999758" rpy="-1.5707963267948966 1.5707963267948966 0" />
            <geometry>
                <mesh filename="meshes/RR-Single-Motor1.stl" />
            </geometry>
        </collision>
    </link>
    <link name="RR-Double-Motor1">
        <inertial>
            <origin xyz="0.06716414766997816 0.0054249409134745005 -0.009451637209221753" rpy="0.0 -0.0 0.0" />
            <mass value="2.4365544485369104" />
            <inertia ixx="0.00157767292264821" iyy="0.004138553852375491" izz="0.003681915845930083" ixy="9.37931492417387e-07" iyz="0.00039187470784972345" ixz="-3.820435682685986e-06" />
        </inertial>
        <visual name="RR-Double-Motor1_visual">
            <origin xyz="0.08225000000000007 3.552713678800501e-16 1.865174681370263e-16" rpy="3.1415926535897927 0.5235987755982988 -1.5707963267948972" />
            <geometry>
                <mesh filename="meshes/RR-Double-Motor1.stl" />
            </geometry>
        </visual>
        <collision name="RR-Double-Motor1_collision">
            <origin xyz="0.08225000000000007 3.552713678800501e-16 1.865174681370263e-16" rpy="3.1415926535897927 0.5235987755982988 -1.5707963267948972" />
            <geometry>
                <mesh filename="meshes/RR-Double-Motor1.stl" />
            </geometry>
        </collision>
    </link>
    <link name="RR-leg-link11">
        <inertial>
            <origin xyz="-0.018187575134681548 0.030283491560377164 -0.040216842508614334" rpy="0.0 -0.0 0.0" />
            <mass value="0.28122487708301536" />
            <inertia ixx="0.0005532624812258013" iyy="0.0004744433867136245" izz="0.00025850380480082363" ixy="0.00010711404278451488" iyz="0.0002493672444621246" ixz="-0.00015941935867354323" />
        </inertial>
        <visual name="RR-leg-link11_visual">
            <origin xyz="1.7763568394002506e-16 0.00866024939550707 0.005000000000000356" rpy="1.0359865675357613 -0.9506573206628419 -0.9415634402058217" />
            <geometry>
                <mesh filename="meshes/RR-leg-link11.stl" />
            </geometry>
        </visual>
        <collision name="RR-leg-link11_collision">
            <origin xyz="1.7763568394002506e-16 0.00866024939550707 0.005000000000000356" rpy="1.0359865675357613 -0.9506573206628419 -0.9415634402058217" />
            <geometry>
                <mesh filename="meshes/RR-leg-link11.stl" />
            </geometry>
        </collision>
    </link>
    <link name="RR-leg-link21">
        <inertial>
            <origin xyz="0.02883886358417584 -0.05770684847321725 -0.03514031862141463" rpy="0.0 -0.0 0.0" />
            <mass value="0.2791876465674252" />
            <inertia ixx="0.0005365072745895337" iyy="0.00027233173726425085" izz="0.0004990412182578525" ixy="0.00020191298094363394" iyz="-0.00023698629811308937" ixz="0.00012641592770994793" />
        </inertial>
        <visual name="RR-leg-link21_visual">
            <origin xyz="-0.001328929205639451 -0.0012408340291320031 0.0008332303849812561" rpy="-0.7066322582640269 -0.874131102421541 -0.23994368519397763" />
            <geometry>
                <mesh filename="meshes/RR-leg-link21.stl" />
            </geometry>
        </visual>
        <collision name="RR-leg-link21_collision">
            <origin xyz="-0.001328929205639451 -0.0012408340291320031 0.0008332303849812561" rpy="-0.7066322582640269 -0.874131102421541 -0.23994368519397763" />
            <geometry>
                <mesh filename="meshes/RR-leg-link21.stl" />
            </geometry>
        </collision>
    </link>
    <link name="RR-leg-link31">
        <inertial>
            <origin xyz="-0.009870261189719542 0.056900248368777544 0.04039492088137397" rpy="0.0 -0.0 0.0" />
            <mass value="0.24917982527179094" />
            <inertia ixx="0.0004097842140707192" iyy="0.00017439118086387884" izz="0.0003730969208313517" ixy="0.00011565490220130119" iyz="-0.0001684288653801659" ixz="6.150201699040975e-05" />
        </inertial>
        <visual name="RR-leg-link31_visual">
            <origin xyz="0.001281717073253965 0.0012113339358940324 -0.0009433319697010845" rpy="-2.4051505190755553 0.7922522618340582 2.9011303431522983" />
            <geometry>
                <mesh filename="meshes/RR-leg-link31.stl" />
            </geometry>
        </visual>
        <collision name="RR-leg-link31_collision">
            <origin xyz="0.001281717073253965 0.0012113339358940324 -0.0009433319697010845" rpy="-2.4051505190755553 0.7922522618340582 2.9011303431522983" />
            <geometry>
                <mesh filename="meshes/RR-leg-link31.stl" />
            </geometry>
        </collision>
    </link>
    <link name="RR-leg-link41">
        <inertial>
            <origin xyz="0.024157928483603472 0.023676735620989185 -0.04583883911064824" rpy="0.0 -0.0 0.0" />
            <mass value="0.30627948094211754" />
            <inertia ixx="0.0005633661114039584" iyy="0.0006081462565512704" izz="0.00022086879643114937" ixy="-9.71885627753522e-05" iyz="0.00019523109942761266" ixz="0.00023299261809367488" />
        </inertial>
        <visual name="RR-leg-link41_visual">
            <origin xyz="1.7763568394002506e-16 -0.007967430604492894 -0.004599999999999653" rpy="-2.202675150205263 0.902511429422904 0.8202511401795644" />
            <geometry>
                <mesh filename="meshes/RR-leg-link41.stl" />
            </geometry>
        </visual>
        <collision name="RR-leg-link41_collision">
            <origin xyz="1.7763568394002506e-16 -0.007967430604492894 -0.004599999999999653" rpy="-2.202675150205263 0.902511429422904 0.8202511401795644" />
            <geometry>
                <mesh filename="meshes/RR-leg-link41.stl" />
            </geometry>
        </collision>
    </link>
    <link name="RR-fingertip_frame1">
        <inertial>
            <origin xyz="0.0007731061545634077 0.00037293729982618373 0.001666991385823593" rpy="0.0 -0.0 1.7105694144590048e-49" />
            <mass value="0.0020551252007295867" />
            <inertia ixx="1.4554534225535516e-08" iyy="1.3612027146073236e-08" izz="1.9037095864548464e-08" ixy="5.925286623793875e-10" iyz="1.277623125161111e-09" ixz="2.6485583361229493e-09" />
        </inertial>
        <visual name="RR-fingertip_frame1_visual">
            <origin xyz="1.1090376972333615e-09 3.5447843060865128e-09 1.8895541842312013e-09" rpy="-2.980898282759893 0.44949911772910633 0.8065086801567639" />
            <geometry>
                <mesh filename="meshes/RR-fingertip_frame1.stl" />
            </geometry>
        </visual>
        <collision name="RR-fingertip_frame1_collision">
            <origin xyz="1.1090376972333615e-09 3.5447843060865128e-09 1.8895541842312013e-09" rpy="-2.980898282759893 0.44949911772910633 0.8065086801567639" />
            <geometry>
                <mesh filename="meshes/RR-fingertip_frame1.stl" />
            </geometry>
        </collision>
    </link>
    <link name="RL-Single-Motor1">
        <inertial>
            <origin xyz="-0.007941488256451548 0.02429103275373483 0.01674999999782962" rpy="0.0 -0.0 0.0" />
            <mass value="0.7011939191100404" />
            <inertia ixx="0.0002624831375911407" iyy="0.00019998987600196305" izz="0.0003354208086328277" ixy="-6.052823711306943e-07" iyz="-1.6519771661727134e-14" ixz="4.017793042709883e-14" />
        </inertial>
        <visual name="RL-Single-Motor1_visual">
            <origin xyz="0.025749999999999957 0.03924999999999999 0.016749999999999973" rpy="-1.5707963267948966 1.5707963267948966 0" />
            <geometry>
                <mesh filename="meshes/RL-Single-Motor1.stl" />
            </geometry>
        </visual>
        <collision name="RL-Single-Motor1_collision">
            <origin xyz="0.025749999999999957 0.03924999999999999 0.016749999999999973" rpy="-1.5707963267948966 1.5707963267948966 0" />
            <geometry>
                <mesh filename="meshes/RL-Single-Motor1.stl" />
            </geometry>
        </collision>
    </link>
    <link name="RL-Double-Motor1">
        <inertial>
            <origin xyz="0.06716414766997812 0.005472887473802999 0.009423955249709284" rpy="0.0 -0.0 0.0" />
            <mass value="2.4365544485369104" />
            <inertia ixx="0.001577672922648099" iyy="0.004135448799639604" izz="0.0036850208986658473" ixy="2.839628608475309e-06" iyz="-0.0003936674108825784" ixz="2.72249034081322e-06" />
        </inertial>
        <visual name="RL-Double-Motor1_visual">
            <origin xyz="0.08225000000000003 -2.1316282072803005e-16 -6.217248937900877e-17" rpy="1.5670812769255316e-15 0.5235987755982988 1.5707963267948968" />
            <geometry>
                <mesh filename="meshes/RL-Double-Motor1.stl" />
            </geometry>
        </visual>
        <collision name="RL-Double-Motor1_collision">
            <origin xyz="0.08225000000000003 -2.1316282072803005e-16 -6.217248937900877e-17" rpy="1.5670812769255316e-15 0.5235987755982988 1.5707963267948968" />
            <geometry>
                <mesh filename="meshes/RL-Double-Motor1.stl" />
            </geometry>
        </collision>
    </link>
    <link name="RL-leg-link11">
        <inertial>
            <origin xyz="-0.018187575134685864 -0.030283491560390827 -0.0402168425086392" rpy="0.0 -0.0 0.0" />
            <mass value="0.2812248770831842" />
            <inertia ixx="0.0005532624812261966" iyy="0.00047444338671391595" izz="0.0002585038048009239" ixy="-0.00010711404278454689" iyz="-0.0002493672444622806" ixz="-0.00015941935867359693" />
        </inertial>
        <visual name="RL-leg-link11_visual">
            <origin xyz="3.552713678800501e-17 -0.008660249395507141 0.0049999999999996445" rpy="2.1056060860540304 -0.9506573206628419 0.9415634402058245" />
            <geometry>
                <mesh filename="meshes/RL-leg-link11.stl" />
            </geometry>
        </visual>
        <collision name="RL-leg-link11_collision">
            <origin xyz="3.552713678800501e-17 -0.008660249395507141 0.0049999999999996445" rpy="2.1056060860540304 -0.9506573206628419 0.9415634402058245" />
            <geometry>
                <mesh filename="meshes/RL-leg-link11.stl" />
            </geometry>
        </collision>
    </link>
    <link name="RL-leg-link21">
        <inertial>
            <origin xyz="0.02883886358416776 0.0577068484732029 -0.035140318621405875" rpy="0.0 -0.0 -3.0814879110195774e-33" />
            <mass value="0.27918764656736367" />
            <inertia ixx="0.0005365072745891278" iyy="0.0002723317372640826" izz="0.0004990412182575247" ixy="-0.0002019129809434775" iyz="0.0002369862981129141" ixz="0.00012641592770986645" />
        </inertial>
        <visual name="RL-leg-link21_visual">
            <origin xyz="-0.0013289292056394863 0.0012408340291322872 0.0008332303849802791" rpy="0.7066322582640286 -0.8741311024215513 0.2399436851939842" />
            <geometry>
                <mesh filename="meshes/RL-leg-link21.stl" />
            </geometry>
        </visual>
        <collision name="RL-leg-link21_collision">
            <origin xyz="-0.0013289292056394863 0.0012408340291322872 0.0008332303849802791" rpy="0.7066322582640286 -0.8741311024215513 0.2399436851939842" />
            <geometry>
                <mesh filename="meshes/RL-leg-link21.stl" />
            </geometry>
        </collision>
    </link>
    <link name="RL-leg-link31">
        <inertial>
            <origin xyz="-0.009870261189729952 -0.05690024836879513 0.040394920881419355" rpy="0.0 -0.0 0.0" />
            <mass value="0.24917982527134377" />
            <inertia ixx="0.0004097842140697236" iyy="0.00017439118086187876" izz="0.0003730969208296849" ixy="-0.00011565490220191324" iyz="0.00016842886538141297" ixz="6.15020169910031e-05" />
        </inertial>
        <visual name="RL-leg-link31_visual">
            <origin xyz="0.0012817170732538586 -0.0012113339358955954 -0.000943331969701422" rpy="-0.7364421345142416 0.7922522618340565 -2.901130343152304" />
            <geometry>
                <mesh filename="meshes/RL-leg-link31.stl" />
            </geometry>
        </visual>
        <collision name="RL-leg-link31_collision">
            <origin xyz="0.0012817170732538586 -0.0012113339358955954 -0.000943331969701422" rpy="-0.7364421345142416 0.7922522618340565 -2.901130343152304" />
            <geometry>
                <mesh filename="meshes/RL-leg-link31.stl" />
            </geometry>
        </collision>
    </link>
    <link name="RL-leg-link41">
        <inertial>
            <origin xyz="0.02415809680666783 -0.023676711126044518 -0.045838812790971274" rpy="0.0 -0.0 0.0" />
            <mass value="0.30627894117127225" />
            <inertia ixx="0.0005633661876117621" iyy="0.0006081466240829003" izz="0.0002208690153326781" ixy="9.718794061956693e-05" iyz="-0.00019523111673036206" ixz="0.00023299104324884734" />
        </inertial>
        <visual name="RL-leg-link41_visual">
            <origin xyz="1.0658141036401502e-16 0.007967430604493 -0.004600000000000293" rpy="-0.9389175033845283 0.9025114294229021 -0.8202511401795558" />
            <geometry>
                <mesh filename="meshes/RL-leg-link41.stl" />
            </geometry>
        </visual>
        <collision name="RL-leg-link41_collision">
            <origin xyz="1.0658141036401502e-16 0.007967430604493 -0.004600000000000293" rpy="-0.9389175033845283 0.9025114294229021 -0.8202511401795558" />
            <geometry>
                <mesh filename="meshes/RL-leg-link41.stl" />
            </geometry>
        </collision>
    </link>
    <link name="RL-fingertip_frame1">
        <inertial>
            <origin xyz="0.000773106149895888 -0.00037293729807760914 0.0016669913765109002" rpy="0.0 -0.0 3.081487911019578e-33" />
            <mass value="0.0020551252007295867" />
            <inertia ixx="1.4554532121261723e-08" iyy="1.3612029568695882e-08" izz="1.9037095546172497e-08" ixy="-5.925287258865305e-10" iyz="-1.277622553224137e-09" ixz="2.648559298271061e-09" />
        </inertial>
        <visual name="RL-fingertip_frame1_visual">
            <origin xyz="1.1046867243180713e-09 -3.5426863576049074e-09 1.880172817436687e-09" rpy="2.9808982827598918 0.4494991177291068 -0.8065086801567766" />
            <geometry>
                <mesh filename="meshes/RL-fingertip_frame1.stl" />
            </geometry>
        </visual>
        <collision name="RL-fingertip_frame1_collision">
            <origin xyz="1.1046867243180713e-09 -3.5426863576049074e-09 1.880172817436687e-09" rpy="2.9808982827598918 0.4494991177291068 -0.8065086801567766" />
            <geometry>
                <mesh filename="meshes/RL-fingertip_frame1.stl" />
            </geometry>
        </collision>
    </link>
    <joint name="Body1_FR-Body-Single_Motor" type="fixed">
        <origin xyz="-0.044000000000000004 0.029500000000000002 0.012000000000000028" rpy="3.141592653589793 -0.0 0.0" />
        <parent link="Body1" />
        <child link="FR-Single-Motor1" />
    </joint>
    <joint name="FR-Single-Motor1_FR-Single-Double_Motor" type="continuous">
        <origin xyz="-0.034499999999999996 -0.03925 0.016750000000000043" rpy="-1.5707963267948966 -0.0 -1.5407439555097887e-33" />
        <parent link="FR-Single-Motor1" />
        <child link="FR-Double-Motor1" />
        <axis xyz="-1.0 0.0 7.806255641895643e-18" />
    </joint>
    <joint name="Body1_FL-Body-Single_Motor" type="fixed">
        <origin xyz="-0.044000000000000004 -0.032 0.012000000000000028" rpy="3.141592653589793 -0.0 0.0" />
        <parent link="Body1" />
        <child link="FL-Single-Motor1" />
    </joint>
    <joint name="FL-Single-Motor1_FL-Single-Double_Motor" type="continuous">
        <origin xyz="-0.034499999999999996 0.03925 0.016750000000000043" rpy="-1.5707963267948966 -0.0 -3.8518598887744726e-34" />
        <parent link="FL-Single-Motor1" />
        <child link="FL-Double-Motor1" />
        <axis xyz="-0.9999999999999999 -1.539512473013105e-48 7.806255641895629e-18" />
    </joint>
    <joint name="FL-Double-Motor1_FL-Double_Motor-Link1" type="continuous">
        <origin xyz="-0.08224999999999998 0.031400000000000004 0.05438639999999999" rpy="-1.5707963267948968 -3.8518598887744726e-34 4.810976478165954e-50" />
        <parent link="FL-Double-Motor1" />
        <child link="FL-leg-link11" />
        <axis xyz="0.0 -0.8660250000000002 0.4999999999999999" />
    </joint>
    <joint name="FL-leg-link11_FL-Link1-Link2" type="continuous">
        <origin xyz="-0.055349129999999996 -0.07090645000000001 -0.09998516000000002" rpy="-0.7853981633974451 5.551115123125783e-17 6.798155367234457e-33" />
        <parent link="FL-leg-link11" />
        <child link="FL-leg-link21" />
        <axis xyz="0.640856 -0.6056687778914328 -0.47166638600232924" />
    </joint>
    <joint name="FL-Double-Motor1_FL-Double_Motor-Link4" type="continuous">
        <origin xyz="-0.08224999999999998 0.041000000000000016 0.07101407999999998" rpy="-1.5707963267948968 -3.8518598887744726e-34 4.810976478165954e-50" />
        <parent link="FL-Double-Motor1" />
        <child link="FL-leg-link41" />
        <axis xyz="0.0 -0.866025 0.5" />
    </joint>
    <joint name="FL-leg-link41_FL-Link4-Link3" type="continuous">
        <origin xyz="0.04450177 -0.05645856000000002 -0.11336067" rpy="-0.7853981633974534 -4.1053665947016125e-48 -1.1102230246251565e-16" />
        <parent link="FL-leg-link41" />
        <child link="FL-leg-link31" />
        <axis xyz="0.6644629999999999 0.6204190253469806 0.4166167088733992" />
    </joint>
    <joint name="FL-leg-link21_FL-Link2-Link3" type="continuous">
        <origin xyz="0.045870350000000004 0.10436275957666326 -0.07044621311142345" rpy="-2.1862760354652835 -0.523598775598294 2.5261129449194093" />
        <parent link="FL-leg-link21" />
        <child link="FL-leg-link31" />
        <axis xyz="-0.6711405018682711 0.20534699999999997 0.712322400804583" />
    </joint>
    <joint name="FL-leg-link21_FL-Link2-Fingertip" type="fixed">
        <origin xyz="0.05896426999999999 0.1342397322802053 -0.08802220068595261" rpy="-2.356194490192348 -2.453269466693391e-17 2.453269466693407e-17" />
        <parent link="FL-leg-link21" />
        <child link="FL-fingertip_frame1" />
    </joint>
    <joint name="Body1_RR-Body-Single_Motor" type="fixed">
        <origin xyz="0.06 0.029500000000000002 0.012000000000000028" rpy="2.2204460492503126e-16 -0.0 0.0" />
        <parent link="Body1" />
        <child link="RR-Single-Motor1" />
    </joint>
    <joint name="RR-Single-Motor1_RR-Single-Double_Motor" type="continuous">
        <origin xyz="0.018499999999999996 0.03924999999999999 -0.016750000000000043" rpy="1.5707963267948966 -1.3684555315672039e-48 -6.162975822039155e-33" />
        <parent link="RR-Single-Motor1" />
        <child link="RR-Double-Motor1" />
        <axis xyz="1.0 0.0 -7.806255641895643e-18" />
    </joint>
    <joint name="Body1_RL-Body-Single_Motor" type="fixed">
        <origin xyz="0.06 -0.032 0.012000000000000028" rpy="3.141592653589793 -0.0 0.0" />
        <parent link="Body1" />
        <child link="RL-Single-Motor1" />
    </joint>
    <joint name="RL-Single-Motor1_RL-Single-Double_Motor" type="continuous">
        <origin xyz="0.018499999999999996 0.03925 0.016750000000000043" rpy="-1.5707963267948966 -5.473822126268817e-48 0.0" />
        <parent link="RL-Single-Motor1" />
        <child link="RL-Double-Motor1" />
        <axis xyz="1.0 4.930380657631325e-32 -7.806255641895544e-18" />
    </joint>
    <joint name="RL-Double-Motor1_RL-Double_Motor-Link1" type="continuous">
        <origin xyz="0.08225 0.031400000000000004 0.054386399999999994" rpy="-1.5707963267948968 -9.860761315262648e-32 1.7789921910373654e-47" />
        <parent link="RL-Double-Motor1" />
        <child link="RL-leg-link11" />
        <axis xyz="8.539665818050335e-32 -0.8660250000000002 0.4999999999999999" />
    </joint>
    <joint name="RL-leg-link11_RL-Link1-Link2" type="continuous">
        <origin xyz="-0.04450176999999998 -0.07308624 -0.10376067" rpy="-0.7853981633974451 2.7755575615628907e-17 5.551115123125793e-17" />
        <parent link="RL-leg-link11" />
        <child link="RL-leg-link21" />
        <axis xyz="0.664463 -0.6204190253469839 -0.41661670887339414" />
    </joint>
    <joint name="RL-Double-Motor1_RL-Double_Motor-Link4" type="continuous">
        <origin xyz="0.08225 0.041000000000000016 0.07101408" rpy="-1.5707963267948968 -9.860761315262648e-32 1.7789921910373654e-47" />
        <parent link="RL-Double-Motor1" />
        <child link="RL-leg-link41" />
        <axis xyz="8.539665818050335e-32 -0.866025 0.5" />
    </joint>
    <joint name="RL-leg-link41_RL-Link4-Link3" type="continuous">
        <origin xyz="0.055349129999999996 -0.054278770000000025 -0.10958516000000003" rpy="2.35619449019234 1.1102230246251565e-16 -1.1102230246251556e-16" />
        <parent link="RL-leg-link41" />
        <child link="RL-leg-link31" />
        <axis xyz="-0.6408559999999999 0.6056687778914289 0.47166638600233346" />
    </joint>
    <joint name="RL-leg-link21_RL-Link2-Link3" type="continuous">
        <origin xyz="0.053980549999999974 0.10323441514378821 -0.06623518009742323" rpy="-2.1862760354652835 -0.523598775598294 2.5261129449194093" />
        <parent link="RL-leg-link21" />
        <child link="RL-leg-link31" />
        <axis xyz="-0.7123224008045759 0.20534699999999995 0.6711405018682787" />
    </joint>
    <joint name="RL-leg-link21_RL-Link2-Fingertip" type="fixed">
        <origin xyz="0.06917824999999998 0.1327916836583524 -0.08261801690258165" rpy="-2.356194490192348 1.9626155733547254e-17 1.962615573354713e-17" />
        <parent link="RL-leg-link21" />
        <child link="RL-fingertip_frame1" />
    </joint>
    <joint name="FR-Double-Motor1_FR-Double_Motor-Link1" type="continuous">
        <origin xyz="-0.08225 0.031400000000000004 -0.054386399999999994" rpy="-1.5707963267948968 -1.5407439555097887e-33 1.9243905912663812e-49" />
        <parent link="FR-Double-Motor1" />
        <child link="FR-leg-link11" />
        <axis xyz="0.0 0.8660249999999999 0.5000000000000001" />
    </joint>
    <joint name="FR-leg-link11_FR-Link1-Link2" type="continuous">
        <origin xyz="-0.055349129999999996 0.07090645000000004 -0.09998516000000002" rpy="0.7853981633974454 -0.0 0.0" />
        <parent link="FR-leg-link11" />
        <child link="FR-leg-link21" />
        <axis xyz="-0.640856 -0.6056687778914328 0.47166638600232924" />
    </joint>
    <joint name="FR-Double-Motor1_FR-Double_Motor-Link4" type="continuous">
        <origin xyz="-0.08225 0.041000000000000016 -0.07101408" rpy="-1.5707963267948968 -1.5407439555097887e-33 1.9243905912663812e-49" />
        <parent link="FR-Double-Motor1" />
        <child link="FR-leg-link41" />
        <axis xyz="0.0 0.866025 0.5" />
    </joint>
    <joint name="FR-leg-link41_FR-Link4-Link3" type="continuous">
        <origin xyz="0.04450177 0.05645856000000002 -0.11336067" rpy="-2.35619449019234 2.775557561562892e-17 0.0" />
        <parent link="FR-leg-link41" />
        <child link="FR-leg-link31" />
        <axis xyz="0.6644629999999999 0.6204190253469807 -0.4166167088733998" />
    </joint>
    <joint name="FR-leg-link21_FR-Link2-Link3" type="continuous">
        <origin xyz="0.045870350000000004 -0.10436275957666319 -0.07044621311142345" rpy="-0.9553166181245096 -0.5235987755982938 -2.5261129449194093" />
        <parent link="FR-leg-link21" />
        <child link="FR-leg-link31" />
        <axis xyz="0.671140501868271 -0.20534699999999997 0.7123224008045831" />
    </joint>
    <joint name="FR-leg-link21_FR-Link2-Fingertip" type="fixed">
        <origin xyz="0.05896426999999999 -0.13423973228020525 -0.0880222006859526" rpy="2.356194490192348 -5.3971928267254846e-17 2.453269466693382e-17" />
        <parent link="FR-leg-link21" />
        <child link="FR-fingertip_frame1" />
    </joint>
    <joint name="RR-Double-Motor1_RR-Double_Motor-Link1" type="continuous">
        <origin xyz="0.08225 0.031400000000000004 -0.05438639999999999" rpy="-1.5707963267948968 6.162975822039155e-33 -7.697562365065525e-49" />
        <parent link="RR-Double-Motor1" />
        <child link="RR-leg-link11" />
        <axis xyz="0.0 0.8660250000000002 0.5000000000000002" />
    </joint>
    <joint name="RR-leg-link11_RR-Link1-Link2" type="continuous">
        <origin xyz="-0.04450176999999998 0.07308624000000004 -0.10376067" rpy="0.7853981633974454 -6.798155367234455e-33 5.551115123125783e-17" />
        <parent link="RR-leg-link11" />
        <child link="RR-leg-link21" />
        <axis xyz="-0.664463 -0.620419025346984 0.4166167088733942" />
    </joint>
    <joint name="RR-Double-Motor1_RR-Double_Motor-Link4" type="continuous">
        <origin xyz="0.08225 0.041000000000000016 -0.07101407999999998" rpy="-1.5707963267948968 6.162975822039155e-33 -7.697562365065525e-49" />
        <parent link="RR-Double-Motor1" />
        <child link="RR-leg-link41" />
        <axis xyz="0.0 0.8660250000000003 0.5000000000000001" />
    </joint>
    <joint name="RR-leg-link41_RR-Link4-Link3" type="continuous">
        <origin xyz="0.055349129999999996 0.054278770000000025 -0.10958516000000003" rpy="-2.35619449019234 5.551115123125784e-17 -5.551115123125784e-17" />
        <parent link="RR-leg-link41" />
        <child link="RR-leg-link31" />
        <axis xyz="0.6408559999999999 0.6056687778914288 -0.4716663860023348" />
    </joint>
    <joint name="RR-leg-link21_RR-Link2-Link3" type="continuous">
        <origin xyz="0.053980549999999995 -0.10323441514378821 -0.06623518009742321" rpy="-0.9553166181245095 -0.523598775598294 -2.5261129449194097" />
        <parent link="RR-leg-link21" />
        <child link="RR-leg-link31" />
        <axis xyz="0.712322400804576 -0.205347 0.6711405018682788" />
    </joint>
    <joint name="RR-leg-link21_RR-Link2-Fingertip" type="fixed">
        <origin xyz="0.06917825000000001 -0.13279168365835242 -0.08261801690258162" rpy="2.356194490192348 -3.925231146709402e-17 -1.1775693440128322e-16" />
        <parent link="RR-leg-link21" />
        <child link="RR-fingertip_frame1" />
    </joint>
</robot>